Workbook

Sheet ПРАЙС
A2: 1 класс - малоразмерные седаны, хетчбеки иностранного и российского производства
A3: 2 класс - среднеразмерные седаны, малые кроссоверы
A4: 3 класс - седаны класса люкс, среднеразмерные кроссоверы
A5: 4 класс - крупные кроссоверы, рамные внедорожники
A6: 4+ класс - микроавтобусы, внедорожники с увеличенной базой, спорткары
A8: ШУМО-, ВИБОИЗОЛЯЦИЯ ТС
D10: Комплекс (без арок) | E10: Двери | F10: Полы | G10: Багажник | H10: Потолок | I10: Капот | J10: Арки
A11: Хетчбек
C12: STP Aerocel | D12: 94500 | E12: 25000 | F12: 31000 | G12: 24000 | H12: 15000 | I12: 5000 | J12: 25000
A13: Седан
C14: STP Aerocel | D14: 95500 | E14: 25000 | F14: 31000 | G14: 25000 | H14: 15000 | I14: 5000 | J14: 28000
A15: Бизнес седан
C16: STP Aerocel | D16: 103500 | E16: 26000 | F16: 36000 | G16: 26500 | H16: 15500 | I16: 6000 | J16: 30000
A17: Кроссовер
C18: STP Aerocel | D18: 106500 | E18: 27000 | F18: 36000 | G18: 26500 | H18: 18000 | I18: 6000 | J18: 30000
A19: Внедорожник
C20: STP Aerocel | D20: 114500 | E20: 28000 | F20: 37000 | G20: 30000 | H20: 20000 | I20: 6500 | J20: 32000

Sheet Цены
A1: SGM | H1: ComfortMat
A2: Наименование | B2: Цена | C2: Скидка | D2: Наша цена | E2: Вес | F2: Толщина | H2: Наименование | I2: Цена | J2: Скидка | K2: Наша цена | L2: Вес | M2: Толщина | Q2: Вес | R2: Толщина
A3: SGM Roof (0.75x1.0) | B3: 806 | D3: =B3-(B3/100)*C3 -> 806 | H3: Turbo M1 | I3: 190 | J3: 35 | K3: =I3-I3/100*J3 -> 123.5 | L3: 0.95 | M3: 1.5
A4: Антискрип -1 КС (0,75х1,0) | B4: 322 | D4: =B4-(B4/100)*C4 -> 322 | H4: Turbo M2 | I4: 210 | J4: 35 | K4: =I4-I4/100*J4 -> 136.5 | L4: 1.3 | M4: 2
A5: Антискрип -1 КС (1,0*0.025) лента | B5: 27 | D5: =B5-(B5/100)*C5 -> 27 | H5: Turbo M3 | I5: 265 | J5: 35 | K5: =I5-I5/100*J5 -> 172.25 | L5: 1.96 | M5: 3
A6: Антискрип -10 КС (ППУ) (0.75x1.0) | B6: 369 | D6: =B6-(B6/100)*C6 -> 369 | H6: Turbo M4 | I6: 340 | J6: 35 | K6: =I6-I6/100*J6 -> 221 | L6: 2.64 | M6: 4
A7: Антискрип -5 КС (ППУ) (0.75x1.0) | B7: 275 | D7: =B7-(B7/100)*C7 -> 275 | H7: Bronze 1 | I7: 240 | J7: 35 | K7: =I7-I7/100*J7 -> 156 | L7: 0.95 | M7: 1.5
A8: Виолон ПТ-540 ( Автовойлок)КС (0,75х1,0) (10мм) | B8: 403 | D8: =B8-(B8/100)*C8 -> 403 | H8: Bronze 2 | I8: 265 | J8: 35 | K8: =I8-I8/100*J8 -> 172.25 | L8: 1.3 | M8: 2
A9: Виолон Black-Vell волна 15 КС (0,75х1,0) | B9: 553 | D9: =B9-(B9/100)*C9 -> 553 | H9: Bronze 3 | I9: 350 | J9: 35 | K9: =I9-I9/100*J9 -> 227.5 | L9: 1.96 | M9: 3
A10: Виолон Бета 10 КС (0,75х1,0) (10мм) | B10: 461 | D10: =B10-(B10/100)*C10 -> 461 | H10: Bronze 4 | I10: 430 | J10: 35 | K10: =I10-I10/100*J10 -> 279.5 | L10: 2.64 | M10: 4
A11: Виолон Бета 5 КС (0,75х1,0) (5мм) | B11: 335 | D11: =B11-(B11/100)*C11 -> 335 | H11: S2 | I11: 330 | J11: 35 | K11: =I11-I11/100*J11 -> 214.5 | L11: 1.32 | M11: 2 | O11: розница | P11: stp
A12: Виолон Вэл 10 КС (0,75х1,0) (10мм) | B12: 480 | D12: =B12-(B12/100)*C12 -> 480 | H12: S3 | I12: 390 | J12: 35 | K12: =I12-I12/100*J12 -> 253.5 | L12: 2.02 | M12: 3
A13: Виолон Вэл 5 КС (0,75х1,0) (5мм) | B13: 335 | D13: =B13-(B13/100)*C13 -> 335 | H13: vespa | I13: 390 | J13: 35 | K13: 255 | L13: 1.23 | M13: 2.3 | N13: g2 | O13: 420
A14: Виолон Вэл волна 15 КС (0,75х1,0) | B14: 490 | D14: =B14-(B14/100)*C14 -> 490 | H14: spider | I14: 480 | J14: 35 | K14: 318 | L14: 1.85 | M14: 3 | N14: g3 | O14: 515
A15: Виолон Вэл-волна 25 КС (0,75х1,0) | B15: 796 | D15: =B15-(B15/100)*C15 -> 796 | H15: G4 | I15: 570 | J15: 35 | K15: =I15-I15/100*J15 -> 370.5 | L15: 2.34 | M15: 4
A16: R-TON 6KC (0.75x1.0) | B16: 576 | D16: =B16-(B16/100)*C16 -> 576 | H16: D2 | I16: 430 | J16: 35 | K16: =I16-I16/100*J16 -> 279.5 | L16: 0.9 | M16: 2.3
A17: БиБи-Тон 4 КС (0,75х1.0) | B17: 289 | D17: =B17-(B17/100)*C17 -> 289 | H17: D3 | I17: 495 | J17: 35 | K17: =I17-I17/100*J17 -> 321.75 | L17: 1.19 | M17: 3
A18: БиБи-Тон 8 КС (0,75х1.0) | B18: 404 | D18: =B18-(B18/100)*C18 -> 404 | H18: Cobra | I18: 495 | J18: 35 | K18: 338 | L18: 0.9 | M18: 2.3 | O18: 510
A19: Изолонтейп (1,0х1,5м) (4004 ВБФ, Серый) | B19: 505 | D19: =B19-(B19/100)*C19 -> 505 | H19: Pro Max | I19: 550 | J19: 35 | K19: =I19-I19/100*J19 -> 357.5 | L19: 2.5 | M19: 8
A20: Изолонтейп (1,0х1,5м) (4004 ВП, Серый) | B20: 311 | D20: =B20-(B20/100)*C20 -> 311 | H20: Viper | I20: 580 | J20: 35 | K20: 398 | L20: 1.19 | M20: 3 | O20: 600
A21: Изолонтейп (1,0х1,5м) (4008 ВБФ, Серый) | B21: 498 | D21: =B21-(B21/100)*C21 -> 498 | H21: Atom | I21: 660 | J21: 35 | K21: 469 | L21: 2.4 | M21: 4.2 | O21: 745
A22: Изолонтейп (1,0х1,5м) (4008 ВП, Серый) | B22: 530 | D22: =B22-(B22/100)*C22 -> 530 | H22: Extreme | I22: 690 | J22: 35 | K22: 487 | L22: 2.25 | M22: 3.5 | O22: 775
A23: Шумо-виброизоляционные материалы SGM AIR 2 (М2Ф) (0,5х0,8) | B23: 278 | D23: =B23-(B23/100)*C23 -> 278 | H23: Extreme Pro | I23: 775 | J23: 35 | K23: =I23-I23/100*J23 -> 503.75 | L23: 3.37
A24: Шумо-виброизоляционные материалы SGM AIR 3 (М3Ф) (0,5х0,8) | B24: 335 | D24: =B24-(B24/100)*C24 -> 335 | H24: Turbo i8 | I24: 300 | J24: 35 | K24: =I24-I24/100*J24 -> 195
A25: Шумо-виброизоляционные материалы SGM AIR 4 (М3Ф) (0,5х0,8) | B25: 404 | D25: =B25-(B25/100)*C25 -> 404 | H25: Turbo i4 | I25: 245 | J25: 35 | K25: =I25-I25/100*J25 -> 159.25
A26: Шумо-виброизоляционные материалы SGM Barrier 3 (0,5х0,8) | B26: 323 | D26: =B26-(B26/100)*C26 -> 323 | H26: Turbo Fi8 | I26: 330 | J26: 35 | K26: =I26-I26/100*J26 -> 214.5
A27: SGM Barrier Lite (0,5х0,8) | B27: 328 | D27: =B27-(B27/100)*C27 -> 328 | H27: Turbo Fi4 | I27: 280 | J27: 35 | K27: =I27-I27/100*J27 -> 182 | T27: 30
A28: Шумо-виброизоляционные материалы SGM Barrier Mix (0,5х0,8) | B28: 357 | D28: =B28-(B28/100)*C28 -> 357 | H28: SkyLine | I28: 275 | J28: 35 | K28: 166 | L28: 0.6 | M28: 6 | O28: 300
A29: Шумо-виброизоляционные материалы SGM Barrier Mix Profi (0,5х0,8) | B29: 553 | D29: =B29-(B29/100)*C29 -> 553 | H29: V-ton 4 | I29: 350 | J29: 35 | K29: =I29-I29/100*J29 -> 227.5 | L29: 0.42 | M29: 4
A30: Шумо-виброизоляционные материалы SGM Barrier Ultra (0,5х0,8) | B30: 404 | D30: =B30-(B30/100)*C30 -> 404 | H30: Bitoflex 5 | I30: 400 | J30: 35 | K30: =I30-I30/100*J30 -> 260 | L30: 0.21 | M30: 5
A31: SGM Dual 4 (0,5х0,8) | B31: 490 | D31: =B31-(B31/100)*C31 -> 490 | H31: Defender | I31: 440 | J31: 35 | K31: 312 | L31: 0.64 | M31: 4.5 | O31: 470
A32: SGM Onux 2 (0,5х0,8) | B32: 265 | D32: =B32-(B32/100)*C32 -> 265 | H32: Bitosoft | I32: 450 | J32: 35 | K32: =I32-I32/100*J32 -> 292.5 | L32: 0.24 | M32: 5
A33: SGM Onux 3 (0,5х0,8) | B33: 311 | D33: =B33-(B33/100)*C33 -> 311 | H33: Автовойлок | I33: 460 | J33: 35 | K33: =I33-I33/100*J33 -> 299 | L33: 0.43 | M33: 10
A34: SGM Onux 4 (0,5х0,8) | B34: 363 | D34: =B34-(B34/100)*C34 -> 363 | H34: Tsunami | I34: 490 | J34: 35 | K34: =I34-I34/100*J34 -> 318.5 | M34: 18
A35: SGM Silshot (0.5x0.8) | B35: 289 | D35: =B35-(B35/100)*C35 -> 289 | H35: V-ton 8 | I35: 500 | J35: 35 | K35: =I35-I35/100*J35 -> 325 | L35: 0.76 | M35: 8
A36: SGM Stripe Lite | B36: 26 | D36: =B36-(B36/100)*C36 -> 26 | H36: Ultra Soft 5 | I36: 520 | J36: 35 | K36: =I36-I36/100*J36 -> 338 | L36: 0.29 | M36: 5
A37: SGM Stripe Mix | B37: 26 | D37: =B37-(B37/100)*C37 -> 26 | H37: Volna | I37: 520 | J37: 35 | K37: =I37-I37/100*J37 -> 338 | L37: 0.34 | M37: 15
A38: SGM Stripe Силтон | B38: 26 | D38: =B38-(B38/100)*C38 -> 26 | H38: Integra | I38: 550 | J38: 35 | K38: 378 | L38: 1.2 | M38: 6 | O38: 600
A39: SGM Силтон (0,5х0,8) | B39: 311 | D39: =B39-(B39/100)*C39 -> 311 | H39: Blockshot | I39: 580 | J39: 35 | K39: 388 | L39: 1.8 | M39: 7 | O39: 635
A40: Алюмаст Base 1 (М1Ф1) (0,5х0,7) | B40: 126 | D40: =B40-(B40/100)*C40 -> 126 | H40: Raptor | I40: 580 | J40: 35 | K40: 400 | L40: 1.15 | M40: 4.5 | O40: 655
...

Sheet Расход
A1: Класс авто | B1: Линейка | D1: Двери (4 шт.) | Q1: Арки (4 шт.) | AD1: Полы (до багажника) | AQ1: Багажник (без крышки) | BE1: Потолок | BR1: Капот | CE1: Крышка багажника
D2: Материал | E2: Кол-во | F2: Вес | G2: Суммарный вес, кг | H2: Цена материала | I2: Норм.ч. | J2: Тариф | K2: Стоимость материала | L2: Работа сотр. | M2: Себестоимость | N2: Прибыль | O2: Rпр, % | P2: ЦЕНА | Q2: Материал | R2: Кол-во | S2: Вес | T2: Суммарный вес, кг | U2: Цена материала | V2: Норм.ч. | W2: Тариф | X2: Стоимость материала | Y2: Работа сотр. | Z2: Себестоимость | AA2: Прибыль | AB2: Rпр, % | AC2: ЦЕНА | AD2: Материал | AE2: Кол-во | AF2: Вес | AG2: Суммарный вес, кг | AH2: Цена материала | AI2: Норм.ч. | AJ2: Тариф | AK2: Стоимость материала | AL2: Работа сотр. | AM2: Себестоимость | AN2: Прибыль | AO2: Rпр, % | AP2: ЦЕНА | AQ2: Материал | AR2: Кол-во | AS2: Вес | AT2: Суммарный вес, кг | AU2: Цена материала | AV2: Норм.ч. | AW2: Тариф | AX2: Стоимость материала | AY2: Работа сотр. | AZ2: Себестоимость | BA2: Прибыль | BB2: Rпр, % | BC2: ЦЕНА | BD2: цена с крышкой | BE2: Материал | BF2: Кол-во | BG2: Вес | BH2: Суммарный вес, кг | BI2: Цена материала | BJ2: Норм.ч. | BK2: Тариф | BL2: Стоимость материала | BM2: Работа сотр. | BN2: Себестоимость | BO2: Прибыль | BP2: Rпр, % | BQ2: ЦЕНА | BR2: Материал | BS2: Кол-во | BT2: Вес | BU2: Суммарный вес, кг | BV2: Цена материала | BW2: Норм.ч. | BX2: Тариф | BY2: Стоимость материала | BZ2: Работа сотр. | CA2: Себестоимость | CB2: Прибыль | CC2: Rпр, % | CD2: ЦЕНА | CE2: Материал | CF2: Кол-во | CG2: Вес | CH2: Суммарный вес, кг | CI2: Цена материала | CJ2: Норм.ч. | CK2: Тариф | CL2: Стоимость материала | CM2: Работа сотр. | CN2: Себестоимость | CO2: Прибыль | CP2: Rпр, % | CQ2: ЦЕНА
A3: A | B3: Comfort | C3: Норма | D3: G2 | E3: 6 | F3: =IF(D3=Цены!$H$3,Цены!$L$3,IF(D3=Цены!$H$4,Цены!$L$4,IF(D3=Цены!$H$5,Цены!$L$5,IF(D3=Цены!$H$6,Цены!$L$6,IF(D3=Цены!$H$7,Цены!$L$7,IF(D3=Цены!$H$8,Цены!$L$8,IF(D3=Цены!$H$9,Цены!$L$9,IF(D3=Цены!$H$10,Цены!$L$10,IF(D3=Цены!$H$11,Цены!$L$11,IF(D3=Цены!$H$12,Цены!$L$12,IF(D3=Цены!$H$13,Цены!$L$13,IF(D3=Цены!$H$14,Цены!$L$14,IF(D3=Цены!$H$14,Цены!$L$14,IF(D3=Цены!$H$15,Цены!$L$15,IF(D3=Цены!$H$16,Цены!$L$16,IF(D3=Цены!$H$17,Цены!$L$17,IF(D3=Цены!$H$18,Цены!$L$18,IF(D3=Цены!$H$19,Цены!$L$19,IF(D3=Цены!$H$20,Цены!$L$20,IF(D3=Цены!$H$21,Цены!$L$21,IF(D3=Цены!$H$22,Цены!$L$22,IF(D3=Цены!$H$23,Цены!$L$23,IF(D3=Цены!$H$24,Цены!$L$24,IF(D3=Цены!$H$25,Цены!$L$25,IF(D3=Цены!$H$26,Цены!$L$26,IF(D3=Цены!$H$27,Цены!$L$27,IF(D3=Цены!$H$28,Цены!$L$28,IF(D3=Цены!$H$29,Цены!$L$29,IF(D3=Цены!$H$30,Цены!$L$30,IF(D3=Цены!$H$31,Цены!$L$31,IF(D3=Цены!$H$32,Цены!$L$32,IF(D3=Цены!$H$33,Цены!$L$33,IF(D3=Цены!$H$34,Цены!$L$34,IF(D3=Цены!$H$35,Цены!$L$35,IF(D3=Цены!$H$36,Цены!$L$36,IF(D3=Цены!$H$37,Цены!$L$37,IF(D3=Цены!$H$38,Цены!$L$38,IF(D3=Цены!$H$39,Цены!$L$39,IF(D3=Цены!$H$40,Цены!$L$40,IF(D3=Цены!$H$41,Цены!$L$41,IF(D3=Цены!$H$42,Цены!$L$42,IF(D3=Цены!$H$43,Цены!$L$43,IF(D3=Цены!$H$44,Цены!$L$44,IF(D3=Цены!$H$45,Цены!$L$45,IF(D3=Цены!$H$46,Цены!$L$46,IF(D3=Цены!$H$47,Цены!$L$47,IF(D3=Цены!$H$48,Цены!$L$48,IF(D3=Цены!$H$49,Цены!$L$49,IF(D3=Цены!$H$50,Цены!$L$50,IF(D3=Цены!$H$51,Цены!$L$51,IF(D3=Цены!$H$52,Цены!$L$52,IF(D3=Цены!$H$53,Цены!$L$53,IF(D3=Цены!$H$54,Цены!$L$54,IF(D3=Цены!$H$55,Цены!$L$55)))))))))))))))))))))))))))))))))))))))))))))))))))))) -> FALSE | G3: =E3*F3+E4*F4+E5*F5+E6*F6 -> 4.5864 | H3: =IF(D3=Цены!$H$3,Цены!$K$3,IF(D3=Цены!$H$4,Цены!$K$4,IF(D3=Цены!$H$5,Цены!$K$5,IF(D3=Цены!$H$6,Цены!$K$6,IF(D3=Цены!$H$7,Цены!$K$7,IF(D3=Цены!$H$8,Цены!$K$8,IF(D3=Цены!$H$9,Цены!$K$9,IF(D3=Цены!$H$10,Цены!$K$10,IF(D3=Цены!$H$11,Цены!$K$11,IF(D3=Цены!$H$12,Цены!$K$12,IF(D3=Цены!$H$13,Цены!$K$13,IF(D3=Цены!$H$14,Цены!$K$14,IF(D3=Цены!$H$14,Цены!$K$14,IF(D3=Цены!$H$15,Цены!$K$15,IF(D3=Цены!$H$16,Цены!$K$16,IF(D3=Цены!$H$17,Цены!$K$17,IF(D3=Цены!$H$18,Цены!$K$18,IF(D3=Цены!$H$19,Цены!$K$19,IF(D3=Цены!$H$20,Цены!$K$20,IF(D3=Цены!$H$21,Цены!$K$21,IF(D3=Цены!$H$22,Цены!$K$22,IF(D3=Цены!$H$23,Цены!$K$23,IF(D3=Цены!$H$24,Цены!$K$24,IF(D3=Цены!$H$25,Цены!$K$25,IF(D3=Цены!$H$26,Цены!$K$26,IF(D3=Цены!$H$27,Цены!$K$27,IF(D3=Цены!$H$28,Цены!$K$28,IF(D3=Цены!$H$29,Цены!$K$29,IF(D3=Цены!$H$30,Цены!$K$30,IF(D3=Цены!$H$31,Цены!$K$31,IF(D3=Цены!$H$32,Цены!$K$32,IF(D3=Цены!$H$33,Цены!$K$33,IF(D3=Цены!$H$34,Цены!$K$34,IF(D3=Цены!$H$35,Цены!$K$35,IF(D3=Цены!$H$36,Цены!$K$36,IF(D3=Цены!$H$37,Цены!$K$37,IF(D3=Цены!$H$38,Цены!$K$38,IF(D3=Цены!$H$39,Цены!$K$39,IF(D3=Цены!$H$40,Цены!$K$40,IF(D3=Цены!$H$41,Цены!$K$41,IF(D3=Цены!$H$42,Цены!$K$42,IF(D3=Цены!$H$43,Цены!$K$43,IF(D3=Цены!$H$44,Цены!$K$44,IF(D3=Цены!$H$45,Цены!$K$45,IF(D3=Цены!$H$46,Цены!$K$46,IF(D3=Цены!$H$47,Цены!$K$47,IF(D3=Цены!$H$48,Цены!$K$48,IF(D3=Цены!$H$49,Цены!$K$49,IF(D3=Цены!$H$50,Цены!$K$50,IF(D3=Цены!$H$51,Цены!$K$51,IF(D3=Цены!$H$52,Цены!$K$52,IF(D3=Цены!$H$53,Цены!$K$53,IF(D3=Цены!$H$54,Цены!$K$54,IF(D3=Цены!$H$55,Цены!$K$55)))))))))))))))))))))))))))))))))))))))))))))))))))))) -> FALSE | I3: 3.5 | J3: 800 | K3: =E3*H3+E4*H4+E5*H5+E6*H6 -> 3434 | L3: =$I$3*$J$3 -> 2800 | M3: =K3+L3 -> 6234 | N3: =I3*J3*1.1 -> 3080 | O3: =N3/M3*100 -> 49.406481 | P3: =MROUND(M3+N3,500) -> 9500 | Q3: g3 | R3: 4 | S3: =IF(Q3=Цены!$H$3,Цены!$L$3,IF(Q3=Цены!$H$4,Цены!$L$4,IF(Q3=Цены!$H$5,Цены!$L$5,IF(Q3=Цены!$H$6,Цены!$L$6,IF(Q3=Цены!$H$7,Цены!$L$7,IF(Q3=Цены!$H$8,Цены!$L$8,IF(Q3=Цены!$H$9,Цены!$L$9,IF(Q3=Цены!$H$10,Цены!$L$10,IF(Q3=Цены!$H$11,Цены!$L$11,IF(Q3=Цены!$H$12,Цены!$L$12,IF(Q3=Цены!$H$13,Цены!$L$13,IF(Q3=Цены!$H$14,Цены!$L$14,IF(Q3=Цены!$H$14,Цены!$L$14,IF(Q3=Цены!$H$15,Цены!$L$15,IF(Q3=Цены!$H$16,Цены!$L$16,IF(Q3=Цены!$H$17,Цены!$L$17,IF(Q3=Цены!$H$18,Цены!$L$18,IF(Q3=Цены!$H$19,Цены!$L$19,IF(Q3=Цены!$H$20,Цены!$L$20,IF(Q3=Цены!$H$21,Цены!$L$21,IF(Q3=Цены!$H$22,Цены!$L$22,IF(Q3=Цены!$H$23,Цены!$L$23,IF(Q3=Цены!$H$24,Цены!$L$24,IF(Q3=Цены!$H$25,Цены!$L$25,IF(Q3=Цены!$H$26,Цены!$L$26,IF(Q3=Цены!$H$27,Цены!$L$27,IF(Q3=Цены!$H$28,Цены!$L$28,IF(Q3=Цены!$H$29,Цены!$L$29,IF(Q3=Цены!$H$30,Цены!$L$30,IF(Q3=Цены!$H$31,Цены!$L$31,IF(Q3=Цены!$H$32,Цены!$L$32,IF(Q3=Цены!$H$33,Цены!$L$33,IF(Q3=Цены!$H$34,Цены!$L$34,IF(Q3=Цены!$H$35,Цены!$L$35,IF(Q3=Цены!$H$36,Цены!$L$36,IF(Q3=Цены!$H$37,Цены!$L$37,IF(Q3=Цены!$H$38,Цены!$L$38,IF(Q3=Цены!$H$39,Цены!$L$39,IF(Q3=Цены!$H$40,Цены!$L$40,IF(Q3=Цены!$H$41,Цены!$L$41,IF(Q3=Цены!$H$42,Цены!$L$42,IF(Q3=Цены!$H$43,Цены!$L$43,IF(Q3=Цены!$H$44,Цены!$L$44,IF(Q3=Цены!$H$45,Цены!$L$45,IF(Q3=Цены!$H$46,Цены!$L$46,IF(Q3=Цены!$H$47,Цены!$L$47,IF(Q3=Цены!$H$48,Цены!$L$48,IF(Q3=Цены!$H$49,Цены!$L$49,IF(Q3=Цены!$H$50,Цены!$L$50,IF(Q3=Цены!$H$51,Цены!$L$51,IF(Q3=Цены!$H$52,Цены!$L$52,IF(Q3=Цены!$H$53,Цены!$L$53,IF(Q3=Цены!$H$54,Цены!$L$54,IF(Q3=Цены!$H$55,Цены!$L$55)))))))))))))))))))))))))))))))))))))))))))))))))))))) -> FALSE | T3: =R3*S3+R4*S4+R5*S5+R6*S6 -> 1.28 | U3: =IF(Q3=Цены!$H$3,Цены!$K$3,IF(Q3=Цены!$H$4,Цены!$K$4,IF(Q3=Цены!$H$5,Цены!$K$5,IF(Q3=Цены!$H$6,Цены!$K$6,IF(Q3=Цены!$H$7,Цены!$K$7,IF(Q3=Цены!$H$8,Цены!$K$8,IF(Q3=Цены!$H$9,Цены!$K$9,IF(Q3=Цены!$H$10,Цены!$K$10,IF(Q3=Цены!$H$11,Цены!$K$11,IF(Q3=Цены!$H$12,Цены!$K$12,IF(Q3=Цены!$H$13,Цены!$K$13,IF(Q3=Цены!$H$14,Цены!$K$14,IF(Q3=Цены!$H$14,Цены!$K$14,IF(Q3=Цены!$H$15,Цены!$K$15,IF(Q3=Цены!$H$16,Цены!$K$16,IF(Q3=Цены!$H$17,Цены!$K$17,IF(Q3=Цены!$H$18,Цены!$K$18,IF(Q3=Цены!$H$19,Цены!$K$19,IF(Q3=Цены!$H$20,Цены!$K$20,IF(Q3=Цены!$H$21,Цены!$K$21,IF(Q3=Цены!$H$22,Цены!$K$22,IF(Q3=Цены!$H$23,Цены!$K$23,IF(Q3=Цены!$H$24,Цены!$K$24,IF(Q3=Цены!$H$25,Цены!$K$25,IF(Q3=Цены!$H$26,Цены!$K$26,IF(Q3=Цены!$H$27,Цены!$K$27,IF(Q3=Цены!$H$28,Цены!$K$28,IF(Q3=Цены!$H$29,Цены!$K$29,IF(Q3=Цены!$H$30,Цены!$K$30,IF(Q3=Цены!$H$31,Цены!$K$31,IF(Q3=Цены!$H$32,Цены!$K$32,IF(Q3=Цены!$H$33,Цены!$K$33,IF(Q3=Цены!$H$34,Цены!$K$34,IF(Q3=Цены!$H$35,Цены!$K$35,IF(Q3=Цены!$H$36,Цены!$K$36,IF(Q3=Цены!$H$37,Цены!$K$37,IF(Q3=Цены!$H$38,Цены!$K$38,IF(Q3=Цены!$H$39,Цены!$K$39,IF(Q3=Цены!$H$40,Цены!$K$40,IF(Q3=Цены!$H$41,Цены!$K$41,IF(Q3=Цены!$H$42,Цены!$K$42,IF(Q3=Цены!$H$43,Цены!$K$43,IF(Q3=Цены!$H$44,Цены!$K$44,IF(Q3=Цены!$H$45,Цены!$K$45,IF(Q3=Цены!$H$46,Цены!$K$46,IF(Q3=Цены!$H$47,Цены!$K$47,IF(Q3=Цены!$H$48,Цены!$K$48,IF(Q3=Цены!$H$49,Цены!$K$49,IF(Q3=Цены!$H$50,Цены!$K$50,IF(Q3=Цены!$H$51,Цены!$K$51,IF(Q3=Цены!$H$52,Цены!$K$52,IF(Q3=Цены!$H$53,Цены!$K$53,IF(Q3=Цены!$H$54,Цены!$K$54,IF(Q3=Цены!$H$55,Цены!$K$55)))))))))))))))))))))))))))))))))))))))))))))))))))))) -> FALSE | V3: 4 | W3: 800 | X3: =R3*U3+R4*U4+R5*U5+R6*U6 -> 624 | Y3: =V3*W3 -> 3200 | Z3: =X3+Y3 -> 3824 | AA3: =V3*W3*1.1 -> 3520 | AB3: =AA3/Z3*100 -> 92.050209 | AC3: =MROUND(Z3+AA3,500) -> 7500 | AD3: G3 | AE3: 4 | AF3: =IF(AD3=Цены!$H$3,Цены!$L$3,IF(AD3=Цены!$H$4,Цены!$L$4,IF(AD3=Цены!$H$5,Цены!$L$5,IF(AD3=Цены!$H$6,Цены!$L$6,IF(AD3=Цены!$H$7,Цены!$L$7,IF(AD3=Цены!$H$8,Цены!$L$8,IF(AD3=Цены!$H$9,Цены!$L$9,IF(AD3=Цены!$H$10,Цены!$L$10,IF(AD3=Цены!$H$11,Цены!$L$11,IF(AD3=Цены!$H$12,Цены!$L$12,IF(AD3=Цены!$H$13,Цены!$L$13,IF(AD3=Цены!$H$14,Цены!$L$14,IF(AD3=Цены!$H$14,Цены!$L$14,IF(AD3=Цены!$H$15,Цены!$L$15,IF(AD3=Цены!$H$16,Цены!$L$16,IF(AD3=Цены!$H$17,Цены!$L$17,IF(AD3=Цены!$H$18,Цены!$L$18,IF(AD3=Цены!$H$19,Цены!$L$19,IF(AD3=Цены!$H$20,Цены!$L$20,IF(AD3=Цены!$H$21,Цены!$L$21,IF(AD3=Цены!$H$22,Цены!$L$22,IF(AD3=Цены!$H$23,Цены!$L$23,IF(AD3=Цены!$H$24,Цены!$L$24,IF(AD3=Цены!$H$25,Цены!$L$25,IF(AD3=Цены!$H$26,Цены!$L$26,IF(AD3=Цены!$H$27,Цены!$L$27,IF(AD3=Цены!$H$28,Цены!$L$28,IF(AD3=Цены!$H$29,Цены!$L$29,IF(AD3=Цены!$H$30,Цены!$L$30,IF(AD3=Цены!$H$31,Цены!$L$31,IF(AD3=Цены!$H$32,Цены!$L$32,IF(AD3=Цены!$H$33,Цены!$L$33,IF(AD3=Цены!$H$34,Цены!$L$34,IF(AD3=Цены!$H$35,Цены!$L$35,IF(AD3=Цены!$H$36,Цены!$L$36,IF(AD3=Цены!$H$37,Цены!$L$37,IF(AD3=Цены!$H$38,Цены!$L$38,IF(AD3=Цены!$H$39,Цены!$L$39,IF(AD3=Цены!$H$40,Цены!$L$40,IF(AD3=Цены!$H$41,Цены!$L$41,IF(AD3=Цены!$H$42,Цены!$L$42,IF(AD3=Цены!$H$43,Цены!$L$43,IF(AD3=Цены!$H$44,Цены!$L$44,IF(AD3=Цены!$H$45,Цены!$L$45,IF(AD3=Цены!$H$46,Цены!$L$46,IF(AD3=Цены!$H$47,Цены!$L$47,IF(AD3=Цены!$H$48,Цены!$L$48,IF(AD3=Цены!$H$49,Цены!$L$49,IF(AD3=Цены!$H$50,Цены!$L$50,IF(AD3=Цены!$H$51,Цены!$L$51,IF(AD3=Цены!$H$52,Цены!$L$52,IF(AD3=Цены!$H$53,Цены!$L$53,IF(AD3=Цены!$H$54,Цены!$L$54,IF(AD3=Цены!$H$55,Цены!$L$55)))))))))))))))))))))))))))))))))))))))))))))))))))))) -> FALSE | AG3: =AE3*AF3+AE4*AF4+AE5*AF5+AE6*AF6 -> 12.38 | AH3: =IF(AD3=Цены!$H$3,Цены!$K$3,IF(AD3=Цены!$H$4,Цены!$K$4,IF(AD3=Цены!$H$5,Цены!$K$5,IF(AD3=Цены!$H$6,Цены!$K$6,IF(AD3=Цены!$H$7,Цены!$K$7,IF(AD3=Цены!$H$8,Цены!$K$8,IF(AD3=Цены!$H$9,Цены!$K$9,IF(AD3=Цены!$H$10,Цены!$K$10,IF(AD3=Цены!$H$11,Цены!$K$11,IF(AD3=Цены!$H$12,Цены!$K$12,IF(AD3=Цены!$H$13,Цены!$K$13,IF(AD3=Цены!$H$14,Цены!$K$14,IF(AD3=Цены!$H$14,Цены!$K$14,IF(AD3=Цены!$H$15,Цены!$K$15,IF(AD3=Цены!$H$16,Цены!$K$16,IF(AD3=Цены!$H$17,Цены!$K$17,IF(AD3=Цены!$H$18,Цены!$K$18,IF(AD3=Цены!$H$19,Цены!$K$19,IF(AD3=Цены!$H$20,Цены!$K$20,IF(AD3=Цены!$H$21,Цены!$K$21,IF(AD3=Цены!$H$22,Цены!$K$22,IF(AD3=Цены!$H$23,Цены!$K$23,IF(AD3=Цены!$H$24,Цены!$K$24,IF(AD3=Цены!$H$25,Цены!$K$25,IF(AD3=Цены!$H$26,Цены!$K$26,IF(AD3=Цены!$H$27,Цены!$K$27,IF(AD3=Цены!$H$28,Цены!$K$28,IF(AD3=Цены!$H$29,Цены!$K$29,IF(AD3=Цены!$H$30,Цены!$K$30,IF(AD3=Цены!$H$31,Цены!$K$31,IF(AD3=Цены!$H$32,Цены!$K$32,IF(AD3=Цены!$H$33,Цены!$K$33,IF(AD3=Цены!$H$34,Цены!$K$34,IF(AD3=Цены!$H$35,Цены!$K$35,IF(AD3=Цены!$H$36,Цены!$K$36,IF(AD3=Цены!$H$37,Цены!$K$37,IF(AD3=Цены!$H$38,Цены!$K$38,IF(AD3=Цены!$H$39,Цены!$K$39,IF(AD3=Цены!$H$40,Цены!$K$40,IF(AD3=Цены!$H$41,Цены!$K$41,IF(AD3=Цены!$H$42,Цены!$K$42,IF(AD3=Цены!$H$43,Цены!$K$43,IF(AD3=Цены!$H$44,Цены!$K$44,IF(AD3=Цены!$H$45,Цены!$K$45,IF(AD3=Цены!$H$46,Цены!$K$46,IF(AD3=Цены!$H$47,Цены!$K$47,IF(AD3=Цены!$H$48,Цены!$K$48,IF(AD3=Цены!$H$49,Цены!$K$49,IF(AD3=Цены!$H$50,Цены!$K$50,IF(AD3=Цены!$H$51,Цены!$K$51,IF(AD3=Цены!$H$52,Цены!$K$52,IF(AD3=Цены!$H$53,Цены!$K$53,IF(AD3=Цены!$H$54,Цены!$K$54,IF(AD3=Цены!$H$55,Цены!$K$55)))))))))))))))))))))))))))))))))))))))))))))))))))))) -> FALSE | AI3: 5 | AJ3: 800 | AK3: =AE3*AH3+AE4*AH4+AE5*AH5+AE6*AH6 -> 4503.5 | AL3: =AI3*AJ3 -> 4000 | AM3: =AK3+AL3 -> 8503.5 | AN3: =AI3*AJ3*1.1 -> 4400 | AO3: =AN3/AM3*100 -> 51.7434 | AP3: =MROUND(AM3+AN3,500) -> 13000 | AQ3: g3 | AR3: 3 | AS3: =IF(AQ3=Цены!$H$3,Цены!$L$3,IF(AQ3=Цены!$H$4,Цены!$L$4,IF(AQ3=Цены!$H$5,Цены!$L$5,IF(AQ3=Цены!$H$6,Цены!$L$6,IF(AQ3=Цены!$H$7,Цены!$L$7,IF(AQ3=Цены!$H$8,Цены!$L$8,IF(AQ3=Цены!$H$9,Цены!$L$9,IF(AQ3=Цены!$H$10,Цены!$L$10,IF(AQ3=Цены!$H$11,Цены!$L$11,IF(AQ3=Цены!$H$12,Цены!$L$12,IF(AQ3=Цены!$H$13,Цены!$L$13,IF(AQ3=Цены!$H$14,Цены!$L$14,IF(AQ3=Цены!$H$14,Цены!$L$14,IF(AQ3=Цены!$H$15,Цены!$L$15,IF(AQ3=Цены!$H$16,Цены!$L$16,IF(AQ3=Цены!$H$17,Цены!$L$17,IF(AQ3=Цены!$H$18,Цены!$L$18,IF(AQ3=Цены!$H$19,Цены!$L$19,IF(AQ3=Цены!$H$20,Цены!$L$20,IF(AQ3=Цены!$H$21,Цены!$L$21,IF(AQ3=Цены!$H$22,Цены!$L$22,IF(AQ3=Цены!$H$23,Цены!$L$23,IF(AQ3=Цены!$H$24,Цены!$L$24,IF(AQ3=Цены!$H$25,Цены!$L$25,IF(AQ3=Цены!$H$26,Цены!$L$26,IF(AQ3=Цены!$H$27,Цены!$L$27,IF(AQ3=Цены!$H$28,Цены!$L$28,IF(AQ3=Цены!$H$29,Цены!$L$29,IF(AQ3=Цены!$H$30,Цены!$L$30,IF(AQ3=Цены!$H$31,Цены!$L$31,IF(AQ3=Цены!$H$32,Цены!$L$32,IF(AQ3=Цены!$H$33,Цены!$L$33,IF(AQ3=Цены!$H$34,Цены!$L$34,IF(AQ3=Цены!$H$35,Цены!$L$35,IF(AQ3=Цены!$H$36,Цены!$L$36,IF(AQ3=Цены!$H$37,Цены!$L$37,IF(AQ3=Цены!$H$38,Цены!$L$38,IF(AQ3=Цены!$H$39,Цены!$L$39,IF(AQ3=Цены!$H$40,Цены!$L$40,IF(AQ3=Цены!$H$41,Цены!$L$41,IF(AQ3=Цены!$H$42,Цены!$L$42,IF(AQ3=Цены!$H$43,Цены!$L$43,IF(AQ3=Цены!$H$44,Цены!$L$44,IF(AQ3=Цены!$H$45,Цены!$L$45,IF(AQ3=Цены!$H$46,Цены!$L$46,IF(AQ3=Цены!$H$47,Цены!$L$47,IF(AQ3=Цены!$H$48,Цены!$L$48,IF(AQ3=Цены!$H$49,Цены!$L$49,IF(AQ3=Цены!$H$50,Цены!$L$50,IF(AQ3=Цены!$H$51,Цены!$L$51,IF(AQ3=Цены!$H$52,Цены!$L$52,IF(AQ3=Цены!$H$53,Цены!$L$53,IF(AQ3=Цены!$H$54,Цены!$L$54,IF(AQ3=Цены!$H$55,Цены!$L$55)))))))))))))))))))))))))))))))))))))))))))))))))))))) -> FALSE | AT3: =AR3*AS3+AR4*AS4+AR5*AS5+AR6*AS6 -> 0.38 | AU3: =IF(AQ3=Цены!$H$3,Цены!$K$3,IF(AQ3=Цены!$H$4,Цены!$K$4,IF(AQ3=Цены!$H$5,Цены!$K$5,IF(AQ3=Цены!$H$6,Цены!$K$6,IF(AQ3=Цены!$H$7,Цены!$K$7,IF(AQ3=Цены!$H$8,Цены!$K$8,IF(AQ3=Цены!$H$9,Цены!$K$9,IF(AQ3=Цены!$H$10,Цены!$K$10,IF(AQ3=Цены!$H$11,Цены!$K$11,IF(AQ3=Цены!$H$12,Цены!$K$12,IF(AQ3=Цены!$H$13,Цены!$K$13,IF(AQ3=Цены!$H$14,Цены!$K$14,IF(AQ3=Цены!$H$14,Цены!$K$14,IF(AQ3=Цены!$H$15,Цены!$K$15,IF(AQ3=Цены!$H$16,Цены!$K$16,IF(AQ3=Цены!$H$17,Цены!$K$17,IF(AQ3=Цены!$H$18,Цены!$K$18,IF(AQ3=Цены!$H$19,Цены!$K$19,IF(AQ3=Цены!$H$20,Цены!$K$20,IF(AQ3=Цены!$H$21,Цены!$K$21,IF(AQ3=Цены!$H$22,Цены!$K$22,IF(AQ3=Цены!$H$23,Цены!$K$23,IF(AQ3=Цены!$H$24,Цены!$K$24,IF(AQ3=Цены!$H$25,Цены!$K$25,IF(AQ3=Цены!$H$26,Цены!$K$26,IF(AQ3=Цены!$H$27,Цены!$K$27,IF(AQ3=Цены!$H$28,Цены!$K$28,IF(AQ3=Цены!$H$29,Цены!$K$29,IF(AQ3=Цены!$H$30,Цены!$K$30,IF(AQ3=Цены!$H$31,Цены!$K$31,IF(AQ3=Цены!$H$32,Цены!$K$32,IF(AQ3=Цены!$H$33,Цены!$K$33,IF(AQ3=Цены!$H$34,Цены!$K$34,IF(AQ3=Цены!$H$35,Цены!$K$35,IF(AQ3=Цены!$H$36,Цены!$K$36,IF(AQ3=Цены!$H$37,Цены!$K$37,IF(AQ3=Цены!$H$38,Цены!$K$38,IF(AQ3=Цены!$H$39,Цены!$K$39,IF(AQ3=Цены!$H$40,Цены!$K$40,IF(AQ3=Цены!$H$41,Цены!$K$41,IF(AQ3=Цены!$H$42,Цены!$K$42,IF(AQ3=Цены!$H$43,Цены!$K$43,IF(AQ3=Цены!$H$44,Цены!$K$44,IF(AQ3=Цены!$H$45,Цены!$K$45,IF(AQ3=Цены!$H$46,Цены!$K$46,IF(AQ3=Цены!$H$47,Цены!$K$47,IF(AQ3=Цены!$H$48,Цены!$K$48,IF(AQ3=Цены!$H$49,Цены!$K$49,IF(AQ3=Цены!$H$50,Цены!$K$50,IF(AQ3=Цены!$H$51,Цены!$K$51,IF(AQ3=Цены!$H$52,Цены!$K$52,IF(AQ3=Цены!$H$53,Цены!$K$53,IF(AQ3=Цены!$H$54,Цены!$K$54,IF(AQ3=Цены!$H$55,Цены!$K$55)))))))))))))))))))))))))))))))))))))))))))))))))))))) -> FALSE | AV3: 5 | AW3: 800 | AX3: =AR3*AU3+AR4*AU4+AR5*AU5+AR6*AU6 -> 896 | AY3: =AV3*AW3 -> 4000 | AZ3: =AX3+AY3 -> 4896 | BA3: =AV3*AW3*1.1 -> 4400 | BB3: =BA3/AZ3*100 -> 89.869281 | BC3: =MROUND(AZ3+BA3,500) -> 9500 | BE3: g2 | BF3: 3 | BG3: =IF(BE3=Цены!$H$3,Цены!$L$3,IF(BE3=Цены!$H$4,Цены!$L$4,IF(BE3=Цены!$H$5,Цены!$L$5,IF(BE3=Цены!$H$6,Цены!$L$6,IF(BE3=Цены!$H$7,Цены!$L$7,IF(BE3=Цены!$H$8,Цены!$L$8,IF(BE3=Цены!$H$9,Цены!$L$9,IF(BE3=Цены!$H$10,Цены!$L$10,IF(BE3=Цены!$H$11,Цены!$L$11,IF(BE3=Цены!$H$12,Цены!$L$12,IF(BE3=Цены!$H$13,Цены!$L$13,IF(BE3=Цены!$H$14,Цены!$L$14,IF(BE3=Цены!$H$14,Цены!$L$14,IF(BE3=Цены!$H$15,Цены!$L$15,IF(BE3=Цены!$H$16,Цены!$L$16,IF(BE3=Цены!$H$17,Цены!$L$17,IF(BE3=Цены!$H$18,Цены!$L$18,IF(BE3=Цены!$H$19,Цены!$L$19,IF(BE3=Цены!$H$20,Цены!$L$20,IF(BE3=Цены!$H$21,Цены!$L$21,IF(BE3=Цены!$H$22,Цены!$L$22,IF(BE3=Цены!$H$23,Цены!$L$23,IF(BE3=Цены!$H$24,Цены!$L$24,IF(BE3=Цены!$H$25,Цены!$L$25,IF(BE3=Цены!$H$26,Цены!$L$26,IF(BE3=Цены!$H$27,Цены!$L$27,IF(BE3=Цены!$H$28,Цены!$L$28,IF(BE3=Цены!$H$29,Цены!$L$29,IF(BE3=Цены!$H$30,Цены!$L$30,IF(BE3=Цены!$H$31,Цены!$L$31,IF(BE3=Цены!$H$32,Цены!$L$32,IF(BE3=Цены!$H$33,Цены!$L$33,IF(BE3=Цены!$H$34,Цены!$L$34,IF(BE3=Цены!$H$35,Цены!$L$35,IF(BE3=Цены!$H$36,Цены!$L$36,IF(BE3=Цены!$H$37,Цены!$L$37,IF(BE3=Цены!$H$38,Цены!$L$38,IF(BE3=Цены!$H$39,Цены!$L$39,IF(BE3=Цены!$H$40,Цены!$L$40,IF(BE3=Цены!$H$41,Цены!$L$41,IF(BE3=Цены!$H$42,Цены!$L$42,IF(BE3=Цены!$H$43,Цены!$L$43,IF(BE3=Цены!$H$44,Цены!$L$44,IF(BE3=Цены!$H$45,Цены!$L$45,IF(BE3=Цены!$H$46,Цены!$L$46,IF(BE3=Цены!$H$47,Цены!$L$47,IF(BE3=Цены!$H$48,Цены!$L$48,IF(BE3=Цены!$H$49,Цены!$L$49,IF(BE3=Цены!$H$50,Цены!$L$50,IF(BE3=Цены!$H$51,Цены!$L$51,IF(BE3=Цены!$H$52,Цены!$L$52,IF(BE3=Цены!$H$53,Цены!$L$53,IF(BE3=Цены!$H$54,Цены!$L$54,IF(BE3=Цены!$H$55,Цены!$L$55)))))))))))))))))))))))))))))))))))))))))))))))))))))) -> FALSE | BH3: =BF3*BG3+BF4*BG4+BF5*BG5+BF6*BG6 -> 0.38 | BI3: =IF(BE3=Цены!$H$3,Цены!$K$3,IF(BE3=Цены!$H$4,Цены!$K$4,IF(BE3=Цены!$H$5,Цены!$K$5,IF(BE3=Цены!$H$6,Цены!$K$6,IF(BE3=Цены!$H$7,Цены!$K$7,IF(BE3=Цены!$H$8,Цены!$K$8,IF(BE3=Цены!$H$9,Цены!$K$9,IF(BE3=Цены!$H$10,Цены!$K$10,IF(BE3=Цены!$H$11,Цены!$K$11,IF(BE3=Цены!$H$12,Цены!$K$12,IF(BE3=Цены!$H$13,Цены!$K$13,IF(BE3=Цены!$H$14,Цены!$K$14,IF(BE3=Цены!$H$14,Цены!$K$14,IF(BE3=Цены!$H$15,Цены!$K$15,IF(BE3=Цены!$H$16,Цены!$K$16,IF(BE3=Цены!$H$17,Цены!$K$17,IF(BE3=Цены!$H$18,Цены!$K$18,IF(BE3=Цены!$H$19,Цены!$K$19,IF(BE3=Цены!$H$20,Цены!$K$20,IF(BE3=Цены!$H$21,Цены!$K$21,IF(BE3=Цены!$H$22,Цены!$K$22,IF(BE3=Цены!$H$23,Цены!$K$23,IF(BE3=Цены!$H$24,Цены!$K$24,IF(BE3=Цены!$H$25,Цены!$K$25,IF(BE3=Цены!$H$26,Цены!$K$26,IF(BE3=Цены!$H$27,Цены!$K$27,IF(BE3=Цены!$H$28,Цены!$K$28,IF(BE3=Цены!$H$29,Цены!$K$29,IF(BE3=Цены!$H$30,Цены!$K$30,IF(BE3=Цены!$H$31,Цены!$K$31,IF(BE3=Цены!$H$32,Цены!$K$32,IF(BE3=Цены!$H$33,Цены!$K$33,IF(BE3=Цены!$H$34,Цены!$K$34,IF(BE3=Цены!$H$35,Цены!$K$35,IF(BE3=Цены!$H$36,Цены!$K$36,IF(BE3=Цены!$H$37,Цены!$K$37,IF(BE3=Цены!$H$38,Цены!$K$38,IF(BE3=Цены!$H$39,Цены!$K$39,IF(BE3=Цены!$H$40,Цены!$K$40,IF(BE3=Цены!$H$41,Цены!$K$41,IF(BE3=Цены!$H$42,Цены!$K$42,IF(BE3=Цены!$H$43,Цены!$K$43,IF(BE3=Цены!$H$44,Цены!$K$44,IF(BE3=Цены!$H$45,Цены!$K$45,IF(BE3=Цены!$H$46,Цены!$K$46,IF(BE3=Цены!$H$47,Цены!$K$47,IF(BE3=Цены!$H$48,Цены!$K$48,IF(BE3=Цены!$H$49,Цены!$K$49,IF(BE3=Цены!$H$50,Цены!$K$50,IF(BE3=Цены!$H$51,Цены!$K$51,IF(BE3=Цены!$H$52,Цены!$K$52,IF(BE3=Цены!$H$53,Цены!$K$53,IF(BE3=Цены!$H$54,Цены!$K$54,IF(BE3=Цены!$H$55,Цены!$K$55)))))))))))))))))))))))))))))))))))))))))))))))))))))) -> FALSE | BJ3: 3.5 | BK3: 800 | BL3: =BF3*BI3+BF4*BI4+BF5*BI5+BF6*BI6 -> 896 | BM3: =BJ3*BK3 -> 2800 | BN3: =BL3+BM3 -> 3696 | BO3: =BJ3*BK3*1.1 -> 3080 | BP3: =BO3/BN3*100 -> 83.333333 | BQ3: =MROUND(BN3+BO3,500) -> 7000 | BR3: G2 | BS3: 2 | BT3: =IF(BR3=Цены!$H$3,Цены!$L$3,IF(BR3=Цены!$H$4,Цены!$L$4,IF(BR3=Цены!$H$5,Цены!$L$5,IF(BR3=Цены!$H$6,Цены!$L$6,IF(BR3=Цены!$H$7,Цены!$L$7,IF(BR3=Цены!$H$8,Цены!$L$8,IF(BR3=Цены!$H$9,Цены!$L$9,IF(BR3=Цены!$H$10,Цены!$L$10,IF(BR3=Цены!$H$11,Цены!$L$11,IF(BR3=Цены!$H$12,Цены!$L$12,IF(BR3=Цены!$H$13,Цены!$L$13,IF(BR3=Цены!$H$14,Цены!$L$14,IF(BR3=Цены!$H$14,Цены!$L$14,IF(BR3=Цены!$H$15,Цены!$L$15,IF(BR3=Цены!$H$16,Цены!$L$16,IF(BR3=Цены!$H$17,Цены!$L$17,IF(BR3=Цены!$H$18,Цены!$L$18,IF(BR3=Цены!$H$19,Цены!$L$19,IF(BR3=Цены!$H$20,Цены!$L$20,IF(BR3=Цены!$H$21,Цены!$L$21,IF(BR3=Цены!$H$22,Цены!$L$22,IF(BR3=Цены!$H$23,Цены!$L$23,IF(BR3=Цены!$H$24,Цены!$L$24,IF(BR3=Цены!$H$25,Цены!$L$25,IF(BR3=Цены!$H$26,Цены!$L$26,IF(BR3=Цены!$H$27,Цены!$L$27,IF(BR3=Цены!$H$28,Цены!$L$28,IF(BR3=Цены!$H$29,Цены!$L$29,IF(BR3=Цены!$H$30,Цены!$L$30,IF(BR3=Цены!$H$31,Цены!$L$31,IF(BR3=Цены!$H$32,Цены!$L$32,IF(BR3=Цены!$H$33,Цены!$L$33,IF(BR3=Цены!$H$34,Цены!$L$34,IF(BR3=Цены!$H$35,Цены!$L$35,IF(BR3=Цены!$H$36,Цены!$L$36,IF(BR3=Цены!$H$37,Цены!$L$37,IF(BR3=Цены!$H$38,Цены!$L$38,IF(BR3=Цены!$H$39,Цены!$L$39,IF(BR3=Цены!$H$40,Цены!$L$40,IF(BR3=Цены!$H$41,Цены!$L$41,IF(BR3=Цены!$H$42,Цены!$L$42,IF(BR3=Цены!$H$43,Цены!$L$43,IF(BR3=Цены!$H$44,Цены!$L$44,IF(BR3=Цены!$H$45,Цены!$L$45,IF(BR3=Цены!$H$46,Цены!$L$46,IF(BR3=Цены!$H$47,Цены!$L$47,IF(BR3=Цены!$H$48,Цены!$L$48,IF(BR3=Цены!$H$49,Цены!$L$49,IF(BR3=Цены!$H$50,Цены!$L$50,IF(BR3=Цены!$H$51,Цены!$L$51,IF(BR3=Цены!$H$52,Цены!$L$52,IF(BR3=Цены!$H$53,Цены!$L$53,IF(BR3=Цены!$H$54,Цены!$L$54,IF(BR3=Цены!$H$55,Цены!$L$55)))))))))))))))))))))))))))))))))))))))))))))))))))))) -> FALSE | BU3: =BS3*BT3+BS4*BT4+BS5*BT5+BS6*BT6 -> 1.2 | BV3: =IF(BR3=Цены!$H$3,Цены!$K$3,IF(BR3=Цены!$H$4,Цены!$K$4,IF(BR3=Цены!$H$5,Цены!$K$5,IF(BR3=Цены!$H$6,Цены!$K$6,IF(BR3=Цены!$H$7,Цены!$K$7,IF(BR3=Цены!$H$8,Цены!$K$8,IF(BR3=Цены!$H$9,Цены!$K$9,IF(BR3=Цены!$H$10,Цены!$K$10,IF(BR3=Цены!$H$11,Цены!$K$11,IF(BR3=Цены!$H$12,Цены!$K$12,IF(BR3=Цены!$H$13,Цены!$K$13,IF(BR3=Цены!$H$14,Цены!$K$14,IF(BR3=Цены!$H$14,Цены!$K$14,IF(BR3=Цены!$H$15,Цены!$K$15,IF(BR3=Цены!$H$16,Цены!$K$16,IF(BR3=Цены!$H$17,Цены!$K$17,IF(BR3=Цены!$H$18,Цены!$K$18,IF(BR3=Цены!$H$19,Цены!$K$19,IF(BR3=Цены!$H$20,Цены!$K$20,IF(BR3=Цены!$H$21,Цены!$K$21,IF(BR3=Цены!$H$22,Цены!$K$22,IF(BR3=Цены!$H$23,Цены!$K$23,IF(BR3=Цены!$H$24,Цены!$K$24,IF(BR3=Цены!$H$25,Цены!$K$25,IF(BR3=Цены!$H$26,Цены!$K$26,IF(BR3=Цены!$H$27,Цены!$K$27,IF(BR3=Цены!$H$28,Цены!$K$28,IF(BR3=Цены!$H$29,Цены!$K$29,IF(BR3=Цены!$H$30,Цены!$K$30,IF(BR3=Цены!$H$31,Цены!$K$31,IF(BR3=Цены!$H$32,Цены!$K$32,IF(BR3=Цены!$H$33,Цены!$K$33,IF(BR3=Цены!$H$34,Цены!$K$34,IF(BR3=Цены!$H$35,Цены!$K$35,IF(BR3=Цены!$H$36,Цены!$K$36,IF(BR3=Цены!$H$37,Цены!$K$37,IF(BR3=Цены!$H$38,Цены!$K$38,IF(BR3=Цены!$H$39,Цены!$K$39,IF(BR3=Цены!$H$40,Цены!$K$40,IF(BR3=Цены!$H$41,Цены!$K$41,IF(BR3=Цены!$H$42,Цены!$K$42,IF(BR3=Цены!$H$43,Цены!$K$43,IF(BR3=Цены!$H$44,Цены!$K$44,IF(BR3=Цены!$H$45,Цены!$K$45,IF(BR3=Цены!$H$46,Цены!$K$46,IF(BR3=Цены!$H$47,Цены!$K$47,IF(BR3=Цены!$H$48,Цены!$K$48,IF(BR3=Цены!$H$49,Цены!$K$49,IF(BR3=Цены!$H$50,Цены!$K$50,IF(BR3=Цены!$H$51,Цены!$K$51,IF(BR3=Цены!$H$52,Цены!$K$52,IF(BR3=Цены!$H$53,Цены!$K$53,IF(BR3=Цены!$H$54,Цены!$K$54,IF(BR3=Цены!$H$55,Цены!$K$55)))))))))))))))))))))))))))))))))))))))))))))))))))))) -> FALSE | BW3: 1 | BX3: 800 | BY3: =BS3*BV3+BS4*BV4+BS5*BV5+BS6*BV6 -> 332 | BZ3: =BW3*BX3 -> 800 | CA3: =BY3+BZ3 -> 1132 | CB3: =BW3*BX3*1.1 -> 880 | CC3: =CB3/CA3*100 -> 77.738516 | CD3: =MROUND(CA3+CB3,500) -> 2000 | CE3: G2 | CF3: 2 | CG3: =IF(CE3=Цены!$H$3,Цены!$L$3,IF(CE3=Цены!$H$4,Цены!$L$4,IF(CE3=Цены!$H$5,Цены!$L$5,IF(CE3=Цены!$H$6,Цены!$L$6,IF(CE3=Цены!$H$7,Цены!$L$7,IF(CE3=Цены!$H$8,Цены!$L$8,IF(CE3=Цены!$H$9,Цены!$L$9,IF(CE3=Цены!$H$10,Цены!$L$10,IF(CE3=Цены!$H$11,Цены!$L$11,IF(CE3=Цены!$H$12,Цены!$L$12,IF(CE3=Цены!$H$13,Цены!$L$13,IF(CE3=Цены!$H$14,Цены!$L$14,IF(CE3=Цены!$H$14,Цены!$L$14,IF(CE3=Цены!$H$15,Цены!$L$15,IF(CE3=Цены!$H$16,Цены!$L$16,IF(CE3=Цены!$H$17,Цены!$L$17,IF(CE3=Цены!$H$18,Цены!$L$18,IF(CE3=Цены!$H$19,Цены!$L$19,IF(CE3=Цены!$H$20,Цены!$L$20,IF(CE3=Цены!$H$21,Цены!$L$21,IF(CE3=Цены!$H$22,Цены!$L$22,IF(CE3=Цены!$H$23,Цены!$L$23,IF(CE3=Цены!$H$24,Цены!$L$24,IF(CE3=Цены!$H$25,Цены!$L$25,IF(CE3=Цены!$H$26,Цены!$L$26,IF(CE3=Цены!$H$27,Цены!$L$27,IF(CE3=Цены!$H$28,Цены!$L$28,IF(CE3=Цены!$H$29,Цены!$L$29,IF(CE3=Цены!$H$30,Цены!$L$30,IF(CE3=Цены!$H$31,Цены!$L$31,IF(CE3=Цены!$H$32,Цены!$L$32,IF(CE3=Цены!$H$33,Цены!$L$33,IF(CE3=Цены!$H$34,Цены!$L$34,IF(CE3=Цены!$H$35,Цены!$L$35,IF(CE3=Цены!$H$36,Цены!$L$36,IF(CE3=Цены!$H$37,Цены!$L$37,IF(CE3=Цены!$H$38,Цены!$L$38,IF(CE3=Цены!$H$39,Цены!$L$39,IF(CE3=Цены!$H$40,Цены!$L$40,IF(CE3=Цены!$H$41,Цены!$L$41,IF(CE3=Цены!$H$42,Цены!$L$42,IF(CE3=Цены!$H$43,Цены!$L$43,IF(CE3=Цены!$H$44,Цены!$L$44,IF(CE3=Цены!$H$45,Цены!$L$45,IF(CE3=Цены!$H$46,Цены!$L$46,IF(CE3=Цены!$H$47,Цены!$L$47,IF(CE3=Цены!$H$48,Цены!$L$48,IF(CE3=Цены!$H$49,Цены!$L$49,IF(CE3=Цены!$H$50,Цены!$L$50,IF(CE3=Цены!$H$51,Цены!$L$51,IF(CE3=Цены!$H$52,Цены!$L$52,IF(CE3=Цены!$H$53,Цены!$L$53,IF(CE3=Цены!$H$54,Цены!$L$54,IF(CE3=Цены!$H$55,Цены!$L$55)))))))))))))))))))))))))))))))))))))))))))))))))))))) -> FALSE | CH3: =CF3*CG3+CF4*CG4+CF5*CG5+CF6*CG6 -> 1.2132 | CI3: =IF(CE3=Цены!$H$3,Цены!$K$3,IF(CE3=Цены!$H$4,Цены!$K$4,IF(CE3=Цены!$H$5,Цены!$K$5,IF(CE3=Цены!$H$6,Цены!$K$6,IF(CE3=Цены!$H$7,Цены!$K$7,IF(CE3=Цены!$H$8,Цены!$K$8,IF(CE3=Цены!$H$9,Цены!$K$9,IF(CE3=Цены!$H$10,Цены!$K$10,IF(CE3=Цены!$H$11,Цены!$K$11,IF(CE3=Цены!$H$12,Цены!$K$12,IF(CE3=Цены!$H$13,Цены!$K$13,IF(CE3=Цены!$H$14,Цены!$K$14,IF(CE3=Цены!$H$14,Цены!$K$14,IF(CE3=Цены!$H$15,Цены!$K$15,IF(CE3=Цены!$H$16,Цены!$K$16,IF(CE3=Цены!$H$17,Цены!$K$17,IF(CE3=Цены!$H$18,Цены!$K$18,IF(CE3=Цены!$H$19,Цены!$K$19,IF(CE3=Цены!$H$20,Цены!$K$20,IF(CE3=Цены!$H$21,Цены!$K$21,IF(CE3=Цены!$H$22,Цены!$K$22,IF(CE3=Цены!$H$23,Цены!$K$23,IF(CE3=Цены!$H$24,Цены!$K$24,IF(CE3=Цены!$H$25,Цены!$K$25,IF(CE3=Цены!$H$26,Цены!$K$26,IF(CE3=Цены!$H$27,Цены!$K$27,IF(CE3=Цены!$H$28,Цены!$K$28,IF(CE3=Цены!$H$29,Цены!$K$29,IF(CE3=Цены!$H$30,Цены!$K$30,IF(CE3=Цены!$H$31,Цены!$K$31,IF(CE3=Цены!$H$32,Цены!$K$32,IF(CE3=Цены!$H$33,Цены!$K$33,IF(CE3=Цены!$H$34,Цены!$K$34,IF(CE3=Цены!$H$35,Цены!$K$35,IF(CE3=Цены!$H$36,Цены!$K$36,IF(CE3=Цены!$H$37,Цены!$K$37,IF(CE3=Цены!$H$38,Цены!$K$38,IF(CE3=Цены!$H$39,Цены!$K$39,IF(CE3=Цены!$H$40,Цены!$K$40,IF(CE3=Цены!$H$41,Цены!$K$41,IF(CE3=Цены!$H$42,Цены!$K$42,IF(CE3=Цены!$H$43,Цены!$K$43,IF(CE3=Цены!$H$44,Цены!$K$44,IF(CE3=Цены!$H$45,Цены!$K$45,IF(CE3=Цены!$H$46,Цены!$K$46,IF(CE3=Цены!$H$47,Цены!$K$47,IF(CE3=Цены!$H$48,Цены!$K$48,IF(CE3=Цены!$H$49,Цены!$K$49,IF(CE3=Цены!$H$50,Цены!$K$50,IF(CE3=Цены!$H$51,Цены!$K$51,IF(CE3=Цены!$H$52,Цены!$K$52,IF(CE3=Цены!$H$53,Цены!$K$53,IF(CE3=Цены!$H$54,Цены!$K$54,IF(CE3=Цены!$H$55,Цены!$K$55)))))))))))))))))))))))))))))))))))))))))))))))))))))) -> FALSE | CJ3: 1.5 | CK3: 800 | CL3: =CF3*CI3+CF4*CI4+CF5*CI5+CF6*CI6 -> 386 | CM3: =CJ3*CK3 -> 1200 | CN3: =CL3+CM3 -> 1586 | CO3: =CJ3*CK3*1.1 -> 1320 | CP3: =CO3/CN3*100 -> 83.228247 | CQ3: =MROUND(CN3+CO3,500) -> 3000
D4: Skyline | E4: 5 | F4: =IF(D4=Цены!$H$3,Цены!$L$3,IF(D4=Цены!$H$4,Цены!$L$4,IF(D4=Цены!$H$5,Цены!$L$5,IF(D4=Цены!$H$6,Цены!$L$6,IF(D4=Цены!$H$7,Цены!$L$7,IF(D4=Цены!$H$8,Цены!$L$8,IF(D4=Цены!$H$9,Цены!$L$9,IF(D4=Цены!$H$10,Цены!$L$10,IF(D4=Цены!$H$11,Цены!$L$11,IF(D4=Цены!$H$12,Цены!$L$12,IF(D4=Цены!$H$13,Цены!$L$13,IF(D4=Цены!$H$14,Цены!$L$14,IF(D4=Цены!$H$14,Цены!$L$14,IF(D4=Цены!$H$15,Цены!$L$15,IF(D4=Цены!$H$16,Цены!$L$16,IF(D4=Цены!$H$17,Цены!$L$17,IF(D4=Цены!$H$18,Цены!$L$18,IF(D4=Цены!$H$19,Цены!$L$19,IF(D4=Цены!$H$20,Цены!$L$20,IF(D4=Цены!$H$21,Цены!$L$21,IF(D4=Цены!$H$22,Цены!$L$22,IF(D4=Цены!$H$23,Цены!$L$23,IF(D4=Цены!$H$24,Цены!$L$24,IF(D4=Цены!$H$25,Цены!$L$25,IF(D4=Цены!$H$26,Цены!$L$26,IF(D4=Цены!$H$27,Цены!$L$27,IF(D4=Цены!$H$28,Цены!$L$28,IF(D4=Цены!$H$29,Цены!$L$29,IF(D4=Цены!$H$30,Цены!$L$30,IF(D4=Цены!$H$31,Цены!$L$31,IF(D4=Цены!$H$32,Цены!$L$32,IF(D4=Цены!$H$33,Цены!$L$33,IF(D4=Цены!$H$34,Цены!$L$34,IF(D4=Цены!$H$35,Цены!$L$35,IF(D4=Цены!$H$36,Цены!$L$36,IF(D4=Цены!$H$37,Цены!$L$37,IF(D4=Цены!$H$38,Цены!$L$38,IF(D4=Цены!$H$39,Цены!$L$39,IF(D4=Цены!$H$40,Цены!$L$40,IF(D4=Цены!$H$41,Цены!$L$41,IF(D4=Цены!$H$42,Цены!$L$42,IF(D4=Цены!$H$43,Цены!$L$43,IF(D4=Цены!$H$44,Цены!$L$44,IF(D4=Цены!$H$45,Цены!$L$45,IF(D4=Цены!$H$46,Цены!$L$46,IF(D4=Цены!$H$47,Цены!$L$47,IF(D4=Цены!$H$48,Цены!$L$48,IF(D4=Цены!$H$49,Цены!$L$49,IF(D4=Цены!$H$50,Цены!$L$50,IF(D4=Цены!$H$51,Цены!$L$51,IF(D4=Цены!$H$52,Цены!$L$52,IF(D4=Цены!$H$53,Цены!$L$53,IF(D4=Цены!$H$54,Цены!$L$54,IF(D4=Цены!$H$55,Цены!$L$55)))))))))))))))))))))))))))))))))))))))))))))))))))))) -> 0.6 | H4: =IF(D4=Цены!$H$3,Цены!$K$3,IF(D4=Цены!$H$4,Цены!$K$4,IF(D4=Цены!$H$5,Цены!$K$5,IF(D4=Цены!$H$6,Цены!$K$6,IF(D4=Цены!$H$7,Цены!$K$7,IF(D4=Цены!$H$8,Цены!$K$8,IF(D4=Цены!$H$9,Цены!$K$9,IF(D4=Цены!$H$10,Цены!$K$10,IF(D4=Цены!$H$11,Цены!$K$11,IF(D4=Цены!$H$12,Цены!$K$12,IF(D4=Цены!$H$13,Цены!$K$13,IF(D4=Цены!$H$14,Цены!$K$14,IF(D4=Цены!$H$14,Цены!$K$14,IF(D4=Цены!$H$15,Цены!$K$15,IF(D4=Цены!$H$16,Цены!$K$16,IF(D4=Цены!$H$17,Цены!$K$17,IF(D4=Цены!$H$18,Цены!$K$18,IF(D4=Цены!$H$19,Цены!$K$19,IF(D4=Цены!$H$20,Цены!$K$20,IF(D4=Цены!$H$21,Цены!$K$21,IF(D4=Цены!$H$22,Цены!$K$22,IF(D4=Цены!$H$23,Цены!$K$23,IF(D4=Цены!$H$24,Цены!$K$24,IF(D4=Цены!$H$25,Цены!$K$25,IF(D4=Цены!$H$26,Цены!$K$26,IF(D4=Цены!$H$27,Цены!$K$27,IF(D4=Цены!$H$28,Цены!$K$28,IF(D4=Цены!$H$29,Цены!$K$29,IF(D4=Цены!$H$30,Цены!$K$30,IF(D4=Цены!$H$31,Цены!$K$31,IF(D4=Цены!$H$32,Цены!$K$32,IF(D4=Цены!$H$33,Цены!$K$33,IF(D4=Цены!$H$34,Цены!$K$34,IF(D4=Цены!$H$35,Цены!$K$35,IF(D4=Цены!$H$36,Цены!$K$36,IF(D4=Цены!$H$37,Цены!$K$37,IF(D4=Цены!$H$38,Цены!$K$38,IF(D4=Цены!$H$39,Цены!$K$39,IF(D4=Цены!$H$40,Цены!$K$40,IF(D4=Цены!$H$41,Цены!$K$41,IF(D4=Цены!$H$42,Цены!$K$42,IF(D4=Цены!$H$43,Цены!$K$43,IF(D4=Цены!$H$44,Цены!$K$44,IF(D4=Цены!$H$45,Цены!$K$45,IF(D4=Цены!$H$46,Цены!$K$46,IF(D4=Цены!$H$47,Цены!$K$47,IF(D4=Цены!$H$48,Цены!$K$48,IF(D4=Цены!$H$49,Цены!$K$49,IF(D4=Цены!$H$50,Цены!$K$50,IF(D4=Цены!$H$51,Цены!$K$51,IF(D4=Цены!$H$52,Цены!$K$52,IF(D4=Цены!$H$53,Цены!$K$53,IF(D4=Цены!$H$54,Цены!$K$54,IF(D4=Цены!$H$55,Цены!$K$55)))))))))))))))))))))))))))))))))))))))))))))))))))))) -> 166 | Q4: Defender | R4: 2 | S4: =IF(Q4=Цены!$H$3,Цены!$L$3,IF(Q4=Цены!$H$4,Цены!$L$4,IF(Q4=Цены!$H$5,Цены!$L$5,IF(Q4=Цены!$H$6,Цены!$L$6,IF(Q4=Цены!$H$7,Цены!$L$7,IF(Q4=Цены!$H$8,Цены!$L$8,IF(Q4=Цены!$H$9,Цены!$L$9,IF(Q4=Цены!$H$10,Цены!$L$10,IF(Q4=Цены!$H$11,Цены!$L$11,IF(Q4=Цены!$H$12,Цены!$L$12,IF(Q4=Цены!$H$13,Цены!$L$13,IF(Q4=Цены!$H$14,Цены!$L$14,IF(Q4=Цены!$H$14,Цены!$L$14,IF(Q4=Цены!$H$15,Цены!$L$15,IF(Q4=Цены!$H$16,Цены!$L$16,IF(Q4=Цены!$H$17,Цены!$L$17,IF(Q4=Цены!$H$18,Цены!$L$18,IF(Q4=Цены!$H$19,Цены!$L$19,IF(Q4=Цены!$H$20,Цены!$L$20,IF(Q4=Цены!$H$21,Цены!$L$21,IF(Q4=Цены!$H$22,Цены!$L$22,IF(Q4=Цены!$H$23,Цены!$L$23,IF(Q4=Цены!$H$24,Цены!$L$24,IF(Q4=Цены!$H$25,Цены!$L$25,IF(Q4=Цены!$H$26,Цены!$L$26,IF(Q4=Цены!$H$27,Цены!$L$27,IF(Q4=Цены!$H$28,Цены!$L$28,IF(Q4=Цены!$H$29,Цены!$L$29,IF(Q4=Цены!$H$30,Цены!$L$30,IF(Q4=Цены!$H$31,Цены!$L$31,IF(Q4=Цены!$H$32,Цены!$L$32,IF(Q4=Цены!$H$33,Цены!$L$33,IF(Q4=Цены!$H$34,Цены!$L$34,IF(Q4=Цены!$H$35,Цены!$L$35,IF(Q4=Цены!$H$36,Цены!$L$36,IF(Q4=Цены!$H$37,Цены!$L$37,IF(Q4=Цены!$H$38,Цены!$L$38,IF(Q4=Цены!$H$39,Цены!$L$39,IF(Q4=Цены!$H$40,Цены!$L$40,IF(Q4=Цены!$H$41,Цены!$L$41,IF(Q4=Цены!$H$42,Цены!$L$42,IF(Q4=Цены!$H$43,Цены!$L$43,IF(Q4=Цены!$H$44,Цены!$L$44,IF(Q4=Цены!$H$45,Цены!$L$45,IF(Q4=Цены!$H$46,Цены!$L$46,IF(Q4=Цены!$H$47,Цены!$L$47,IF(Q4=Цены!$H$48,Цены!$L$48,IF(Q4=Цены!$H$49,Цены!$L$49,IF(Q4=Цены!$H$50,Цены!$L$50,IF(Q4=Цены!$H$51,Цены!$L$51,IF(Q4=Цены!$H$52,Цены!$L$52,IF(Q4=Цены!$H$53,Цены!$L$53,IF(Q4=Цены!$H$54,Цены!$L$54,IF(Q4=Цены!$H$55,Цены!$L$55)))))))))))))))))))))))))))))))))))))))))))))))))))))) -> 0.64 | U4: =IF(Q4=Цены!$H$3,Цены!$K$3,IF(Q4=Цены!$H$4,Цены!$K$4,IF(Q4=Цены!$H$5,Цены!$K$5,IF(Q4=Цены!$H$6,Цены!$K$6,IF(Q4=Цены!$H$7,Цены!$K$7,IF(Q4=Цены!$H$8,Цены!$K$8,IF(Q4=Цены!$H$9,Цены!$K$9,IF(Q4=Цены!$H$10,Цены!$K$10,IF(Q4=Цены!$H$11,Цены!$K$11,IF(Q4=Цены!$H$12,Цены!$K$12,IF(Q4=Цены!$H$13,Цены!$K$13,IF(Q4=Цены!$H$14,Цены!$K$14,IF(Q4=Цены!$H$14,Цены!$K$14,IF(Q4=Цены!$H$15,Цены!$K$15,IF(Q4=Цены!$H$16,Цены!$K$16,IF(Q4=Цены!$H$17,Цены!$K$17,IF(Q4=Цены!$H$18,Цены!$K$18,IF(Q4=Цены!$H$19,Цены!$K$19,IF(Q4=Цены!$H$20,Цены!$K$20,IF(Q4=Цены!$H$21,Цены!$K$21,IF(Q4=Цены!$H$22,Цены!$K$22,IF(Q4=Цены!$H$23,Цены!$K$23,IF(Q4=Цены!$H$24,Цены!$K$24,IF(Q4=Цены!$H$25,Цены!$K$25,IF(Q4=Цены!$H$26,Цены!$K$26,IF(Q4=Цены!$H$27,Цены!$K$27,IF(Q4=Цены!$H$28,Цены!$K$28,IF(Q4=Цены!$H$29,Цены!$K$29,IF(Q4=Цены!$H$30,Цены!$K$30,IF(Q4=Цены!$H$31,Цены!$K$31,IF(Q4=Цены!$H$32,Цены!$K$32,IF(Q4=Цены!$H$33,Цены!$K$33,IF(Q4=Цены!$H$34,Цены!$K$34,IF(Q4=Цены!$H$35,Цены!$K$35,IF(Q4=Цены!$H$36,Цены!$K$36,IF(Q4=Цены!$H$37,Цены!$K$37,IF(Q4=Цены!$H$38,Цены!$K$38,IF(Q4=Цены!$H$39,Цены!$K$39,IF(Q4=Цены!$H$40,Цены!$K$40,IF(Q4=Цены!$H$41,Цены!$K$41,IF(Q4=Цены!$H$42,Цены!$K$42,IF(Q4=Цены!$H$43,Цены!$K$43,IF(Q4=Цены!$H$44,Цены!$K$44,IF(Q4=Цены!$H$45,Цены!$K$45,IF(Q4=Цены!$H$46,Цены!$K$46,IF(Q4=Цены!$H$47,Цены!$K$47,IF(Q4=Цены!$H$48,Цены!$K$48,IF(Q4=Цены!$H$49,Цены!$K$49,IF(Q4=Цены!$H$50,Цены!$K$50,IF(Q4=Цены!$H$51,Цены!$K$51,IF(Q4=Цены!$H$52,Цены!$K$52,IF(Q4=Цены!$H$53,Цены!$K$53,IF(Q4=Цены!$H$54,Цены!$K$54,IF(Q4=Цены!$H$55,Цены!$K$55)))))))))))))))))))))))))))))))))))))))))))))))))))))) -> 312 | AD4: G4 | AE4: 3 | AF4: =IF(AD4=Цены!$H$3,Цены!$L$3,IF(AD4=Цены!$H$4,Цены!$L$4,IF(AD4=Цены!$H$5,Цены!$L$5,IF(AD4=Цены!$H$6,Цены!$L$6,IF(AD4=Цены!$H$7,Цены!$L$7,IF(AD4=Цены!$H$8,Цены!$L$8,IF(AD4=Цены!$H$9,Цены!$L$9,IF(AD4=Цены!$H$10,Цены!$L$10,IF(AD4=Цены!$H$11,Цены!$L$11,IF(AD4=Цены!$H$12,Цены!$L$12,IF(AD4=Цены!$H$13,Цены!$L$13,IF(AD4=Цены!$H$14,Цены!$L$14,IF(AD4=Цены!$H$14,Цены!$L$14,IF(AD4=Цены!$H$15,Цены!$L$15,IF(AD4=Цены!$H$16,Цены!$L$16,IF(AD4=Цены!$H$17,Цены!$L$17,IF(AD4=Цены!$H$18,Цены!$L$18,IF(AD4=Цены!$H$19,Цены!$L$19,IF(AD4=Цены!$H$20,Цены!$L$20,IF(AD4=Цены!$H$21,Цены!$L$21,IF(AD4=Цены!$H$22,Цены!$L$22,IF(AD4=Цены!$H$23,Цены!$L$23,IF(AD4=Цены!$H$24,Цены!$L$24,IF(AD4=Цены!$H$25,Цены!$L$25,IF(AD4=Цены!$H$26,Цены!$L$26,IF(AD4=Цены!$H$27,Цены!$L$27,IF(AD4=Цены!$H$28,Цены!$L$28,IF(AD4=Цены!$H$29,Цены!$L$29,IF(AD4=Цены!$H$30,Цены!$L$30,IF(AD4=Цены!$H$31,Цены!$L$31,IF(AD4=Цены!$H$32,Цены!$L$32,IF(AD4=Цены!$H$33,Цены!$L$33,IF(AD4=Цены!$H$34,Цены!$L$34,IF(AD4=Цены!$H$35,Цены!$L$35,IF(AD4=Цены!$H$36,Цены!$L$36,IF(AD4=Цены!$H$37,Цены!$L$37,IF(AD4=Цены!$H$38,Цены!$L$38,IF(AD4=Цены!$H$39,Цены!$L$39,IF(AD4=Цены!$H$40,Цены!$L$40,IF(AD4=Цены!$H$41,Цены!$L$41,IF(AD4=Цены!$H$42,Цены!$L$42,IF(AD4=Цены!$H$43,Цены!$L$43,IF(AD4=Цены!$H$44,Цены!$L$44,IF(AD4=Цены!$H$45,Цены!$L$45,IF(AD4=Цены!$H$46,Цены!$L$46,IF(AD4=Цены!$H$47,Цены!$L$47,IF(AD4=Цены!$H$48,Цены!$L$48,IF(AD4=Цены!$H$49,Цены!$L$49,IF(AD4=Цены!$H$50,Цены!$L$50,IF(AD4=Цены!$H$51,Цены!$L$51,IF(AD4=Цены!$H$52,Цены!$L$52,IF(AD4=Цены!$H$53,Цены!$L$53,IF(AD4=Цены!$H$54,Цены!$L$54,IF(AD4=Цены!$H$55,Цены!$L$55)))))))))))))))))))))))))))))))))))))))))))))))))))))) -> 2.34 | AH4: =IF(AD4=Цены!$H$3,Цены!$K$3,IF(AD4=Цены!$H$4,Цены!$K$4,IF(AD4=Цены!$H$5,Цены!$K$5,IF(AD4=Цены!$H$6,Цены!$K$6,IF(AD4=Цены!$H$7,Цены!$K$7,IF(AD4=Цены!$H$8,Цены!$K$8,IF(AD4=Цены!$H$9,Цены!$K$9,IF(AD4=Цены!$H$10,Цены!$K$10,IF(AD4=Цены!$H$11,Цены!$K$11,IF(AD4=Цены!$H$12,Цены!$K$12,IF(AD4=Цены!$H$13,Цены!$K$13,IF(AD4=Цены!$H$14,Цены!$K$14,IF(AD4=Цены!$H$14,Цены!$K$14,IF(AD4=Цены!$H$15,Цены!$K$15,IF(AD4=Цены!$H$16,Цены!$K$16,IF(AD4=Цены!$H$17,Цены!$K$17,IF(AD4=Цены!$H$18,Цены!$K$18,IF(AD4=Цены!$H$19,Цены!$K$19,IF(AD4=Цены!$H$20,Цены!$K$20,IF(AD4=Цены!$H$21,Цены!$K$21,IF(AD4=Цены!$H$22,Цены!$K$22,IF(AD4=Цены!$H$23,Цены!$K$23,IF(AD4=Цены!$H$24,Цены!$K$24,IF(AD4=Цены!$H$25,Цены!$K$25,IF(AD4=Цены!$H$26,Цены!$K$26,IF(AD4=Цены!$H$27,Цены!$K$27,IF(AD4=Цены!$H$28,Цены!$K$28,IF(AD4=Цены!$H$29,Цены!$K$29,IF(AD4=Цены!$H$30,Цены!$K$30,IF(AD4=Цены!$H$31,Цены!$K$31,IF(AD4=Цены!$H$32,Цены!$K$32,IF(AD4=Цены!$H$33,Цены!$K$33,IF(AD4=Цены!$H$34,Цены!$K$34,IF(AD4=Цены!$H$35,Цены!$K$35,IF(AD4=Цены!$H$36,Цены!$K$36,IF(AD4=Цены!$H$37,Цены!$K$37,IF(AD4=Цены!$H$38,Цены!$K$38,IF(AD4=Цены!$H$39,Цены!$K$39,IF(AD4=Цены!$H$40,Цены!$K$40,IF(AD4=Цены!$H$41,Цены!$K$41,IF(AD4=Цены!$H$42,Цены!$K$42,IF(AD4=Цены!$H$43,Цены!$K$43,IF(AD4=Цены!$H$44,Цены!$K$44,IF(AD4=Цены!$H$45,Цены!$K$45,IF(AD4=Цены!$H$46,Цены!$K$46,IF(AD4=Цены!$H$47,Цены!$K$47,IF(AD4=Цены!$H$48,Цены!$K$48,IF(AD4=Цены!$H$49,Цены!$K$49,IF(AD4=Цены!$H$50,Цены!$K$50,IF(AD4=Цены!$H$51,Цены!$K$51,IF(AD4=Цены!$H$52,Цены!$K$52,IF(AD4=Цены!$H$53,Цены!$K$53,IF(AD4=Цены!$H$54,Цены!$K$54,IF(AD4=Цены!$H$55,Цены!$K$55)))))))))))))))))))))))))))))))))))))))))))))))))))))) -> 370.5 | AQ4: fusion | AR4: 2 | AS4: =IF(AQ4=Цены!$H$3,Цены!$L$3,IF(AQ4=Цены!$H$4,Цены!$L$4,IF(AQ4=Цены!$H$5,Цены!$L$5,IF(AQ4=Цены!$H$6,Цены!$L$6,IF(AQ4=Цены!$H$7,Цены!$L$7,IF(AQ4=Цены!$H$8,Цены!$L$8,IF(AQ4=Цены!$H$9,Цены!$L$9,IF(AQ4=Цены!$H$10,Цены!$L$10,IF(AQ4=Цены!$H$11,Цены!$L$11,IF(AQ4=Цены!$H$12,Цены!$L$12,IF(AQ4=Цены!$H$13,Цены!$L$13,IF(AQ4=Цены!$H$14,Цены!$L$14,IF(AQ4=Цены!$H$14,Цены!$L$14,IF(AQ4=Цены!$H$15,Цены!$L$15,IF(AQ4=Цены!$H$16,Цены!$L$16,IF(AQ4=Цены!$H$17,Цены!$L$17,IF(AQ4=Цены!$H$18,Цены!$L$18,IF(AQ4=Цены!$H$19,Цены!$L$19,IF(AQ4=Цены!$H$20,Цены!$L$20,IF(AQ4=Цены!$H$21,Цены!$L$21,IF(AQ4=Цены!$H$22,Цены!$L$22,IF(AQ4=Цены!$H$23,Цены!$L$23,IF(AQ4=Цены!$H$24,Цены!$L$24,IF(AQ4=Цены!$H$25,Цены!$L$25,IF(AQ4=Цены!$H$26,Цены!$L$26,IF(AQ4=Цены!$H$27,Цены!$L$27,IF(AQ4=Цены!$H$28,Цены!$L$28,IF(AQ4=Цены!$H$29,Цены!$L$29,IF(AQ4=Цены!$H$30,Цены!$L$30,IF(AQ4=Цены!$H$31,Цены!$L$31,IF(AQ4=Цены!$H$32,Цены!$L$32,IF(AQ4=Цены!$H$33,Цены!$L$33,IF(AQ4=Цены!$H$34,Цены!$L$34,IF(AQ4=Цены!$H$35,Цены!$L$35,IF(AQ4=Цены!$H$36,Цены!$L$36,IF(AQ4=Цены!$H$37,Цены!$L$37,IF(AQ4=Цены!$H$38,Цены!$L$38,IF(AQ4=Цены!$H$39,Цены!$L$39,IF(AQ4=Цены!$H$40,Цены!$L$40,IF(AQ4=Цены!$H$41,Цены!$L$41,IF(AQ4=Цены!$H$42,Цены!$L$42,IF(AQ4=Цены!$H$43,Цены!$L$43,IF(AQ4=Цены!$H$44,Цены!$L$44,IF(AQ4=Цены!$H$45,Цены!$L$45,IF(AQ4=Цены!$H$46,Цены!$L$46,IF(AQ4=Цены!$H$47,Цены!$L$47,IF(AQ4=Цены!$H$48,Цены!$L$48,IF(AQ4=Цены!$H$49,Цены!$L$49,IF(AQ4=Цены!$H$50,Цены!$L$50,IF(AQ4=Цены!$H$51,Цены!$L$51,IF(AQ4=Цены!$H$52,Цены!$L$52,IF(AQ4=Цены!$H$53,Цены!$L$53,IF(AQ4=Цены!$H$54,Цены!$L$54,IF(AQ4=Цены!$H$55,Цены!$L$55)))))))))))))))))))))))))))))))))))))))))))))))))))))) -> 0.19 | AU4: =IF(AQ4=Цены!$H$3,Цены!$K$3,IF(AQ4=Цены!$H$4,Цены!$K$4,IF(AQ4=Цены!$H$5,Цены!$K$5,IF(AQ4=Цены!$H$6,Цены!$K$6,IF(AQ4=Цены!$H$7,Цены!$K$7,IF(AQ4=Цены!$H$8,Цены!$K$8,IF(AQ4=Цены!$H$9,Цены!$K$9,IF(AQ4=Цены!$H$10,Цены!$K$10,IF(AQ4=Цены!$H$11,Цены!$K$11,IF(AQ4=Цены!$H$12,Цены!$K$12,IF(AQ4=Цены!$H$13,Цены!$K$13,IF(AQ4=Цены!$H$14,Цены!$K$14,IF(AQ4=Цены!$H$14,Цены!$K$14,IF(AQ4=Цены!$H$15,Цены!$K$15,IF(AQ4=Цены!$H$16,Цены!$K$16,IF(AQ4=Цены!$H$17,Цены!$K$17,IF(AQ4=Цены!$H$18,Цены!$K$18,IF(AQ4=Цены!$H$19,Цены!$K$19,IF(AQ4=Цены!$H$20,Цены!$K$20,IF(AQ4=Цены!$H$21,Цены!$K$21,IF(AQ4=Цены!$H$22,Цены!$K$22,IF(AQ4=Цены!$H$23,Цены!$K$23,IF(AQ4=Цены!$H$24,Цены!$K$24,IF(AQ4=Цены!$H$25,Цены!$K$25,IF(AQ4=Цены!$H$26,Цены!$K$26,IF(AQ4=Цены!$H$27,Цены!$K$27,IF(AQ4=Цены!$H$28,Цены!$K$28,IF(AQ4=Цены!$H$29,Цены!$K$29,IF(AQ4=Цены!$H$30,Цены!$K$30,IF(AQ4=Цены!$H$31,Цены!$K$31,IF(AQ4=Цены!$H$32,Цены!$K$32,IF(AQ4=Цены!$H$33,Цены!$K$33,IF(AQ4=Цены!$H$34,Цены!$K$34,IF(AQ4=Цены!$H$35,Цены!$K$35,IF(AQ4=Цены!$H$36,Цены!$K$36,IF(AQ4=Цены!$H$37,Цены!$K$37,IF(AQ4=Цены!$H$38,Цены!$K$38,IF(AQ4=Цены!$H$39,Цены!$K$39,IF(AQ4=Цены!$H$40,Цены!$K$40,IF(AQ4=Цены!$H$41,Цены!$K$41,IF(AQ4=Цены!$H$42,Цены!$K$42,IF(AQ4=Цены!$H$43,Цены!$K$43,IF(AQ4=Цены!$H$44,Цены!$K$44,IF(AQ4=Цены!$H$45,Цены!$K$45,IF(AQ4=Цены!$H$46,Цены!$K$46,IF(AQ4=Цены!$H$47,Цены!$K$47,IF(AQ4=Цены!$H$48,Цены!$K$48,IF(AQ4=Цены!$H$49,Цены!$K$49,IF(AQ4=Цены!$H$50,Цены!$K$50,IF(AQ4=Цены!$H$51,Цены!$K$51,IF(AQ4=Цены!$H$52,Цены!$K$52,IF(AQ4=Цены!$H$53,Цены!$K$53,IF(AQ4=Цены!$H$54,Цены!$K$54,IF(AQ4=Цены!$H$55,Цены!$K$55)))))))))))))))))))))))))))))))))))))))))))))))))))))) -> 448 | BE4: fusion | BF4: 2 | BG4: =IF(BE4=Цены!$H$3,Цены!$L$3,IF(BE4=Цены!$H$4,Цены!$L$4,IF(BE4=Цены!$H$5,Цены!$L$5,IF(BE4=Цены!$H$6,Цены!$L$6,IF(BE4=Цены!$H$7,Цены!$L$7,IF(BE4=Цены!$H$8,Цены!$L$8,IF(BE4=Цены!$H$9,Цены!$L$9,IF(BE4=Цены!$H$10,Цены!$L$10,IF(BE4=Цены!$H$11,Цены!$L$11,IF(BE4=Цены!$H$12,Цены!$L$12,IF(BE4=Цены!$H$13,Цены!$L$13,IF(BE4=Цены!$H$14,Цены!$L$14,IF(BE4=Цены!$H$14,Цены!$L$14,IF(BE4=Цены!$H$15,Цены!$L$15,IF(BE4=Цены!$H$16,Цены!$L$16,IF(BE4=Цены!$H$17,Цены!$L$17,IF(BE4=Цены!$H$18,Цены!$L$18,IF(BE4=Цены!$H$19,Цены!$L$19,IF(BE4=Цены!$H$20,Цены!$L$20,IF(BE4=Цены!$H$21,Цены!$L$21,IF(BE4=Цены!$H$22,Цены!$L$22,IF(BE4=Цены!$H$23,Цены!$L$23,IF(BE4=Цены!$H$24,Цены!$L$24,IF(BE4=Цены!$H$25,Цены!$L$25,IF(BE4=Цены!$H$26,Цены!$L$26,IF(BE4=Цены!$H$27,Цены!$L$27,IF(BE4=Цены!$H$28,Цены!$L$28,IF(BE4=Цены!$H$29,Цены!$L$29,IF(BE4=Цены!$H$30,Цены!$L$30,IF(BE4=Цены!$H$31,Цены!$L$31,IF(BE4=Цены!$H$32,Цены!$L$32,IF(BE4=Цены!$H$33,Цены!$L$33,IF(BE4=Цены!$H$34,Цены!$L$34,IF(BE4=Цены!$H$35,Цены!$L$35,IF(BE4=Цены!$H$36,Цены!$L$36,IF(BE4=Цены!$H$37,Цены!$L$37,IF(BE4=Цены!$H$38,Цены!$L$38,IF(BE4=Цены!$H$39,Цены!$L$39,IF(BE4=Цены!$H$40,Цены!$L$40,IF(BE4=Цены!$H$41,Цены!$L$41,IF(BE4=Цены!$H$42,Цены!$L$42,IF(BE4=Цены!$H$43,Цены!$L$43,IF(BE4=Цены!$H$44,Цены!$L$44,IF(BE4=Цены!$H$45,Цены!$L$45,IF(BE4=Цены!$H$46,Цены!$L$46,IF(BE4=Цены!$H$47,Цены!$L$47,IF(BE4=Цены!$H$48,Цены!$L$48,IF(BE4=Цены!$H$49,Цены!$L$49,IF(BE4=Цены!$H$50,Цены!$L$50,IF(BE4=Цены!$H$51,Цены!$L$51,IF(BE4=Цены!$H$52,Цены!$L$52,IF(BE4=Цены!$H$53,Цены!$L$53,IF(BE4=Цены!$H$54,Цены!$L$54,IF(BE4=Цены!$H$55,Цены!$L$55)))))))))))))))))))))))))))))))))))))))))))))))))))))) -> 0.19 | BI4: =IF(BE4=Цены!$H$3,Цены!$K$3,IF(BE4=Цены!$H$4,Цены!$K$4,IF(BE4=Цены!$H$5,Цены!$K$5,IF(BE4=Цены!$H$6,Цены!$K$6,IF(BE4=Цены!$H$7,Цены!$K$7,IF(BE4=Цены!$H$8,Цены!$K$8,IF(BE4=Цены!$H$9,Цены!$K$9,IF(BE4=Цены!$H$10,Цены!$K$10,IF(BE4=Цены!$H$11,Цены!$K$11,IF(BE4=Цены!$H$12,Цены!$K$12,IF(BE4=Цены!$H$13,Цены!$K$13,IF(BE4=Цены!$H$14,Цены!$K$14,IF(BE4=Цены!$H$14,Цены!$K$14,IF(BE4=Цены!$H$15,Цены!$K$15,IF(BE4=Цены!$H$16,Цены!$K$16,IF(BE4=Цены!$H$17,Цены!$K$17,IF(BE4=Цены!$H$18,Цены!$K$18,IF(BE4=Цены!$H$19,Цены!$K$19,IF(BE4=Цены!$H$20,Цены!$K$20,IF(BE4=Цены!$H$21,Цены!$K$21,IF(BE4=Цены!$H$22,Цены!$K$22,IF(BE4=Цены!$H$23,Цены!$K$23,IF(BE4=Цены!$H$24,Цены!$K$24,IF(BE4=Цены!$H$25,Цены!$K$25,IF(BE4=Цены!$H$26,Цены!$K$26,IF(BE4=Цены!$H$27,Цены!$K$27,IF(BE4=Цены!$H$28,Цены!$K$28,IF(BE4=Цены!$H$29,Цены!$K$29,IF(BE4=Цены!$H$30,Цены!$K$30,IF(BE4=Цены!$H$31,Цены!$K$31,IF(BE4=Цены!$H$32,Цены!$K$32,IF(BE4=Цены!$H$33,Цены!$K$33,IF(BE4=Цены!$H$34,Цены!$K$34,IF(BE4=Цены!$H$35,Цены!$K$35,IF(BE4=Цены!$H$36,Цены!$K$36,IF(BE4=Цены!$H$37,Цены!$K$37,IF(BE4=Цены!$H$38,Цены!$K$38,IF(BE4=Цены!$H$39,Цены!$K$39,IF(BE4=Цены!$H$40,Цены!$K$40,IF(BE4=Цены!$H$41,Цены!$K$41,IF(BE4=Цены!$H$42,Цены!$K$42,IF(BE4=Цены!$H$43,Цены!$K$43,IF(BE4=Цены!$H$44,Цены!$K$44,IF(BE4=Цены!$H$45,Цены!$K$45,IF(BE4=Цены!$H$46,Цены!$K$46,IF(BE4=Цены!$H$47,Цены!$K$47,IF(BE4=Цены!$H$48,Цены!$K$48,IF(BE4=Цены!$H$49,Цены!$K$49,IF(BE4=Цены!$H$50,Цены!$K$50,IF(BE4=Цены!$H$51,Цены!$K$51,IF(BE4=Цены!$H$52,Цены!$K$52,IF(BE4=Цены!$H$53,Цены!$K$53,IF(BE4=Цены!$H$54,Цены!$K$54,IF(BE4=Цены!$H$55,Цены!$K$55)))))))))))))))))))))))))))))))))))))))))))))))))))))) -> 448 | BR4: Skyline | BS4: 2 | BT4: =IF(BR4=Цены!$H$3,Цены!$L$3,IF(BR4=Цены!$H$4,Цены!$L$4,IF(BR4=Цены!$H$5,Цены!$L$5,IF(BR4=Цены!$H$6,Цены!$L$6,IF(BR4=Цены!$H$7,Цены!$L$7,IF(BR4=Цены!$H$8,Цены!$L$8,IF(BR4=Цены!$H$9,Цены!$L$9,IF(BR4=Цены!$H$10,Цены!$L$10,IF(BR4=Цены!$H$11,Цены!$L$11,IF(BR4=Цены!$H$12,Цены!$L$12,IF(BR4=Цены!$H$13,Цены!$L$13,IF(BR4=Цены!$H$14,Цены!$L$14,IF(BR4=Цены!$H$14,Цены!$L$14,IF(BR4=Цены!$H$15,Цены!$L$15,IF(BR4=Цены!$H$16,Цены!$L$16,IF(BR4=Цены!$H$17,Цены!$L$17,IF(BR4=Цены!$H$18,Цены!$L$18,IF(BR4=Цены!$H$19,Цены!$L$19,IF(BR4=Цены!$H$20,Цены!$L$20,IF(BR4=Цены!$H$21,Цены!$L$21,IF(BR4=Цены!$H$22,Цены!$L$22,IF(BR4=Цены!$H$23,Цены!$L$23,IF(BR4=Цены!$H$24,Цены!$L$24,IF(BR4=Цены!$H$25,Цены!$L$25,IF(BR4=Цены!$H$26,Цены!$L$26,IF(BR4=Цены!$H$27,Цены!$L$27,IF(BR4=Цены!$H$28,Цены!$L$28,IF(BR4=Цены!$H$29,Цены!$L$29,IF(BR4=Цены!$H$30,Цены!$L$30,IF(BR4=Цены!$H$31,Цены!$L$31,IF(BR4=Цены!$H$32,Цены!$L$32,IF(BR4=Цены!$H$33,Цены!$L$33,IF(BR4=Цены!$H$34,Цены!$L$34,IF(BR4=Цены!$H$35,Цены!$L$35,IF(BR4=Цены!$H$36,Цены!$L$36,IF(BR4=Цены!$H$37,Цены!$L$37,IF(BR4=Цены!$H$38,Цены!$L$38,IF(BR4=Цены!$H$39,Цены!$L$39,IF(BR4=Цены!$H$40,Цены!$L$40,IF(BR4=Цены!$H$41,Цены!$L$41,IF(BR4=Цены!$H$42,Цены!$L$42,IF(BR4=Цены!$H$43,Цены!$L$43,IF(BR4=Цены!$H$44,Цены!$L$44,IF(BR4=Цены!$H$45,Цены!$L$45,IF(BR4=Цены!$H$46,Цены!$L$46,IF(BR4=Цены!$H$47,Цены!$L$47,IF(BR4=Цены!$H$48,Цены!$L$48,IF(BR4=Цены!$H$49,Цены!$L$49,IF(BR4=Цены!$H$50,Цены!$L$50,IF(BR4=Цены!$H$51,Цены!$L$51,IF(BR4=Цены!$H$52,Цены!$L$52,IF(BR4=Цены!$H$53,Цены!$L$53,IF(BR4=Цены!$H$54,Цены!$L$54,IF(BR4=Цены!$H$55,Цены!$L$55)))))))))))))))))))))))))))))))))))))))))))))))))))))) -> 0.6 | BV4: =IF(BR4=Цены!$H$3,Цены!$K$3,IF(BR4=Цены!$H$4,Цены!$K$4,IF(BR4=Цены!$H$5,Цены!$K$5,IF(BR4=Цены!$H$6,Цены!$K$6,IF(BR4=Цены!$H$7,Цены!$K$7,IF(BR4=Цены!$H$8,Цены!$K$8,IF(BR4=Цены!$H$9,Цены!$K$9,IF(BR4=Цены!$H$10,Цены!$K$10,IF(BR4=Цены!$H$11,Цены!$K$11,IF(BR4=Цены!$H$12,Цены!$K$12,IF(BR4=Цены!$H$13,Цены!$K$13,IF(BR4=Цены!$H$14,Цены!$K$14,IF(BR4=Цены!$H$14,Цены!$K$14,IF(BR4=Цены!$H$15,Цены!$K$15,IF(BR4=Цены!$H$16,Цены!$K$16,IF(BR4=Цены!$H$17,Цены!$K$17,IF(BR4=Цены!$H$18,Цены!$K$18,IF(BR4=Цены!$H$19,Цены!$K$19,IF(BR4=Цены!$H$20,Цены!$K$20,IF(BR4=Цены!$H$21,Цены!$K$21,IF(BR4=Цены!$H$22,Цены!$K$22,IF(BR4=Цены!$H$23,Цены!$K$23,IF(BR4=Цены!$H$24,Цены!$K$24,IF(BR4=Цены!$H$25,Цены!$K$25,IF(BR4=Цены!$H$26,Цены!$K$26,IF(BR4=Цены!$H$27,Цены!$K$27,IF(BR4=Цены!$H$28,Цены!$K$28,IF(BR4=Цены!$H$29,Цены!$K$29,IF(BR4=Цены!$H$30,Цены!$K$30,IF(BR4=Цены!$H$31,Цены!$K$31,IF(BR4=Цены!$H$32,Цены!$K$32,IF(BR4=Цены!$H$33,Цены!$K$33,IF(BR4=Цены!$H$34,Цены!$K$34,IF(BR4=Цены!$H$35,Цены!$K$35,IF(BR4=Цены!$H$36,Цены!$K$36,IF(BR4=Цены!$H$37,Цены!$K$37,IF(BR4=Цены!$H$38,Цены!$K$38,IF(BR4=Цены!$H$39,Цены!$K$39,IF(BR4=Цены!$H$40,Цены!$K$40,IF(BR4=Цены!$H$41,Цены!$K$41,IF(BR4=Цены!$H$42,Цены!$K$42,IF(BR4=Цены!$H$43,Цены!$K$43,IF(BR4=Цены!$H$44,Цены!$K$44,IF(BR4=Цены!$H$45,Цены!$K$45,IF(BR4=Цены!$H$46,Цены!$K$46,IF(BR4=Цены!$H$47,Цены!$K$47,IF(BR4=Цены!$H$48,Цены!$K$48,IF(BR4=Цены!$H$49,Цены!$K$49,IF(BR4=Цены!$H$50,Цены!$K$50,IF(BR4=Цены!$H$51,Цены!$K$51,IF(BR4=Цены!$H$52,Цены!$K$52,IF(BR4=Цены!$H$53,Цены!$K$53,IF(BR4=Цены!$H$54,Цены!$K$54,IF(BR4=Цены!$H$55,Цены!$K$55)))))))))))))))))))))))))))))))))))))))))))))))))))))) -> 166 | CE4: Skyline | CF4: 2 | CG4: =IF(CE4=Цены!$H$3,Цены!$L$3,IF(CE4=Цены!$H$4,Цены!$L$4,IF(CE4=Цены!$H$5,Цены!$L$5,IF(CE4=Цены!$H$6,Цены!$L$6,IF(CE4=Цены!$H$7,Цены!$L$7,IF(CE4=Цены!$H$8,Цены!$L$8,IF(CE4=Цены!$H$9,Цены!$L$9,IF(CE4=Цены!$H$10,Цены!$L$10,IF(CE4=Цены!$H$11,Цены!$L$11,IF(CE4=Цены!$H$12,Цены!$L$12,IF(CE4=Цены!$H$13,Цены!$L$13,IF(CE4=Цены!$H$14,Цены!$L$14,IF(CE4=Цены!$H$14,Цены!$L$14,IF(CE4=Цены!$H$15,Цены!$L$15,IF(CE4=Цены!$H$16,Цены!$L$16,IF(CE4=Цены!$H$17,Цены!$L$17,IF(CE4=Цены!$H$18,Цены!$L$18,IF(CE4=Цены!$H$19,Цены!$L$19,IF(CE4=Цены!$H$20,Цены!$L$20,IF(CE4=Цены!$H$21,Цены!$L$21,IF(CE4=Цены!$H$22,Цены!$L$22,IF(CE4=Цены!$H$23,Цены!$L$23,IF(CE4=Цены!$H$24,Цены!$L$24,IF(CE4=Цены!$H$25,Цены!$L$25,IF(CE4=Цены!$H$26,Цены!$L$26,IF(CE4=Цены!$H$27,Цены!$L$27,IF(CE4=Цены!$H$28,Цены!$L$28,IF(CE4=Цены!$H$29,Цены!$L$29,IF(CE4=Цены!$H$30,Цены!$L$30,IF(CE4=Цены!$H$31,Цены!$L$31,IF(CE4=Цены!$H$32,Цены!$L$32,IF(CE4=Цены!$H$33,Цены!$L$33,IF(CE4=Цены!$H$34,Цены!$L$34,IF(CE4=Цены!$H$35,Цены!$L$35,IF(CE4=Цены!$H$36,Цены!$L$36,IF(CE4=Цены!$H$37,Цены!$L$37,IF(CE4=Цены!$H$38,Цены!$L$38,IF(CE4=Цены!$H$39,Цены!$L$39,IF(CE4=Цены!$H$40,Цены!$L$40,IF(CE4=Цены!$H$41,Цены!$L$41,IF(CE4=Цены!$H$42,Цены!$L$42,IF(CE4=Цены!$H$43,Цены!$L$43,IF(CE4=Цены!$H$44,Цены!$L$44,IF(CE4=Цены!$H$45,Цены!$L$45,IF(CE4=Цены!$H$46,Цены!$L$46,IF(CE4=Цены!$H$47,Цены!$L$47,IF(CE4=Цены!$H$48,Цены!$L$48,IF(CE4=Цены!$H$49,Цены!$L$49,IF(CE4=Цены!$H$50,Цены!$L$50,IF(CE4=Цены!$H$51,Цены!$L$51,IF(CE4=Цены!$H$52,Цены!$L$52,IF(CE4=Цены!$H$53,Цены!$L$53,IF(CE4=Цены!$H$54,Цены!$L$54,IF(CE4=Цены!$H$55,Цены!$L$55)))))))))))))))))))))))))))))))))))))))))))))))))))))) -> 0.6 | CI4: =IF(CE4=Цены!$H$3,Цены!$K$3,IF(CE4=Цены!$H$4,Цены!$K$4,IF(CE4=Цены!$H$5,Цены!$K$5,IF(CE4=Цены!$H$6,Цены!$K$6,IF(CE4=Цены!$H$7,Цены!$K$7,IF(CE4=Цены!$H$8,Цены!$K$8,IF(CE4=Цены!$H$9,Цены!$K$9,IF(CE4=Цены!$H$10,Цены!$K$10,IF(CE4=Цены!$H$11,Цены!$K$11,IF(CE4=Цены!$H$12,Цены!$K$12,IF(CE4=Цены!$H$13,Цены!$K$13,IF(CE4=Цены!$H$14,Цены!$K$14,IF(CE4=Цены!$H$14,Цены!$K$14,IF(CE4=Цены!$H$15,Цены!$K$15,IF(CE4=Цены!$H$16,Цены!$K$16,IF(CE4=Цены!$H$17,Цены!$K$17,IF(CE4=Цены!$H$18,Цены!$K$18,IF(CE4=Цены!$H$19,Цены!$K$19,IF(CE4=Цены!$H$20,Цены!$K$20,IF(CE4=Цены!$H$21,Цены!$K$21,IF(CE4=Цены!$H$22,Цены!$K$22,IF(CE4=Цены!$H$23,Цены!$K$23,IF(CE4=Цены!$H$24,Цены!$K$24,IF(CE4=Цены!$H$25,Цены!$K$25,IF(CE4=Цены!$H$26,Цены!$K$26,IF(CE4=Цены!$H$27,Цены!$K$27,IF(CE4=Цены!$H$28,Цены!$K$28,IF(CE4=Цены!$H$29,Цены!$K$29,IF(CE4=Цены!$H$30,Цены!$K$30,IF(CE4=Цены!$H$31,Цены!$K$31,IF(CE4=Цены!$H$32,Цены!$K$32,IF(CE4=Цены!$H$33,Цены!$K$33,IF(CE4=Цены!$H$34,Цены!$K$34,IF(CE4=Цены!$H$35,Цены!$K$35,IF(CE4=Цены!$H$36,Цены!$K$36,IF(CE4=Цены!$H$37,Цены!$K$37,IF(CE4=Цены!$H$38,Цены!$K$38,IF(CE4=Цены!$H$39,Цены!$K$39,IF(CE4=Цены!$H$40,Цены!$K$40,IF(CE4=Цены!$H$41,Цены!$K$41,IF(CE4=Цены!$H$42,Цены!$K$42,IF(CE4=Цены!$H$43,Цены!$K$43,IF(CE4=Цены!$H$44,Цены!$K$44,IF(CE4=Цены!$H$45,Цены!$K$45,IF(CE4=Цены!$H$46,Цены!$K$46,IF(CE4=Цены!$H$47,Цены!$K$47,IF(CE4=Цены!$H$48,Цены!$K$48,IF(CE4=Цены!$H$49,Цены!$K$49,IF(CE4=Цены!$H$50,Цены!$K$50,IF(CE4=Цены!$H$51,Цены!$K$51,IF(CE4=Цены!$H$52,Цены!$K$52,IF(CE4=Цены!$H$53,Цены!$K$53,IF(CE4=Цены!$H$54,Цены!$K$54,IF(CE4=Цены!$H$55,Цены!$K$55)))))))))))))))))))))))))))))))))))))))))))))))))))))) -> 166
