Workbook

Sheet Лист1
A1: Узел | B1: =12*60 -> 720 | C1: % от объема | D1: Работы | E1: Кол-во | F1: ФОТ, %
B2: =SUM(B8:B86) -> 870 | H2: 12000 | I2: ФОТ, руб | J2: GPM, % | K2: GP, руб | M2: 12000 | N2: ФОТ, руб | O2: GPM, % | P2: GP, руб | R2: 15000 | S2: ФОТ, руб | T2: GPM, % | U2: GP, руб | W2: 20000 | X2: ФОТ, руб | Y2: GPM, % | Z2: GP, руб | AB2: 30000 | AC2: ФОТ, руб | AD2: GPM, % | AE2: GP, руб | AG2: ФОТ | AH2: расч
H3: =SUM(I8:I86) -> 13825 | M3: =SUM(N8:N86) -> 13825 | R3: =SUM(S8:S86) -> 15575 | W3: =SUM(X8:X86) -> 20125 | AB3: =SUM(AC8:AC86) -> 31675 | AG3: ФОТ | AH3: факт
H4: =MROUND(H2/0.35,500) -> 34500 | M4: =MROUND(M2/0.35,500) -> 34500 | R4: =MROUND(R2/0.35,500) -> 43000 | W4: =MROUND(W2/0.35,500) -> 57000 | AB4: =MROUND(AB2/0.35,500) -> 85500 | AG4: Выручка | AH4: расч
H5: =SUM(H8:H86) -> 39500 | M5: =SUM(M8:M86) -> 39500 | R5: =SUM(R8:R86) -> 44500 | W5: =SUM(W8:W86) -> 57500 | AB5: =SUM(AB8:AB86) -> 90500 | AG5: Выручка | AH5: факт
C6: =SUM(C8:C86) -> 102 | H6: 1 класс | M6: 2 класс | R6: 3 класс | W6: 4 класс | AB6: 4+ класс
A8: Решетка радиатора | B8: 20 | C8: =MROUND(B8*100/$B$2,0.5) -> 2.5 | D8: Решетка радиатора съем | E8: 1 | F8: 35 | H8: =MROUND($H$4/100*C8,500) -> 1000 | I8: =H8/100*F8 -> 350 | J8: =(H8-K8)/H8*100 -> 35 | K8: =H8-I8 -> 650 | M8: =MROUND($M$4/100*C8,500) -> 1000 | N8: =M8/100*F8 -> 350 | O8: =(M8-P8)/M8*100 -> 35 | P8: =M8-N8 -> 650 | R8: =MROUND($R$4/100*C8,500) -> 1000 | S8: =R8/100*F8 -> 350 | T8: =(R8-U8)/R8*100 -> 35 | U8: =R8-S8 -> 650 | W8: =MROUND($W$4/100*C8,500) -> 1500 | X8: =W8/100*F8 -> 525 | Y8: =(W8-Z8)/W8*100 -> 35 | Z8: =W8-X8 -> 975 | AB8: =MROUND($AB$4/100*C8,500) -> 2000 | AC8: =AB8/100*F8 -> 700 | AD8: =(AB8-AE8)/AB8*100 -> 35 | AE8: =AB8-AC8 -> 1300
C9: =MROUND(B9*100/$B$2,0.5) -> 0 | D9: Решетка радиатора разборка | E9: 1 | F9: 35 | H9: =MROUND($H$4/100*C9,500) -> 0 | I9: =H9/100*F9 -> 0 | J9: =(H9-K9)/H9*100 -> #DIV/0! | K9: =H9-I9 -> 0 | M9: =MROUND($M$4/100*C9,500) -> 0 | N9: =M9/100*F9 -> 0 | O9: =(M9-P9)/M9*100 -> #DIV/0! | P9: =M9-N9 -> 0 | R9: =MROUND($R$4/100*C9,500) -> 0 | S9: =R9/100*F9 -> 0 | T9: =(R9-U9)/R9*100 -> #DIV/0! | U9: =R9-S9 -> 0 | W9: =MROUND($W$4/100*C9,500) -> 0 | X9: =W9/100*F9 -> 0 | Y9: =(W9-Z9)/W9*100 -> #DIV/0! | Z9: =W9-X9 -> 0 | AB9: =MROUND($AB$4/100*C9,500) -> 0 | AC9: =AB9/100*F9 -> 0 | AD9: =(AB9-AE9)/AB9*100 -> #DIV/0! | AE9: =AB9-AC9 -> 0
C10: =MROUND(B10*100/$B$2,0.5) -> 0 | D10: Решетка радиатора сборка | E10: 1 | F10: 35 | H10: =MROUND($H$4/100*C10,500) -> 0 | I10: =H10/100*F10 -> 0 | J10: =(H10-K10)/H10*100 -> #DIV/0! | K10: =H10-I10 -> 0 | M10: =MROUND($M$4/100*C10,500) -> 0 | N10: =M10/100*F10 -> 0 | O10: =(M10-P10)/M10*100 -> #DIV/0! | P10: =M10-N10 -> 0 | R10: =MROUND($R$4/100*C10,500) -> 0 | S10: =R10/100*F10 -> 0 | T10: =(R10-U10)/R10*100 -> #DIV/0! | U10: =R10-S10 -> 0 | W10: =MROUND($W$4/100*C10,500) -> 0 | X10: =W10/100*F10 -> 0 | Y10: =(W10-Z10)/W10*100 -> #DIV/0! | Z10: =W10-X10 -> 0 | AB10: =MROUND($AB$4/100*C10,500) -> 0 | AC10: =AB10/100*F10 -> 0 | AD10: =(AB10-AE10)/AB10*100 -> #DIV/0! | AE10: =AB10-AC10 -> 0
B11: 20 | C11: =MROUND(B11*100/$B$2,0.5) -> 2.5 | D11: Решетка радиатора установка | E11: 1 | F11: 35 | H11: =MROUND($H$4/100*C11,500) -> 1000 | I11: =H11/100*F11 -> 350 | J11: =(H11-K11)/H11*100 -> 35 | K11: =H11-I11 -> 650 | M11: =MROUND($M$4/100*C11,500) -> 1000 | N11: =M11/100*F11 -> 350 | O11: =(M11-P11)/M11*100 -> 35 | P11: =M11-N11 -> 650 | R11: =MROUND($R$4/100*C11,500) -> 1000 | S11: =R11/100*F11 -> 350 | T11: =(R11-U11)/R11*100 -> 35 | U11: =R11-S11 -> 650 | W11: =MROUND($W$4/100*C11,500) -> 1500 | X11: =W11/100*F11 -> 525 | Y11: =(W11-Z11)/W11*100 -> 35 | Z11: =W11-X11 -> 975 | AB11: =MROUND($AB$4/100*C11,500) -> 2000 | AC11: =AB11/100*F11 -> 700 | AD11: =(AB11-AE11)/AB11*100 -> 35 | AE11: =AB11-AC11 -> 1300
A13: Передний бампер | B13: 30 | C13: =MROUND(B13*100/$B$2,0.5) -> 3.5 | D13: Передний бампер съем | E13: 1 | F13: 35 | H13: =MROUND($H$4/100*C13,500) -> 1000 | I13: =H13/100*F13 -> 350 | J13: =(H13-K13)/H13*100 -> 35 | K13: =H13-I13 -> 650 | M13: =MROUND($M$4/100*C13,500) -> 1000 | N13: =M13/100*F13 -> 350 | O13: =(M13-P13)/M13*100 -> 35 | P13: =M13-N13 -> 650 | R13: =MROUND($R$4/100*C13,500) -> 1500 | S13: =R13/100*F13 -> 525 | T13: =(R13-U13)/R13*100 -> 35 | U13: =R13-S13 -> 975 | W13: =MROUND($W$4/100*C13,500) -> 2000 | X13: =W13/100*F13 -> 700 | Y13: =(W13-Z13)/W13*100 -> 35 | Z13: =W13-X13 -> 1300 | AB13: =MROUND($AB$4/100*C13,500) -> 3000 | AC13: =AB13/100*F13 -> 1050 | AD13: =(AB13-AE13)/AB13*100 -> 35 | AE13: =AB13-AC13 -> 1950
B14: 20 | C14: =MROUND(B14*100/$B$2,0.5) -> 2.5 | D14: Передний бампер разборка | E14: 1 | F14: 35 | H14: =MROUND($H$4/100*C14,500) -> 1000 | I14: =H14/100*F14 -> 350 | J14: =(H14-K14)/H14*100 -> 35 | K14: =H14-I14 -> 650 | M14: =MROUND($M$4/100*C14,500) -> 1000 | N14: =M14/100*F14 -> 350 | O14: =(M14-P14)/M14*100 -> 35 | P14: =M14-N14 -> 650 | R14: =MROUND($R$4/100*C14,500) -> 1000 | S14: =R14/100*F14 -> 350 | T14: =(R14-U14)/R14*100 -> 35 | U14: =R14-S14 -> 650 | W14: =MROUND($W$4/100*C14,500) -> 1500 | X14: =W14/100*F14 -> 525 | Y14: =(W14-Z14)/W14*100 -> 35 | Z14: =W14-X14 -> 975 | AB14: =MROUND($AB$4/100*C14,500) -> 2000 | AC14: =AB14/100*F14 -> 700 | AD14: =(AB14-AE14)/AB14*100 -> 35 | AE14: =AB14-AC14 -> 1300
B15: 20 | C15: =MROUND(B15*100/$B$2,0.5) -> 2.5 | D15: Передний бампер сборка | E15: 1 | F15: 35 | H15: =MROUND($H$4/100*C15,500) -> 1000 | I15: =H15/100*F15 -> 350 | J15: =(H15-K15)/H15*100 -> 35 | K15: =H15-I15 -> 650 | M15: =MROUND($M$4/100*C15,500) -> 1000 | N15: =M15/100*F15 -> 350 | O15: =(M15-P15)/M15*100 -> 35 | P15: =M15-N15 -> 650 | R15: =MROUND($R$4/100*C15,500) -> 1000 | S15: =R15/100*F15 -> 350 | T15: =(R15-U15)/R15*100 -> 35 | U15: =R15-S15 -> 650 | W15: =MROUND($W$4/100*C15,500) -> 1500 | X15: =W15/100*F15 -> 525 | Y15: =(W15-Z15)/W15*100 -> 35 | Z15: =W15-X15 -> 975 | AB15: =MROUND($AB$4/100*C15,500) -> 2000 | AC15: =AB15/100*F15 -> 700 | AD15: =(AB15-AE15)/AB15*100 -> 35 | AE15: =AB15-AC15 -> 1300
B16: 30 | C16: =MROUND(B16*100/$B$2,0.5) -> 3.5 | D16: Передний бампер установка | E16: 1 | F16: 35 | H16: =MROUND($H$4/100*C16,500) -> 1000 | I16: =H16/100*F16 -> 350 | J16: =(H16-K16)/H16*100 -> 35 | K16: =H16-I16 -> 650 | M16: =MROUND($M$4/100*C16,500) -> 1000 | N16: =M16/100*F16 -> 350 | O16: =(M16-P16)/M16*100 -> 35 | P16: =M16-N16 -> 650 | R16: =MROUND($R$4/100*C16,500) -> 1500 | S16: =R16/100*F16 -> 525 | T16: =(R16-U16)/R16*100 -> 35 | U16: =R16-S16 -> 975 | W16: =MROUND($W$4/100*C16,500) -> 2000 | X16: =W16/100*F16 -> 700 | Y16: =(W16-Z16)/W16*100 -> 35 | Z16: =W16-X16 -> 1300 | AB16: =MROUND($AB$4/100*C16,500) -> 3000 | AC16: =AB16/100*F16 -> 1050 | AD16: =(AB16-AE16)/AB16*100 -> 35 | AE16: =AB16-AC16 -> 1950
A18: Пороги | B18: 25 | C18: =MROUND(B18*100/$B$2,0.5) -> 3 | D18: Пороги внешние съем | E18: 2 | F18: 35 | H18: =MROUND($H$4/100*C18,500) -> 1000 | I18: =H18/100*F18 -> 350 | J18: =(H18-K18)/H18*100 -> 35 | K18: =H18-I18 -> 650 | M18: =MROUND($M$4/100*C18,500) -> 1000 | N18: =M18/100*F18 -> 350 | O18: =(M18-P18)/M18*100 -> 35 | P18: =M18-N18 -> 650 | R18: =MROUND($R$4/100*C18,500) -> 1500 | S18: =R18/100*F18 -> 525 | T18: =(R18-U18)/R18*100 -> 35 | U18: =R18-S18 -> 975 | W18: =MROUND($W$4/100*C18,500) -> 1500 | X18: =W18/100*F18 -> 525 | Y18: =(W18-Z18)/W18*100 -> 35 | Z18: =W18-X18 -> 975 | AB18: =MROUND($AB$4/100*C18,500) -> 2500 | AC18: =AB18/100*F18 -> 875 | AD18: =(AB18-AE18)/AB18*100 -> 35 | AE18: =AB18-AC18 -> 1625
C19: =MROUND(B19*100/$B$2,0.5) -> 0 | D19: Пороги внешние разборка | E19: 2 | F19: 35 | H19: =MROUND($H$4/100*C19,500) -> 0 | I19: =H19/100*F19 -> 0 | J19: =(H19-K19)/H19*100 -> #DIV/0! | K19: =H19-I19 -> 0 | M19: =MROUND($M$4/100*C19,500) -> 0 | N19: =M19/100*F19 -> 0 | O19: =(M19-P19)/M19*100 -> #DIV/0! | P19: =M19-N19 -> 0 | R19: =MROUND($R$4/100*C19,500) -> 0 | S19: =R19/100*F19 -> 0 | T19: =(R19-U19)/R19*100 -> #DIV/0! | U19: =R19-S19 -> 0 | W19: =MROUND($W$4/100*C19,500) -> 0 | X19: =W19/100*F19 -> 0 | Y19: =(W19-Z19)/W19*100 -> #DIV/0! | Z19: =W19-X19 -> 0 | AB19: =MROUND($AB$4/100*C19,500) -> 0 | AC19: =AB19/100*F19 -> 0 | AD19: =(AB19-AE19)/AB19*100 -> #DIV/0! | AE19: =AB19-AC19 -> 0
C20: =MROUND(B20*100/$B$2,0.5) -> 0 | D20: Пороги внешние сборка | E20: 2 | F20: 35 | H20: =MROUND($H$4/100*C20,500) -> 0 | I20: =H20/100*F20 -> 0 | J20: =(H20-K20)/H20*100 -> #DIV/0! | K20: =H20-I20 -> 0 | M20: =MROUND($M$4/100*C20,500) -> 0 | N20: =M20/100*F20 -> 0 | O20: =(M20-P20)/M20*100 -> #DIV/0! | P20: =M20-N20 -> 0 | R20: =MROUND($R$4/100*C20,500) -> 0 | S20: =R20/100*F20 -> 0 | T20: =(R20-U20)/R20*100 -> #DIV/0! | U20: =R20-S20 -> 0 | W20: =MROUND($W$4/100*C20,500) -> 0 | X20: =W20/100*F20 -> 0 | Y20: =(W20-Z20)/W20*100 -> #DIV/0! | Z20: =W20-X20 -> 0 | AB20: =MROUND($AB$4/100*C20,500) -> 0 | AC20: =AB20/100*F20 -> 0 | AD20: =(AB20-AE20)/AB20*100 -> #DIV/0! | AE20: =AB20-AC20 -> 0
B21: 25 | C21: =MROUND(B21*100/$B$2,0.5) -> 3 | D21: Пороги внешние установка | E21: 2 | F21: 35 | H21: =MROUND($H$4/100*C21,500) -> 1000 | I21: =H21/100*F21 -> 350 | J21: =(H21-K21)/H21*100 -> 35 | K21: =H21-I21 -> 650 | M21: =MROUND($M$4/100*C21,500) -> 1000 | N21: =M21/100*F21 -> 350 | O21: =(M21-P21)/M21*100 -> 35 | P21: =M21-N21 -> 650 | R21: =MROUND($R$4/100*C21,500) -> 1500 | S21: =R21/100*F21 -> 525 | T21: =(R21-U21)/R21*100 -> 35 | U21: =R21-S21 -> 975 | W21: =MROUND($W$4/100*C21,500) -> 1500 | X21: =W21/100*F21 -> 525 | Y21: =(W21-Z21)/W21*100 -> 35 | Z21: =W21-X21 -> 975 | AB21: =MROUND($AB$4/100*C21,500) -> 2500 | AC21: =AB21/100*F21 -> 875 | AD21: =(AB21-AE21)/AB21*100 -> 35 | AE21: =AB21-AC21 -> 1625
A23: Задний бампер | B23: 15 | C23: =MROUND(B23*100/$B$2,0.5) -> 1.5 | D23: Задний бампер съем | E23: 1 | F23: 35 | H23: =MROUND($H$4/100*C23,500) -> 500 | I23: =H23/100*F23 -> 175 | J23: =(H23-K23)/H23*100 -> 35 | K23: =H23-I23 -> 325 | M23: =MROUND($M$4/100*C23,500) -> 500 | N23: =M23/100*F23 -> 175 | O23: =(M23-P23)/M23*100 -> 35 | P23: =M23-N23 -> 325 | R23: =MROUND($R$4/100*C23,500) -> 500 | S23: =R23/100*F23 -> 175 | T23: =(R23-U23)/R23*100 -> 35 | U23: =R23-S23 -> 325 | W23: =MROUND($W$4/100*C23,500) -> 1000 | X23: =W23/100*F23 -> 350 | Y23: =(W23-Z23)/W23*100 -> 35 | Z23: =W23-X23 -> 650 | AB23: =MROUND($AB$4/100*C23,500) -> 1500 | AC23: =AB23/100*F23 -> 525 | AD23: =(AB23-AE23)/AB23*100 -> 35 | AE23: =AB23-AC23 -> 975
B24: 25 | C24: =MROUND(B24*100/$B$2,0.5) -> 3 | D24: Задний бампер разборка | E24: 1 | F24: 35 | H24: =MROUND($H$4/100*C24,500) -> 1000 | I24: =H24/100*F24 -> 350 | J24: =(H24-K24)/H24*100 -> 35 | K24: =H24-I24 -> 650 | M24: =MROUND($M$4/100*C24,500) -> 1000 | N24: =M24/100*F24 -> 350 | O24: =(M24-P24)/M24*100 -> 35 | P24: =M24-N24 -> 650 | R24: =MROUND($R$4/100*C24,500) -> 1500 | S24: =R24/100*F24 -> 525 | T24: =(R24-U24)/R24*100 -> 35 | U24: =R24-S24 -> 975 | W24: =MROUND($W$4/100*C24,500) -> 1500 | X24: =W24/100*F24 -> 525 | Y24: =(W24-Z24)/W24*100 -> 35 | Z24: =W24-X24 -> 975 | AB24: =MROUND($AB$4/100*C24,500) -> 2500 | AC24: =AB24/100*F24 -> 875 | AD24: =(AB24-AE24)/AB24*100 -> 35 | AE24: =AB24-AC24 -> 1625
B25: 25 | C25: =MROUND(B25*100/$B$2,0.5) -> 3 | D25: Задний бампер сборка | E25: 1 | F25: 35 | H25: =MROUND($H$4/100*C25,500) -> 1000 | I25: =H25/100*F25 -> 350 | J25: =(H25-K25)/H25*100 -> 35 | K25: =H25-I25 -> 650 | M25: =MROUND($M$4/100*C25,500) -> 1000 | N25: =M25/100*F25 -> 350 | O25: =(M25-P25)/M25*100 -> 35 | P25: =M25-N25 -> 650 | R25: =MROUND($R$4/100*C25,500) -> 1500 | S25: =R25/100*F25 -> 525 | T25: =(R25-U25)/R25*100 -> 35 | U25: =R25-S25 -> 975 | W25: =MROUND($W$4/100*C25,500) -> 1500 | X25: =W25/100*F25 -> 525 | Y25: =(W25-Z25)/W25*100 -> 35 | Z25: =W25-X25 -> 975 | AB25: =MROUND($AB$4/100*C25,500) -> 2500 | AC25: =AB25/100*F25 -> 875 | AD25: =(AB25-AE25)/AB25*100 -> 35 | AE25: =AB25-AC25 -> 1625
B26: 15 | C26: =MROUND(B26*100/$B$2,0.5) -> 1.5 | D26: Задний бампер установка | E26: 1 | F26: 35 | H26: =MROUND($H$4/100*C26,500) -> 500 | I26: =H26/100*F26 -> 175 | J26: =(H26-K26)/H26*100 -> 35 | K26: =H26-I26 -> 325 | M26: =MROUND($M$4/100*C26,500) -> 500 | N26: =M26/100*F26 -> 175 | O26: =(M26-P26)/M26*100 -> 35 | P26: =M26-N26 -> 325 | R26: =MROUND($R$4/100*C26,500) -> 500 | S26: =R26/100*F26 -> 175 | T26: =(R26-U26)/R26*100 -> 35 | U26: =R26-S26 -> 325 | W26: =MROUND($W$4/100*C26,500) -> 1000 | X26: =W26/100*F26 -> 350 | Y26: =(W26-Z26)/W26*100 -> 35 | Z26: =W26-X26 -> 650 | AB26: =MROUND($AB$4/100*C26,500) -> 1500 | AC26: =AB26/100*F26 -> 525 | AD26: =(AB26-AE26)/AB26*100 -> 35 | AE26: =AB26-AC26 -> 975
A28: Спойлер | B28: 10 | C28: =MROUND(B28*100/$B$2,0.5) -> 1 | D28: Спойлер съем | E28: 1 | F28: 35 | H28: =MROUND($H$4/100*C28,500) -> 500 | I28: =H28/100*F28 -> 175 | J28: =(H28-K28)/H28*100 -> 35 | K28: =H28-I28 -> 325 | M28: =MROUND($M$4/100*C28,500) -> 500 | N28: =M28/100*F28 -> 175 | O28: =(M28-P28)/M28*100 -> 35 | P28: =M28-N28 -> 325 | R28: =MROUND($R$4/100*C28,500) -> 500 | S28: =R28/100*F28 -> 175 | T28: =(R28-U28)/R28*100 -> 35 | U28: =R28-S28 -> 325 | W28: =MROUND($W$4/100*C28,500) -> 500 | X28: =W28/100*F28 -> 175 | Y28: =(W28-Z28)/W28*100 -> 35 | Z28: =W28-X28 -> 325 | AB28: =MROUND($AB$4/100*C28,500) -> 1000 | AC28: =AB28/100*F28 -> 350 | AD28: =(AB28-AE28)/AB28*100 -> 35 | AE28: =AB28-AC28 -> 650
B29: 8 | C29: =MROUND(B29*100/$B$2,0.5) -> 1 | D29: Спойлер разборка | E29: 1 | F29: 35 | H29: =MROUND($H$4/100*C29,500) -> 500 | I29: =H29/100*F29 -> 175 | J29: =(H29-K29)/H29*100 -> 35 | K29: =H29-I29 -> 325 | M29: =MROUND($M$4/100*C29,500) -> 500 | N29: =M29/100*F29 -> 175 | O29: =(M29-P29)/M29*100 -> 35 | P29: =M29-N29 -> 325 | R29: =MROUND($R$4/100*C29,500) -> 500 | S29: =R29/100*F29 -> 175 | T29: =(R29-U29)/R29*100 -> 35 | U29: =R29-S29 -> 325 | W29: =MROUND($W$4/100*C29,500) -> 500 | X29: =W29/100*F29 -> 175 | Y29: =(W29-Z29)/W29*100 -> 35 | Z29: =W29-X29 -> 325 | AB29: =MROUND($AB$4/100*C29,500) -> 1000 | AC29: =AB29/100*F29 -> 350 | AD29: =(AB29-AE29)/AB29*100 -> 35 | AE29: =AB29-AC29 -> 650
B30: 8 | C30: =MROUND(B30*100/$B$2,0.5) -> 1 | D30: Спойлер сборка | E30: 1 | F30: 35 | H30: =MROUND($H$4/100*C30,500) -> 500 | I30: =H30/100*F30 -> 175 | J30: =(H30-K30)/H30*100 -> 35 | K30: =H30-I30 -> 325 | M30: =MROUND($M$4/100*C30,500) -> 500 | N30: =M30/100*F30 -> 175 | O30: =(M30-P30)/M30*100 -> 35 | P30: =M30-N30 -> 325 | R30: =MROUND($R$4/100*C30,500) -> 500 | S30: =R30/100*F30 -> 175 | T30: =(R30-U30)/R30*100 -> 35 | U30: =R30-S30 -> 325 | W30: =MROUND($W$4/100*C30,500) -> 500 | X30: =W30/100*F30 -> 175 | Y30: =(W30-Z30)/W30*100 -> 35 | Z30: =W30-X30 -> 325 | AB30: =MROUND($AB$4/100*C30,500) -> 1000 | AC30: =AB30/100*F30 -> 350 | AD30: =(AB30-AE30)/AB30*100 -> 35 | AE30: =AB30-AC30 -> 650
B31: 8 | C31: =MROUND(B31*100/$B$2,0.5) -> 1 | D31: Спойлер установка | E31: 1 | F31: 35 | H31: =MROUND($H$4/100*C31,500) -> 500 | I31: =H31/100*F31 -> 175 | J31: =(H31-K31)/H31*100 -> 35 | K31: =H31-I31 -> 325 | M31: =MROUND($M$4/100*C31,500) -> 500 | N31: =M31/100*F31 -> 175 | O31: =(M31-P31)/M31*100 -> 35 | P31: =M31-N31 -> 325 | R31: =MROUND($R$4/100*C31,500) -> 500 | S31: =R31/100*F31 -> 175 | T31: =(R31-U31)/R31*100 -> 35 | U31: =R31-S31 -> 325 | W31: =MROUND($W$4/100*C31,500) -> 500 | X31: =W31/100*F31 -> 175 | Y31: =(W31-Z31)/W31*100 -> 35 | Z31: =W31-X31 -> 325 | AB31: =MROUND($AB$4/100*C31,500) -> 1000 | AC31: =AB31/100*F31 -> 350 | AD31: =(AB31-AE31)/AB31*100 -> 35 | AE31: =AB31-AC31 -> 650
A33: Фара передняя | B33: 20 | C33: =MROUND(B33*100/$B$2,0.5) -> 2.5 | D33: Фара передняя съем | E33: 2 | F33: 35 | H33: =MROUND($H$4/100*C33,500) -> 1000 | I33: =H33/100*F33 -> 350 | J33: =(H33-K33)/H33*100 -> 35 | K33: =H33-I33 -> 650 | M33: =MROUND($M$4/100*C33,500) -> 1000 | N33: =M33/100*F33 -> 350 | O33: =(M33-P33)/M33*100 -> 35 | P33: =M33-N33 -> 650 | R33: =MROUND($R$4/100*C33,500) -> 1000 | S33: =R33/100*F33 -> 350 | T33: =(R33-U33)/R33*100 -> 35 | U33: =R33-S33 -> 650 | W33: =MROUND($W$4/100*C33,500) -> 1500 | X33: =W33/100*F33 -> 525 | Y33: =(W33-Z33)/W33*100 -> 35 | Z33: =W33-X33 -> 975 | AB33: =MROUND($AB$4/100*C33,500) -> 2000 | AC33: =AB33/100*F33 -> 700 | AD33: =(AB33-AE33)/AB33*100 -> 35 | AE33: =AB33-AC33 -> 1300
B34: 20 | C34: =MROUND(B34*100/$B$2,0.5) -> 2.5 | D34: фара передняя установка | E34: 2 | F34: 35 | H34: =MROUND($H$4/100*C34,500) -> 1000 | I34: =H34/100*F34 -> 350 | J34: =(H34-K34)/H34*100 -> 35 | K34: =H34-I34 -> 650 | M34: =MROUND($M$4/100*C34,500) -> 1000 | N34: =M34/100*F34 -> 350 | O34: =(M34-P34)/M34*100 -> 35 | P34: =M34-N34 -> 650 | R34: =MROUND($R$4/100*C34,500) -> 1000 | S34: =R34/100*F34 -> 350 | T34: =(R34-U34)/R34*100 -> 35 | U34: =R34-S34 -> 650 | W34: =MROUND($W$4/100*C34,500) -> 1500 | X34: =W34/100*F34 -> 525 | Y34: =(W34-Z34)/W34*100 -> 35 | Z34: =W34-X34 -> 975 | AB34: =MROUND($AB$4/100*C34,500) -> 2000 | AC34: =AB34/100*F34 -> 700 | AD34: =(AB34-AE34)/AB34*100 -> 35 | AE34: =AB34-AC34 -> 1300
A36: Фонарь задний | B36: 20 | C36: =MROUND(B36*100/$B$2,0.5) -> 2.5 | D36: Фонарь задний съем | E36: 2 | F36: 35 | H36: =MROUND($H$4/100*C36,500) -> 1000 | I36: =H36/100*F36 -> 350 | J36: =(H36-K36)/H36*100 -> 35 | K36: =H36-I36 -> 650 | M36: =MROUND($M$4/100*C36,500) -> 1000 | N36: =M36/100*F36 -> 350 | O36: =(M36-P36)/M36*100 -> 35 | P36: =M36-N36 -> 650 | R36: =MROUND($R$4/100*C36,500) -> 1000 | S36: =R36/100*F36 -> 350 | T36: =(R36-U36)/R36*100 -> 35 | U36: =R36-S36 -> 650 | W36: =MROUND($W$4/100*C36,500) -> 1500 | X36: =W36/100*F36 -> 525 | Y36: =(W36-Z36)/W36*100 -> 35 | Z36: =W36-X36 -> 975 | AB36: =MROUND($AB$4/100*C36,500) -> 2000 | AC36: =AB36/100*F36 -> 700 | AD36: =(AB36-AE36)/AB36*100 -> 35 | AE36: =AB36-AC36 -> 1300
B37: 20 | C37: =MROUND(B37*100/$B$2,0.5) -> 2.5 | D37: Фонарь задний установка | E37: 2 | F37: 35 | H37: =MROUND($H$4/100*C37,500) -> 1000 | I37: =H37/100*F37 -> 350 | J37: =(H37-K37)/H37*100 -> 35 | K37: =H37-I37 -> 650 | M37: =MROUND($M$4/100*C37,500) -> 1000 | N37: =M37/100*F37 -> 350 | O37: =(M37-P37)/M37*100 -> 35 | P37: =M37-N37 -> 650 | R37: =MROUND($R$4/100*C37,500) -> 1000 | S37: =R37/100*F37 -> 350 | T37: =(R37-U37)/R37*100 -> 35 | U37: =R37-S37 -> 650 | W37: =MROUND($W$4/100*C37,500) -> 1500 | X37: =W37/100*F37 -> 525 | Y37: =(W37-Z37)/W37*100 -> 35 | Z37: =W37-X37 -> 975 | AB37: =MROUND($AB$4/100*C37,500) -> 2000 | AC37: =AB37/100*F37 -> 700 | AD37: =(AB37-AE37)/AB37*100 -> 35 | AE37: =AB37-AC37 -> 1300
A39: Расширитель арки колеса | B39: 8 | C39: =MROUND(B39*100/$B$2,0.5) -> 1 | D39: Расширитель арки колеса съем/разборка | E39: 4 | F39: 35 | H39: =MROUND($H$4/100*C39,500) -> 500 | I39: =H39/100*F39 -> 175 | J39: =(H39-K39)/H39*100 -> 35 | K39: =H39-I39 -> 325 | M39: =MROUND($M$4/100*C39,500) -> 500 | N39: =M39/100*F39 -> 175 | O39: =(M39-P39)/M39*100 -> 35 | P39: =M39-N39 -> 325 | R39: =MROUND($R$4/100*C39,500) -> 500 | S39: =R39/100*F39 -> 175 | T39: =(R39-U39)/R39*100 -> 35 | U39: =R39-S39 -> 325 | W39: =MROUND($W$4/100*C39,500) -> 500 | X39: =W39/100*F39 -> 175 | Y39: =(W39-Z39)/W39*100 -> 35 | Z39: =W39-X39 -> 325 | AB39: =MROUND($AB$4/100*C39,500) -> 1000 | AC39: =AB39/100*F39 -> 350 | AD39: =(AB39-AE39)/AB39*100 -> 35 | AE39: =AB39-AC39 -> 650
B40: 12 | C40: =MROUND(B40*100/$B$2,0.5) -> 1.5 | D40: Расширитель арки колеса сборка/установка | E40: 4 | F40: 35 | H40: =MROUND($H$4/100*C40,500) -> 500 | I40: =H40/100*F40 -> 175 | J40: =(H40-K40)/H40*100 -> 35 | K40: =H40-I40 -> 325 | M40: =MROUND($M$4/100*C40,500) -> 500 | N40: =M40/100*F40 -> 175 | O40: =(M40-P40)/M40*100 -> 35 | P40: =M40-N40 -> 325 | R40: =MROUND($R$4/100*C40,500) -> 500 | S40: =R40/100*F40 -> 175 | T40: =(R40-U40)/R40*100 -> 35 | U40: =R40-S40 -> 325 | W40: =MROUND($W$4/100*C40,500) -> 1000 | X40: =W40/100*F40 -> 350 | Y40: =(W40-Z40)/W40*100 -> 35 | Z40: =W40-X40 -> 650 | AB40: =MROUND($AB$4/100*C40,500) -> 1500 | AC40: =AB40/100*F40 -> 525 | AD40: =(AB40-AE40)/AB40*100 -> 35 | AE40: =AB40-AC40 -> 975
A42: Люк бензобака | B42: 8 | C42: =MROUND(B42*100/$B$2,0.5) -> 1 | D42: Люк бензобака съем | E42: 1 | F42: 35 | H42: =MROUND($H$4/100*C42,500) -> 500 | I42: =H42/100*F42 -> 175 | J42: =(H42-K42)/H42*100 -> 35 | K42: =H42-I42 -> 325 | M42: =MROUND($M$4/100*C42,500) -> 500 | N42: =M42/100*F42 -> 175 | O42: =(M42-P42)/M42*100 -> 35 | P42: =M42-N42 -> 325 | R42: =MROUND($R$4/100*C42,500) -> 500 | S42: =R42/100*F42 -> 175 | T42: =(R42-U42)/R42*100 -> 35 | U42: =R42-S42 -> 325 | W42: =MROUND($W$4/100*C42,500) -> 500 | X42: =W42/100*F42 -> 175 | Y42: =(W42-Z42)/W42*100 -> 35 | Z42: =W42-X42 -> 325 | AB42: =MROUND($AB$4/100*C42,500) -> 1000 | AC42: =AB42/100*F42 -> 350 | AD42: =(AB42-AE42)/AB42*100 -> 35 | AE42: =AB42-AC42 -> 650
B43: 8 | C43: =MROUND(B43*100/$B$2,0.5) -> 1 | D43: Люк бензобака установка | E43: 1 | F43: 35 | H43: =MROUND($H$4/100*C43,500) -> 500 | I43: =H43/100*F43 -> 175 | J43: =(H43-K43)/H43*100 -> 35 | K43: =H43-I43 -> 325 | M43: =MROUND($M$4/100*C43,500) -> 500 | N43: =M43/100*F43 -> 175 | O43: =(M43-P43)/M43*100 -> 35 | P43: =M43-N43 -> 325 | R43: =MROUND($R$4/100*C43,500) -> 500 | S43: =R43/100*F43 -> 175 | T43: =(R43-U43)/R43*100 -> 35 | U43: =R43-S43 -> 325 | W43: =MROUND($W$4/100*C43,500) -> 500 | X43: =W43/100*F43 -> 175 | Y43: =(W43-Z43)/W43*100 -> 35 | Z43: =W43-X43 -> 325 | AB43: =MROUND($AB$4/100*C43,500) -> 1000 | AC43: =AB43/100*F43 -> 350 | AD43: =(AB43-AE43)/AB43*100 -> 35 | AE43: =AB43-AC43 -> 650
A45: Накладки двери | B45: 15 | C45: =MROUND(B45*100/$B$2,0.5) -> 1.5 | D45: Накладка двери съем/разборка | E45: 4 | F45: 35 | H45: =MROUND($H$4/100*C45,500) -> 500 | I45: =H45/100*F45 -> 175 | J45: =(H45-K45)/H45*100 -> 35 | K45: =H45-I45 -> 325 | M45: =MROUND($M$4/100*C45,500) -> 500 | N45: =M45/100*F45 -> 175 | O45: =(M45-P45)/M45*100 -> 35 | P45: =M45-N45 -> 325 | R45: =MROUND($R$4/100*C45,500) -> 500 | S45: =R45/100*F45 -> 175 | T45: =(R45-U45)/R45*100 -> 35 | U45: =R45-S45 -> 325 | W45: =MROUND($W$4/100*C45,500) -> 1000 | X45: =W45/100*F45 -> 350 | Y45: =(W45-Z45)/W45*100 -> 35 | Z45: =W45-X45 -> 650 | AB45: =MROUND($AB$4/100*C45,500) -> 1500 | AC45: =AB45/100*F45 -> 525 | AD45: =(AB45-AE45)/AB45*100 -> 35 | AE45: =AB45-AC45 -> 975
B46: 15 | C46: =MROUND(B46*100/$B$2,0.5) -> 1.5 | D46: Накладка двери сборка/установка | E46: 4 | F46: 35 | H46: =MROUND($H$4/100*C46,500) -> 500 | I46: =H46/100*F46 -> 175 | J46: =(H46-K46)/H46*100 -> 35 | K46: =H46-I46 -> 325 | M46: =MROUND($M$4/100*C46,500) -> 500 | N46: =M46/100*F46 -> 175 | O46: =(M46-P46)/M46*100 -> 35 | P46: =M46-N46 -> 325 | R46: =MROUND($R$4/100*C46,500) -> 500 | S46: =R46/100*F46 -> 175 | T46: =(R46-U46)/R46*100 -> 35 | U46: =R46-S46 -> 325 | W46: =MROUND($W$4/100*C46,500) -> 1000 | X46: =W46/100*F46 -> 350 | Y46: =(W46-Z46)/W46*100 -> 35 | Z46: =W46-X46 -> 650 | AB46: =MROUND($AB$4/100*C46,500) -> 1500 | AC46: =AB46/100*F46 -> 525 | AD46: =(AB46-AE46)/AB46*100 -> 35 | AE46: =AB46-AC46 -> 975
A48: Наружняя ручка двери | B48: 10 | C48: =MROUND(B48*100/$B$2,0.5) -> 1 | D48: Наружняя ручка двери съем/разборка | E48: 4 | F48: 35 | H48: =MROUND($H$4/100*C48,500) -> 500 | I48: =H48/100*F48 -> 175 | J48: =(H48-K48)/H48*100 -> 35 | K48: =H48-I48 -> 325 | M48: =MROUND($M$4/100*C48,500) -> 500 | N48: =M48/100*F48 -> 175 | O48: =(M48-P48)/M48*100 -> 35 | P48: =M48-N48 -> 325 | R48: =MROUND($R$4/100*C48,500) -> 500 | S48: =R48/100*F48 -> 175 | T48: =(R48-U48)/R48*100 -> 35 | U48: =R48-S48 -> 325 | W48: =MROUND($W$4/100*C48,500) -> 500 | X48: =W48/100*F48 -> 175 | Y48: =(W48-Z48)/W48*100 -> 35 | Z48: =W48-X48 -> 325 | AB48: =MROUND($AB$4/100*C48,500) -> 1000 | AC48: =AB48/100*F48 -> 350 | AD48: =(AB48-AE48)/AB48*100 -> 35 | AE48: =AB48-AC48 -> 650
B49: 10 | C49: =MROUND(B49*100/$B$2,0.5) -> 1 | D49: Наружняя ручка двери сборка/установка | E49: 4 | F49: 35 | H49: =MROUND($H$4/100*C49,500) -> 500 | I49: =H49/100*F49 -> 175 | J49: =(H49-K49)/H49*100 -> 35 | K49: =H49-I49 -> 325 | M49: =MROUND($M$4/100*C49,500) -> 500 | N49: =M49/100*F49 -> 175 | O49: =(M49-P49)/M49*100 -> 35 | P49: =M49-N49 -> 325 | R49: =MROUND($R$4/100*C49,500) -> 500 | S49: =R49/100*F49 -> 175 | T49: =(R49-U49)/R49*100 -> 35 | U49: =R49-S49 -> 325 | W49: =MROUND($W$4/100*C49,500) -> 500 | X49: =W49/100*F49 -> 175 | Y49: =(W49-Z49)/W49*100 -> 35 | Z49: =W49-X49 -> 325 | AB49: =MROUND($AB$4/100*C49,500) -> 1000 | AC49: =AB49/100*F49 -> 350 | AD49: =(AB49-AE49)/AB49*100 -> 35 | AE49: =AB49-AC49 -> 650
A51: Наружнее зеркало | B51: 10 | C51: =MROUND(B51*100/$B$2,0.5) -> 1 | D51: Наружнее зеркало съем | E51: 2 | F51: 35 | H51: =MROUND($H$4/100*C51,500) -> 500 | I51: =H51/100*F51 -> 175 | J51: =(H51-K51)/H51*100 -> 35 | K51: =H51-I51 -> 325 | M51: =MROUND($M$4/100*C51,500) -> 500 | N51: =M51/100*F51 -> 175 | O51: =(M51-P51)/M51*100 -> 35 | P51: =M51-N51 -> 325 | R51: =MROUND($R$4/100*C51,500) -> 500 | S51: =R51/100*F51 -> 175 | T51: =(R51-U51)/R51*100 -> 35 | U51: =R51-S51 -> 325 | W51: =MROUND($W$4/100*C51,500) -> 500 | X51: =W51/100*F51 -> 175 | Y51: =(W51-Z51)/W51*100 -> 35 | Z51: =W51-X51 -> 325 | AB51: =MROUND($AB$4/100*C51,500) -> 1000 | AC51: =AB51/100*F51 -> 350 | AD51: =(AB51-AE51)/AB51*100 -> 35 | AE51: =AB51-AC51 -> 650
C52: =MROUND(B52*100/$B$2,0.5) -> 0 | D52: Наружнее зеркало разборка | E52: 2 | F52: 35 | H52: =MROUND($H$4/100*C52,500) -> 0 | I52: =H52/100*F52 -> 0 | J52: =(H52-K52)/H52*100 -> #DIV/0! | K52: =H52-I52 -> 0 | M52: =MROUND($M$4/100*C52,500) -> 0 | N52: =M52/100*F52 -> 0 | O52: =(M52-P52)/M52*100 -> #DIV/0! | P52: =M52-N52 -> 0 | R52: =MROUND($R$4/100*C52,500) -> 0 | S52: =R52/100*F52 -> 0 | T52: =(R52-U52)/R52*100 -> #DIV/0! | U52: =R52-S52 -> 0 | W52: =MROUND($W$4/100*C52,500) -> 0 | X52: =W52/100*F52 -> 0 | Y52: =(W52-Z52)/W52*100 -> #DIV/0! | Z52: =W52-X52 -> 0 | AB52: =MROUND($AB$4/100*C52,500) -> 0 | AC52: =AB52/100*F52 -> 0 | AD52: =(AB52-AE52)/AB52*100 -> #DIV/0! | AE52: =AB52-AC52 -> 0
...

Sheet АРМАТУРНЫЕ РАБОТЫ
M2: ФОТ, % | N2: ФОТ, руб | O2: GPM, % | P2: GP, руб | S2: ФОТ, % | T2: ФОТ, руб | U2: GPM, % | V2: GP, руб | Y2: ФОТ, % | Z2: ФОТ, руб | AA2: GPM, % | AB2: GP, руб | AE2: ФОТ, % | AF2: ФОТ, руб | AG2: GPM, % | AH2: GP, руб | AK2: ФОТ, % | AL2: ФОТ, руб | AM2: GPM, % | AN2: GP, руб
B4: № п.п. | D4: ВИД РАБОТ | L4: СТОИМОСТЬ РАБОТ
L6: 1 класс | R6: 2 класс | X6: 3 класс | AD6: 4 класс | AJ6: 4+ класс
B8: АРМАТУРНЫЕ РАБОТЫ
B10: 1 | D10: БАМПЕР ЗАДНИЙ | H10: Задний бампер съем | L10: 1000 | M10: 35 | N10: =L10/100*M10 -> 350 | O10: =(L10-P10)/L10*100 -> 35 | P10: =L10-N10 -> 650 | R10: 1000 | S10: 35 | T10: =R10/100*S10 -> 350 | U10: =(R10-V10)/R10*100 -> 35 | V10: =R10-T10 -> 650 | X10: 1000 | Y10: 35 | Z10: =X10/100*Y10 -> 350 | AA10: =(X10-AB10)/X10*100 -> 35 | AB10: =X10-Z10 -> 650 | AD10: 1500 | AE10: 35 | AF10: =AD10/100*AE10 -> 525 | AG10: =(AD10-AH10)/AD10*100 -> 35 | AH10: =AD10-AF10 -> 975 | AJ10: 2000 | AK10: 35 | AL10: =AJ10/100*AK10 -> 700 | AM10: =(AJ10-AN10)/AJ10*100 -> 35 | AN10: =AJ10-AL10 -> 1300
H11: Задний бампер разборка | L11: 1000 | M11: 35 | N11: =L11/100*M11 -> 350 | O11: =(L11-P11)/L11*100 -> 35 | P11: =L11-N11 -> 650 | R11: 1000 | S11: 35 | T11: =R11/100*S11 -> 350 | U11: =(R11-V11)/R11*100 -> 35 | V11: =R11-T11 -> 650 | X11: 1000 | Y11: 35 | Z11: =X11/100*Y11 -> 350 | AA11: =(X11-AB11)/X11*100 -> 35 | AB11: =X11-Z11 -> 650 | AD11: 1500 | AE11: 35 | AF11: =AD11/100*AE11 -> 525 | AG11: =(AD11-AH11)/AD11*100 -> 35 | AH11: =AD11-AF11 -> 975 | AJ11: 2000 | AK11: 35 | AL11: =AJ11/100*AK11 -> 700 | AM11: =(AJ11-AN11)/AJ11*100 -> 35 | AN11: =AJ11-AL11 -> 1300
H12: Задний бампер сборка | L12: 1000 | M12: 35 | N12: =L12/100*M12 -> 350 | O12: =(L12-P12)/L12*100 -> 35 | P12: =L12-N12 -> 650 | R12: 1000 | S12: 35 | T12: =R12/100*S12 -> 350 | U12: =(R12-V12)/R12*100 -> 35 | V12: =R12-T12 -> 650 | X12: 1000 | Y12: 35 | Z12: =X12/100*Y12 -> 350 | AA12: =(X12-AB12)/X12*100 -> 35 | AB12: =X12-Z12 -> 650 | AD12: 1500 | AE12: 35 | AF12: =AD12/100*AE12 -> 525 | AG12: =(AD12-AH12)/AD12*100 -> 35 | AH12: =AD12-AF12 -> 975 | AJ12: 2000 | AK12: 35 | AL12: =AJ12/100*AK12 -> 700 | AM12: =(AJ12-AN12)/AJ12*100 -> 35 | AN12: =AJ12-AL12 -> 1300
H13: Задний бампер установка | L13: 1000 | M13: 35 | N13: =L13/100*M13 -> 350 | O13: =(L13-P13)/L13*100 -> 35 | P13: =L13-N13 -> 650 | R13: 1000 | S13: 35 | T13: =R13/100*S13 -> 350 | U13: =(R13-V13)/R13*100 -> 35 | V13: =R13-T13 -> 650 | X13: 1000 | Y13: 35 | Z13: =X13/100*Y13 -> 350 | AA13: =(X13-AB13)/X13*100 -> 35 | AB13: =X13-Z13 -> 650 | AD13: 1500 | AE13: 35 | AF13: =AD13/100*AE13 -> 525 | AG13: =(AD13-AH13)/AD13*100 -> 35 | AH13: =AD13-AF13 -> 975 | AJ13: 2000 | AK13: 35 | AL13: =AJ13/100*AK13 -> 700 | AM13: =(AJ13-AN13)/AJ13*100 -> 35 | AN13: =AJ13-AL13 -> 1300
B15: 2 | D15: БАМПЕР ПЕРЕДНИЙ | H15: Передний бампер съем | L15: 1000 | M15: 35 | N15: =L15/100*M15 -> 350 | O15: =(L15-P15)/L15*100 -> 35 | P15: =L15-N15 -> 650 | R15: 1000 | S15: 35 | T15: =R15/100*S15 -> 350 | U15: =(R15-V15)/R15*100 -> 35 | V15: =R15-T15 -> 650 | X15: 1500 | Y15: 35 | Z15: =X15/100*Y15 -> 525 | AA15: =(X15-AB15)/X15*100 -> 35 | AB15: =X15-Z15 -> 975 | AD15: 2000 | AE15: 35 | AF15: =AD15/100*AE15 -> 700 | AG15: =(AD15-AH15)/AD15*100 -> 35 | AH15: =AD15-AF15 -> 1300 | AJ15: 2500 | AK15: 35 | AL15: =AJ15/100*AK15 -> 875 | AM15: =(AJ15-AN15)/AJ15*100 -> 35 | AN15: =AJ15-AL15 -> 1625
H16: Передний бампер разборка | L16: 1000 | M16: 35 | N16: =L16/100*M16 -> 350 | O16: =(L16-P16)/L16*100 -> 35 | P16: =L16-N16 -> 650 | R16: 1000 | S16: 35 | T16: =R16/100*S16 -> 350 | U16: =(R16-V16)/R16*100 -> 35 | V16: =R16-T16 -> 650 | X16: 1000 | Y16: 35 | Z16: =X16/100*Y16 -> 350 | AA16: =(X16-AB16)/X16*100 -> 35 | AB16: =X16-Z16 -> 650 | AD16: 1500 | AE16: 35 | AF16: =AD16/100*AE16 -> 525 | AG16: =(AD16-AH16)/AD16*100 -> 35 | AH16: =AD16-AF16 -> 975 | AJ16: 2000 | AK16: 35 | AL16: =AJ16/100*AK16 -> 700 | AM16: =(AJ16-AN16)/AJ16*100 -> 35 | AN16: =AJ16-AL16 -> 1300
H17: Передний бампер сборка | L17: 1000 | M17: 35 | N17: =L17/100*M17 -> 350 | O17: =(L17-P17)/L17*100 -> 35 | P17: =L17-N17 -> 650 | R17: 1000 | S17: 35 | T17: =R17/100*S17 -> 350 | U17: =(R17-V17)/R17*100 -> 35 | V17: =R17-T17 -> 650 | X17: 1000 | Y17: 35 | Z17: =X17/100*Y17 -> 350 | AA17: =(X17-AB17)/X17*100 -> 35 | AB17: =X17-Z17 -> 650 | AD17: 1500 | AE17: 35 | AF17: =AD17/100*AE17 -> 525 | AG17: =(AD17-AH17)/AD17*100 -> 35 | AH17: =AD17-AF17 -> 975 | AJ17: 2000 | AK17: 35 | AL17: =AJ17/100*AK17 -> 700 | AM17: =(AJ17-AN17)/AJ17*100 -> 35 | AN17: =AJ17-AL17 -> 1300
H18: Передний бампер установка | L18: 1000 | M18: 35 | N18: =L18/100*M18 -> 350 | O18: =(L18-P18)/L18*100 -> 35 | P18: =L18-N18 -> 650 | R18: 1000 | S18: 35 | T18: =R18/100*S18 -> 350 | U18: =(R18-V18)/R18*100 -> 35 | V18: =R18-T18 -> 650 | X18: 1500 | Y18: 35 | Z18: =X18/100*Y18 -> 525 | AA18: =(X18-AB18)/X18*100 -> 35 | AB18: =X18-Z18 -> 975 | AD18: 2000 | AE18: 35 | AF18: =AD18/100*AE18 -> 700 | AG18: =(AD18-AH18)/AD18*100 -> 35 | AH18: =AD18-AF18 -> 1300 | AJ18: 2500 | AK18: 35 | AL18: =AJ18/100*AK18 -> 875 | AM18: =(AJ18-AN18)/AJ18*100 -> 35 | AN18: =AJ18-AL18 -> 1625
B20: 3 | D20: ДВЕРЬ | H20: Дверь съем | L20: 1000 | M20: 35 | N20: =L20/100*M20 -> 350 | O20: =(L20-P20)/L20*100 -> 35 | P20: =L20-N20 -> 650 | R20: 1000 | S20: 35 | T20: =R20/100*S20 -> 350 | U20: =(R20-V20)/R20*100 -> 35 | V20: =R20-T20 -> 650 | X20: 1500 | Y20: 35 | Z20: =X20/100*Y20 -> 525 | AA20: =(X20-AB20)/X20*100 -> 35 | AB20: =X20-Z20 -> 975 | AD20: 1500 | AE20: 35 | AF20: =AD20/100*AE20 -> 525 | AG20: =(AD20-AH20)/AD20*100 -> 35 | AH20: =AD20-AF20 -> 975 | AJ20: 2000 | AK20: 35 | AL20: =AJ20/100*AK20 -> 700 | AM20: =(AJ20-AN20)/AJ20*100 -> 35 | AN20: =AJ20-AL20 -> 1300
H21: Дверь установка | L21: 1000 | M21: 35 | N21: =L21/100*M21 -> 350 | O21: =(L21-P21)/L21*100 -> 35 | P21: =L21-N21 -> 650 | R21: 1000 | S21: 35 | T21: =R21/100*S21 -> 350 | U21: =(R21-V21)/R21*100 -> 35 | V21: =R21-T21 -> 650 | X21: 1500 | Y21: 35 | Z21: =X21/100*Y21 -> 525 | AA21: =(X21-AB21)/X21*100 -> 35 | AB21: =X21-Z21 -> 975 | AD21: 1500 | AE21: 35 | AF21: =AD21/100*AE21 -> 525 | AG21: =(AD21-AH21)/AD21*100 -> 35 | AH21: =AD21-AF21 -> 975 | AJ21: 2000 | AK21: 35 | AL21: =AJ21/100*AK21 -> 700 | AM21: =(AJ21-AN21)/AJ21*100 -> 35 | AN21: =AJ21-AL21 -> 1300
B23: 4 | D23: ДВЕРНАЯ КАРТА | H23: Дверная карта съем/разборка | L23: 500 | M23: 35 | N23: =L23/100*M23 -> 175 | O23: =(L23-P23)/L23*100 -> 35 | P23: =L23-N23 -> 325 | R23: 500 | S23: 35 | T23: =R23/100*S23 -> 175 | U23: =(R23-V23)/R23*100 -> 35 | V23: =R23-T23 -> 325 | X23: 500 | Y23: 35 | Z23: =X23/100*Y23 -> 175 | AA23: =(X23-AB23)/X23*100 -> 35 | AB23: =X23-Z23 -> 325 | AD23: 750 | AE23: 35 | AF23: =AD23/100*AE23 -> 262.5 | AG23: =(AD23-AH23)/AD23*100 -> 35 | AH23: =AD23-AF23 -> 487.5 | AJ23: 1000 | AK23: 35 | AL23: =AJ23/100*AK23 -> 350 | AM23: =(AJ23-AN23)/AJ23*100 -> 35 | AN23: =AJ23-AL23 -> 650
H24: Дверная карта сборка/установка | L24: 500 | M24: 35 | N24: =L24/100*M24 -> 175 | O24: =(L24-P24)/L24*100 -> 35 | P24: =L24-N24 -> 325 | R24: 500 | S24: 35 | T24: =R24/100*S24 -> 175 | U24: =(R24-V24)/R24*100 -> 35 | V24: =R24-T24 -> 325 | X24: 500 | Y24: 35 | Z24: =X24/100*Y24 -> 175 | AA24: =(X24-AB24)/X24*100 -> 35 | AB24: =X24-Z24 -> 325 | AD24: 750 | AE24: 35 | AF24: =AD24/100*AE24 -> 262.5 | AG24: =(AD24-AH24)/AD24*100 -> 35 | AH24: =AD24-AF24 -> 487.5 | AJ24: 1000 | AK24: 35 | AL24: =AJ24/100*AK24 -> 350 | AM24: =(AJ24-AN24)/AJ24*100 -> 35 | AN24: =AJ24-AL24 -> 650
B26: 5 | D26: ДИВАН | H26: Диван съем | L26: 500 | M26: 35 | N26: =L26/100*M26 -> 175 | O26: =(L26-P26)/L26*100 -> 35 | P26: =L26-N26 -> 325 | R26: 500 | S26: 35 | T26: =R26/100*S26 -> 175 | U26: =(R26-V26)/R26*100 -> 35 | V26: =R26-T26 -> 325 | X26: 500 | Y26: 35 | Z26: =X26/100*Y26 -> 175 | AA26: =(X26-AB26)/X26*100 -> 35 | AB26: =X26-Z26 -> 325 | AD26: 500 | AE26: 35 | AF26: =AD26/100*AE26 -> 175 | AG26: =(AD26-AH26)/AD26*100 -> 35 | AH26: =AD26-AF26 -> 325 | AJ26: 750 | AK26: 35 | AL26: =AJ26/100*AK26 -> 262.5 | AM26: =(AJ26-AN26)/AJ26*100 -> 35 | AN26: =AJ26-AL26 -> 487.5
H27: Диван установка | L27: 500 | M27: 35 | N27: =L27/100*M27 -> 175 | O27: =(L27-P27)/L27*100 -> 35 | P27: =L27-N27 -> 325 | R27: 500 | S27: 35 | T27: =R27/100*S27 -> 175 | U27: =(R27-V27)/R27*100 -> 35 | V27: =R27-T27 -> 325 | X27: 500 | Y27: 35 | Z27: =X27/100*Y27 -> 175 | AA27: =(X27-AB27)/X27*100 -> 35 | AB27: =X27-Z27 -> 325 | AD27: 500 | AE27: 35 | AF27: =AD27/100*AE27 -> 175 | AG27: =(AD27-AH27)/AD27*100 -> 35 | AH27: =AD27-AF27 -> 325 | AJ27: 750 | AK27: 35 | AL27: =AJ27/100*AK27 -> 262.5 | AM27: =(AJ27-AN27)/AJ27*100 -> 35 | AN27: =AJ27-AL27 -> 487.5
B29: 6 | D29: ЗАЩИТА ДВГАТЕЛЯ | H29: Защита двигателя съем | L29: 500 | M29: 35 | N29: =L29/100*M29 -> 175 | O29: =(L29-P29)/L29*100 -> 35 | P29: =L29-N29 -> 325 | R29: 500 | S29: 35 | T29: =R29/100*S29 -> 175 | U29: =(R29-V29)/R29*100 -> 35 | V29: =R29-T29 -> 325 | X29: 500 | Y29: 35 | Z29: =X29/100*Y29 -> 175 | AA29: =(X29-AB29)/X29*100 -> 35 | AB29: =X29-Z29 -> 325 | AD29: 1000 | AE29: 35 | AF29: =AD29/100*AE29 -> 350 | AG29: =(AD29-AH29)/AD29*100 -> 35 | AH29: =AD29-AF29 -> 650 | AJ29: 1500 | AK29: 35 | AL29: =AJ29/100*AK29 -> 525 | AM29: =(AJ29-AN29)/AJ29*100 -> 35 | AN29: =AJ29-AL29 -> 975
H30: Защита двигателя установка | L30: 500 | M30: 35 | N30: =L30/100*M30 -> 175 | O30: =(L30-P30)/L30*100 -> 35 | P30: =L30-N30 -> 325 | R30: 500 | S30: 35 | T30: =R30/100*S30 -> 175 | U30: =(R30-V30)/R30*100 -> 35 | V30: =R30-T30 -> 325 | X30: 500 | Y30: 35 | Z30: =X30/100*Y30 -> 175 | AA30: =(X30-AB30)/X30*100 -> 35 | AB30: =X30-Z30 -> 325 | AD30: 1000 | AE30: 35 | AF30: =AD30/100*AE30 -> 350 | AG30: =(AD30-AH30)/AD30*100 -> 35 | AH30: =AD30-AF30 -> 650 | AJ30: 1500 | AK30: 35 | AL30: =AJ30/100*AK30 -> 525 | AM30: =(AJ30-AN30)/AJ30*100 -> 35 | AN30: =AJ30-AL30 -> 975
B32: 7 | D32: ЗЕРКАЛО НАРУЖНЕЕ | H32: Наружнее зеркало съем | L32: 250 | M32: 35 | N32: =L32/100*M32 -> 87.5 | O32: =(L32-P32)/L32*100 -> 35 | P32: =L32-N32 -> 162.5 | R32: 250 | S32: 35 | T32: =R32/100*S32 -> 87.5 | U32: =(R32-V32)/R32*100 -> 35 | V32: =R32-T32 -> 162.5 | X32: 250 | Y32: 35 | Z32: =X32/100*Y32 -> 87.5 | AA32: =(X32-AB32)/X32*100 -> 35 | AB32: =X32-Z32 -> 162.5 | AD32: 300 | AE32: 35 | AF32: =AD32/100*AE32 -> 105 | AG32: =(AD32-AH32)/AD32*100 -> 35 | AH32: =AD32-AF32 -> 195 | AJ32: 300 | AK32: 35 | AL32: =AJ32/100*AK32 -> 105 | AM32: =(AJ32-AN32)/AJ32*100 -> 35 | AN32: =AJ32-AL32 -> 195
H33: Наружнее зеркало разборка | L33: 250 | M33: 35 | N33: =L33/100*M33 -> 87.5 | O33: =(L33-P33)/L33*100 -> 35 | P33: =L33-N33 -> 162.5 | R33: 250 | S33: 35 | T33: =R33/100*S33 -> 87.5 | U33: =(R33-V33)/R33*100 -> 35 | V33: =R33-T33 -> 162.5 | X33: 250 | Y33: 35 | Z33: =X33/100*Y33 -> 87.5 | AA33: =(X33-AB33)/X33*100 -> 35 | AB33: =X33-Z33 -> 162.5 | AD33: 300 | AE33: 35 | AF33: =AD33/100*AE33 -> 105 | AG33: =(AD33-AH33)/AD33*100 -> 35 | AH33: =AD33-AF33 -> 195 | AJ33: 500 | AK33: 35 | AL33: =AJ33/100*AK33 -> 175 | AM33: =(AJ33-AN33)/AJ33*100 -> 35 | AN33: =AJ33-AL33 -> 325
H34: Наружнее зеркало сборка | L34: 250 | M34: 35 | N34: =L34/100*M34 -> 87.5 | O34: =(L34-P34)/L34*100 -> 35 | P34: =L34-N34 -> 162.5 | R34: 250 | S34: 35 | T34: =R34/100*S34 -> 87.5 | U34: =(R34-V34)/R34*100 -> 35 | V34: =R34-T34 -> 162.5 | X34: 250 | Y34: 35 | Z34: =X34/100*Y34 -> 87.5 | AA34: =(X34-AB34)/X34*100 -> 35 | AB34: =X34-Z34 -> 162.5 | AD34: 300 | AE34: 35 | AF34: =AD34/100*AE34 -> 105 | AG34: =(AD34-AH34)/AD34*100 -> 35 | AH34: =AD34-AF34 -> 195 | AJ34: 500 | AK34: 35 | AL34: =AJ34/100*AK34 -> 175 | AM34: =(AJ34-AN34)/AJ34*100 -> 35 | AN34: =AJ34-AL34 -> 325
H35: Наружнее зеркало установка | L35: 250 | M35: 35 | N35: =L35/100*M35 -> 87.5 | O35: =(L35-P35)/L35*100 -> 35 | P35: =L35-N35 -> 162.5 | R35: 250 | S35: 35 | T35: =R35/100*S35 -> 87.5 | U35: =(R35-V35)/R35*100 -> 35 | V35: =R35-T35 -> 162.5 | X35: 250 | Y35: 35 | Z35: =X35/100*Y35 -> 87.5 | AA35: =(X35-AB35)/X35*100 -> 35 | AB35: =X35-Z35 -> 162.5 | AD35: 300 | AE35: 35 | AF35: =AD35/100*AE35 -> 105 | AG35: =(AD35-AH35)/AD35*100 -> 35 | AH35: =AD35-AF35 -> 195 | AJ35: 300 | AK35: 35 | AL35: =AJ35/100*AK35 -> 105 | AM35: =(AJ35-AN35)/AJ35*100 -> 35 | AN35: =AJ35-AL35 -> 195
B37: 8 | D37: КРЕСЛО | H37: Кресло съем | L37: 500 | M37: 35 | N37: =L37/100*M37 -> 175 | O37: =(L37-P37)/L37*100 -> 35 | P37: =L37-N37 -> 325 | R37: 750 | S37: 35 | T37: =R37/100*S37 -> 262.5 | U37: =(R37-V37)/R37*100 -> 35 | V37: =R37-T37 -> 487.5 | X37: 750 | Y37: 35 | Z37: =X37/100*Y37 -> 262.5 | AA37: =(X37-AB37)/X37*100 -> 35 | AB37: =X37-Z37 -> 487.5 | AD37: 1000 | AE37: 35 | AF37: =AD37/100*AE37 -> 350 | AG37: =(AD37-AH37)/AD37*100 -> 35 | AH37: =AD37-AF37 -> 650 | AJ37: 1500 | AK37: 35 | AL37: =AJ37/100*AK37 -> 525 | AM37: =(AJ37-AN37)/AJ37*100 -> 35 | AN37: =AJ37-AL37 -> 975
H38: Кресло установка | L38: 500 | M38: 35 | N38: =L38/100*M38 -> 175 | O38: =(L38-P38)/L38*100 -> 35 | P38: =L38-N38 -> 325 | R38: 750 | S38: 35 | T38: =R38/100*S38 -> 262.5 | U38: =(R38-V38)/R38*100 -> 35 | V38: =R38-T38 -> 487.5 | X38: 750 | Y38: 35 | Z38: =X38/100*Y38 -> 262.5 | AA38: =(X38-AB38)/X38*100 -> 35 | AB38: =X38-Z38 -> 487.5 | AD38: 1000 | AE38: 35 | AF38: =AD38/100*AE38 -> 350 | AG38: =(AD38-AH38)/AD38*100 -> 35 | AH38: =AD38-AF38 -> 650 | AJ38: 1500 | AK38: 35 | AL38: =AJ38/100*AK38 -> 525 | AM38: =(AJ38-AN38)/AJ38*100 -> 35 | AN38: =AJ38-AL38 -> 975
B40: 9 | D40: КАПОТ | H40: Капот съем | L40: 1000 | M40: 35 | N40: =L40/100*M40 -> 350 | O40: =(L40-P40)/L40*100 -> 35 | P40: =L40-N40 -> 650 | R40: 1500 | S40: 35 | T40: =R40/100*S40 -> 525 | U40: =(R40-V40)/R40*100 -> 35 | V40: =R40-T40 -> 975 | X40: 1500 | Y40: 35 | Z40: =X40/100*Y40 -> 525 | AA40: =(X40-AB40)/X40*100 -> 35 | AB40: =X40-Z40 -> 975 | AD40: 2000 | AE40: 35 | AF40: =AD40/100*AE40 -> 700 | AG40: =(AD40-AH40)/AD40*100 -> 35 | AH40: =AD40-AF40 -> 1300 | AJ40: 2500 | AK40: 35 | AL40: =AJ40/100*AK40 -> 875 | AM40: =(AJ40-AN40)/AJ40*100 -> 35 | AN40: =AJ40-AL40 -> 1625
H41: Капот установка | L41: 1000 | M41: 35 | N41: =L41/100*M41 -> 350 | O41: =(L41-P41)/L41*100 -> 35 | P41: =L41-N41 -> 650 | R41: 1500 | S41: 35 | T41: =R41/100*S41 -> 525 | U41: =(R41-V41)/R41*100 -> 35 | V41: =R41-T41 -> 975 | X41: 1500 | Y41: 35 | Z41: =X41/100*Y41 -> 525 | AA41: =(X41-AB41)/X41*100 -> 35 | AB41: =X41-Z41 -> 975 | AD41: 2000 | AE41: 35 | AF41: =AD41/100*AE41 -> 700 | AG41: =(AD41-AH41)/AD41*100 -> 35 | AH41: =AD41-AF41 -> 1300 | AJ41: 2500 | AK41: 35 | AL41: =AJ41/100*AK41 -> 875 | AM41: =(AJ41-AN41)/AJ41*100 -> 35 | AN41: =AJ41-AL41 -> 1625
B43: 10 | D43: КРЫЛО ПЕРЕДНЕЕ | H43: Крыло переднее съем | L43: 500 | M43: 35 | N43: =L43/100*M43 -> 175 | O43: =(L43-P43)/L43*100 -> 35 | P43: =L43-N43 -> 325 | R43: 500 | S43: 35 | T43: =R43/100*S43 -> 175 | U43: =(R43-V43)/R43*100 -> 35 | V43: =R43-T43 -> 325 | X43: 750 | Y43: 35 | Z43: =X43/100*Y43 -> 262.5 | AA43: =(X43-AB43)/X43*100 -> 35 | AB43: =X43-Z43 -> 487.5 | AD43: 750 | AE43: 35 | AF43: =AD43/100*AE43 -> 262.5 | AG43: =(AD43-AH43)/AD43*100 -> 35 | AH43: =AD43-AF43 -> 487.5 | AJ43: 1000 | AK43: 35 | AL43: =AJ43/100*AK43 -> 350 | AM43: =(AJ43-AN43)/AJ43*100 -> 35 | AN43: =AJ43-AL43 -> 650
H44: Крыло переднее установка | L44: 500 | M44: 35 | N44: =L44/100*M44 -> 175 | O44: =(L44-P44)/L44*100 -> 35 | P44: =L44-N44 -> 325 | R44: 500 | S44: 35 | T44: =R44/100*S44 -> 175 | U44: =(R44-V44)/R44*100 -> 35 | V44: =R44-T44 -> 325 | X44: 750 | Y44: 35 | Z44: =X44/100*Y44 -> 262.5 | AA44: =(X44-AB44)/X44*100 -> 35 | AB44: =X44-Z44 -> 487.5 | AD44: 750 | AE44: 35 | AF44: =AD44/100*AE44 -> 262.5 | AG44: =(AD44-AH44)/AD44*100 -> 35 | AH44: =AD44-AF44 -> 487.5 | AJ44: 1000 | AK44: 35 | AL44: =AJ44/100*AK44 -> 350 | AM44: =(AJ44-AN44)/AJ44*100 -> 35 | AN44: =AJ44-AL44 -> 650
B46: 11 | D46: КРЫШКА (ДВЕРЬ) БАГАЖНИКА | H46: Крышка (дверь) багажника съем | L46: 1000 | M46: 35 | N46: =L46/100*M46 -> 350 | O46: =(L46-P46)/L46*100 -> 35 | P46: =L46-N46 -> 650 | R46: 1500 | S46: 35 | T46: =R46/100*S46 -> 525 | U46: =(R46-V46)/R46*100 -> 35 | V46: =R46-T46 -> 975 | X46: 1500 | Y46: 35 | Z46: =X46/100*Y46 -> 525 | AA46: =(X46-AB46)/X46*100 -> 35 | AB46: =X46-Z46 -> 975 | AD46: 2000 | AE46: 35 | AF46: =AD46/100*AE46 -> 700 | AG46: =(AD46-AH46)/AD46*100 -> 35 | AH46: =AD46-AF46 -> 1300 | AJ46: 2500 | AK46: 35 | AL46: =AJ46/100*AK46 -> 875 | AM46: =(AJ46-AN46)/AJ46*100 -> 35 | AN46: =AJ46-AL46 -> 1625
H47: Крышка (дверь) багажника установка | L47: 1000 | M47: 35 | N47: =L47/100*M47 -> 350 | O47: =(L47-P47)/L47*100 -> 35 | P47: =L47-N47 -> 650 | R47: 1500 | S47: 35 | T47: =R47/100*S47 -> 525 | U47: =(R47-V47)/R47*100 -> 35 | V47: =R47-T47 -> 975 | X47: 1500 | Y47: 35 | Z47: =X47/100*Y47 -> 525 | AA47: =(X47-AB47)/X47*100 -> 35 | AB47: =X47-Z47 -> 975 | AD47: 2000 | AE47: 35 | AF47: =AD47/100*AE47 -> 700 | AG47: =(AD47-AH47)/AD47*100 -> 35 | AH47: =AD47-AF47 -> 1300 | AJ47: 2500 | AK47: 35 | AL47: =AJ47/100*AK47 -> 875 | AM47: =(AJ47-AN47)/AJ47*100 -> 35 | AN47: =AJ47-AL47 -> 1625
B49: 12 | D49: КОЛЕСО | H49: Колесо съем | L49: 250 | M49: 35 | N49: =L49/100*M49 -> 87.5 | O49: =(L49-P49)/L49*100 -> 35 | P49: =L49-N49 -> 162.5 | R49: 250 | S49: 35 | T49: =R49/100*S49 -> 87.5 | U49: =(R49-V49)/R49*100 -> 35 | V49: =R49-T49 -> 162.5 | X49: 350 | Y49: 35 | Z49: =X49/100*Y49 -> 122.5 | AA49: =(X49-AB49)/X49*100 -> 35 | AB49: =X49-Z49 -> 227.5 | AD49: 350 | AE49: 35 | AF49: =AD49/100*AE49 -> 122.5 | AG49: =(AD49-AH49)/AD49*100 -> 35 | AH49: =AD49-AF49 -> 227.5 | AJ49: 500
H50: Колесо установка | L50: 250 | M50: 35 | N50: =L50/100*M50 -> 87.5 | O50: =(L50-P50)/L50*100 -> 35 | P50: =L50-N50 -> 162.5 | R50: 250 | S50: 35 | T50: =R50/100*S50 -> 87.5 | U50: =(R50-V50)/R50*100 -> 35 | V50: =R50-T50 -> 162.5 | X50: 350 | Y50: 35 | Z50: =X50/100*Y50 -> 122.5 | AA50: =(X50-AB50)/X50*100 -> 35 | AB50: =X50-Z50 -> 227.5 | AD50: 350 | AE50: 35 | AF50: =AD50/100*AE50 -> 122.5 | AG50: =(AD50-AH50)/AD50*100 -> 35 | AH50: =AD50-AF50 -> 227.5 | AJ50: 500
B52: 13 | D52: ЛЮК БЕНЗОБАКА | H52: Люк бензобака съем | L52: 500 | M52: 35 | N52: =L52/100*M52 -> 175 | O52: =(L52-P52)/L52*100 -> 35 | P52: =L52-N52 -> 325 | R52: 500 | S52: 35 | T52: =R52/100*S52 -> 175 | U52: =(R52-V52)/R52*100 -> 35 | V52: =R52-T52 -> 325 | X52: 500 | Y52: 35 | Z52: =X52/100*Y52 -> 175 | AA52: =(X52-AB52)/X52*100 -> 35 | AB52: =X52-Z52 -> 325 | AD52: 500 | AE52: 35 | AF52: =AD52/100*AE52 -> 175 | AG52: =(AD52-AH52)/AD52*100 -> 35 | AH52: =AD52-AF52 -> 325 | AJ52: 750 | AK52: 35 | AL52: =AJ52/100*AK52 -> 262.5 | AM52: =(AJ52-AN52)/AJ52*100 -> 35 | AN52: =AJ52-AL52 -> 487.5
H53: Люк бензобака установка | L53: 500 | M53: 35 | N53: =L53/100*M53 -> 175 | O53: =(L53-P53)/L53*100 -> 35 | P53: =L53-N53 -> 325 | R53: 500 | S53: 35 | T53: =R53/100*S53 -> 175 | U53: =(R53-V53)/R53*100 -> 35 | V53: =R53-T53 -> 325 | X53: 500 | Y53: 35 | Z53: =X53/100*Y53 -> 175 | AA53: =(X53-AB53)/X53*100 -> 35 | AB53: =X53-Z53 -> 325 | AD53: 500 | AE53: 35 | AF53: =AD53/100*AE53 -> 175 | AG53: =(AD53-AH53)/AD53*100 -> 35 | AH53: =AD53-AF53 -> 325 | AJ53: 750 | AK53: 35 | AL53: =AJ53/100*AK53 -> 262.5 | AM53: =(AJ53-AN53)/AJ53*100 -> 35 | AN53: =AJ53-AL53 -> 487.5
B55: 14 | D55: ЛОКЕР | H55: Локер съем | L55: 250 | M55: 35 | N55: =L55/100*M55 -> 87.5 | O55: =(L55-P55)/L55*100 -> 35 | P55: =L55-N55 -> 162.5 | R55: 250 | S55: 35 | T55: =R55/100*S55 -> 87.5 | U55: =(R55-V55)/R55*100 -> 35 | V55: =R55-T55 -> 162.5 | X55: 300 | Y55: 35 | Z55: =X55/100*Y55 -> 105 | AA55: =(X55-AB55)/X55*100 -> 35 | AB55: =X55-Z55 -> 195 | AD55: 300 | AE55: 35 | AF55: =AD55/100*AE55 -> 105 | AG55: =(AD55-AH55)/AD55*100 -> 35 | AH55: =AD55-AF55 -> 195 | AJ55: 350 | AK55: 35 | AL55: =AJ55/100*AK55 -> 122.5 | AM55: =(AJ55-AN55)/AJ55*100 -> 35 | AN55: =AJ55-AL55 -> 227.5
H56: Локер установка | L56: 250 | M56: 35 | N56: =L56/100*M56 -> 87.5 | O56: =(L56-P56)/L56*100 -> 35 | P56: =L56-N56 -> 162.5 | R56: 250 | S56: 35 | T56: =R56/100*S56 -> 87.5 | U56: =(R56-V56)/R56*100 -> 35 | V56: =R56-T56 -> 162.5 | X56: 300 | Y56: 35 | Z56: =X56/100*Y56 -> 105 | AA56: =(X56-AB56)/X56*100 -> 35 | AB56: =X56-Z56 -> 195 | AD56: 300 | AE56: 35 | AF56: =AD56/100*AE56 -> 105 | AG56: =(AD56-AH56)/AD56*100 -> 35 | AH56: =AD56-AF56 -> 195 | AJ56: 350 | AK56: 35 | AL56: =AJ56/100*AK56 -> 122.5 | AM56: =(AJ56-AN56)/AJ56*100 -> 35 | AN56: =AJ56-AL56 -> 227.5
B58: 15 | D58: МОЛДИНГИ ОКОННЫЕ | H58: Оконные молдинги двери съем | L58: 500 | M58: 35 | N58: =L58/100*M58 -> 175 | O58: =(L58-P58)/L58*100 -> 35 | P58: =L58-N58 -> 325 | R58: 500 | S58: 35 | T58: =R58/100*S58 -> 175 | U58: =(R58-V58)/R58*100 -> 35 | V58: =R58-T58 -> 325 | X58: 500 | Y58: 35 | Z58: =X58/100*Y58 -> 175 | AA58: =(X58-AB58)/X58*100 -> 35 | AB58: =X58-Z58 -> 325 | AD58: 500 | AE58: 35 | AF58: =AD58/100*AE58 -> 175 | AG58: =(AD58-AH58)/AD58*100 -> 35 | AH58: =AD58-AF58 -> 325 | AJ58: 750 | AK58: 35 | AL58: =AJ58/100*AK58 -> 262.5 | AM58: =(AJ58-AN58)/AJ58*100 -> 35 | AN58: =AJ58-AL58 -> 487.5
H59: Оконные молдинги двери разборка | L59: 250 | M59: 35 | N59: =L59/100*M59 -> 87.5 | O59: =(L59-P59)/L59*100 -> 35 | P59: =L59-N59 -> 162.5 | R59: 250 | S59: 35 | T59: =R59/100*S59 -> 87.5 | U59: =(R59-V59)/R59*100 -> 35 | V59: =R59-T59 -> 162.5 | X59: 250 | Y59: 35 | Z59: =X59/100*Y59 -> 87.5 | AA59: =(X59-AB59)/X59*100 -> 35 | AB59: =X59-Z59 -> 162.5 | AD59: 300 | AE59: 35 | AF59: =AD59/100*AE59 -> 105 | AG59: =(AD59-AH59)/AD59*100 -> 35 | AH59: =AD59-AF59 -> 195 | AJ59: 500 | AK59: 35 | AL59: =AJ59/100*AK59 -> 175 | AM59: =(AJ59-AN59)/AJ59*100 -> 35 | AN59: =AJ59-AL59 -> 325
...

Sheet ТОНИРОВКА СТЕКОЛ
M2: ФОТ, % | N2: ФОТ, руб | O2: Материал | Q2: Доп. Работы | R2: GPM, % | S2: GP, руб | V2: ФОТ, % | W2: ФОТ, руб | X2: Материал | Z2: Доп. Работы | AA2: GPM, % | AB2: GP, руб | AE2: ФОТ, % | AF2: ФОТ, руб | AG2: Материал | AI2: Доп. Работы | AJ2: GPM, % | AK2: GP, руб | AN2: ФОТ, % | AO2: ФОТ, руб | AP2: Материал | AR2: Доп. Работы | AS2: GPM, % | AT2: GP, руб | AW2: ФОТ, % | AX2: ФОТ, руб | AY2: Материал | BA2: Доп. Работы | BB2: GPM, % | BC2: GP, руб
O3: Сумма | P3: Расход | X3: Сумма | Y3: Расход | AG3: Сумма | AH3: Расход | AP3: Сумма | AQ3: Расход | AY3: Сумма | AZ3: Расход
B5: № п.п. | D5: ВИД РАБОТ | L5: СТОИМОСТЬ с учетом арматурных работ
L7: 1 класс | U7: 2 класс | AD7: 3 класс | AM7: 4 класс | AV7: 4+ класс
B9: ТОНИРУЮЩАЯ ПЛЕНКА. СВЕТОПРОПУСКАЕМОСТЬ: 5%, 15%, 35%, 50%. SUNTEK (USA)
B11: 1 | D11: Лобовое стекло | L11: =MROUND(N11+O11+Q11+S11,500) -> 5500 | M11: =N11*100/L11 -> 21.818182 | N11: =2*$F$65 -> 1200 | O11: =P11*$F$57 -> 2000 | P11: 1.5 | R11: 40 | S11: =MROUND((N11+O11)*R11/(100-R11),100) -> 2100 | U11: =MROUND(W11+X11+Z11+AB11,500) -> 5500 | V11: =W11*100/U11 -> 21.818182 | W11: =2*$F$65 -> 1200 | X11: =Y11*$F$57 -> 2133.3333 | Y11: 1.6 | AA11: 40 | AB11: =MROUND((W11+X11)*AA11/(100-AA11),100) -> 2200 | AD11: =MROUND(AF11+AG11+AI11+AK11,500) -> 6000 | AE11: =AF11*100/AD11 -> 20 | AF11: =2*$F$65 -> 1200 | AG11: =AH11*$F$57 -> 2266.6667 | AH11: 1.7 | AJ11: 40 | AK11: =MROUND((AF11+AG11)*AJ11/(100-AJ11),100) -> 2300 | AM11: =MROUND(AO11+AP11+AR11+AT11,500) -> 6000 | AN11: =AO11*100/AM11 -> 20 | AO11: =2*$F$65 -> 1200 | AP11: =AQ11*$F$57 -> 2400 | AQ11: 1.8 | AS11: 40 | AT11: =MROUND((AO11+AP11)*AS11/(100-AS11),100) -> 2400 | AV11: =MROUND(AX11+AY11+BA11+BC11,500) -> 6500 | AW11: =AX11*100/AV11 -> 18.461538 | AX11: =2*$F$65 -> 1200 | AY11: =AZ11*$F$57 -> 2666.6667 | AZ11: 2 | BB11: 40 | BC11: =MROUND((AX11+AY11)*BB11/(100-BB11),100) -> 2600
B13: 2 | D13: Передние боковые | L13: =MROUND(N13+O13+Q13+S13,500) -> 6000 | M13: =N13*100/L13 -> 10 | N13: =1*$F$65 -> 600 | O13: =P13*$F$57 -> 1333.3333 | P13: 1 | Q13: =('АРМАТУРНЫЕ РАБОТЫ'!$L$23+'АРМАТУРНЫЕ РАБОТЫ'!$L$24+'АРМАТУРНЫЕ РАБОТЫ'!$L$115+'АРМАТУРНЫЕ РАБОТЫ'!$L$116)*2 -> 3000 | R13: 40 | S13: =MROUND((N13+O13)*R13/(100-R13),100) -> 1300 | U13: =MROUND(W13+X13+Z13+AB13,500) -> 7000 | V13: =W13*100/U13 -> 8.5714286 | W13: =1*$F$65 -> 600 | X13: =Y13*$F$57 -> 1733.3333 | Y13: 1.3 | Z13: =('АРМАТУРНЫЕ РАБОТЫ'!$R$23+'АРМАТУРНЫЕ РАБОТЫ'!$R$24+'АРМАТУРНЫЕ РАБОТЫ'!$R$115+'АРМАТУРНЫЕ РАБОТЫ'!$R$116)*2 -> 3000 | AA13: 40 | AB13: =MROUND((W13+X13)*AA13/(100-AA13),100) -> 1600 | AD13: =MROUND(AF13+AG13+AI13+AK13,500) -> 8000 | AE13: =AF13*100/AD13 -> 7.5 | AF13: =1*$F$65 -> 600 | AG13: =AH13*$F$57 -> 1866.6667 | AH13: 1.4 | AI13: =2*('АРМАТУРНЫЕ РАБОТЫ'!$X$23+'АРМАТУРНЫЕ РАБОТЫ'!$X$24+'АРМАТУРНЫЕ РАБОТЫ'!$X$115+'АРМАТУРНЫЕ РАБОТЫ'!$X$116) -> 3800 | AJ13: 40 | AK13: =MROUND((AF13+AG13)*AJ13/(100-AJ13),100) -> 1600 | AM13: =MROUND(AO13+AP13+AR13+AT13,500) -> 10500 | AN13: =AO13*100/AM13 -> 5.7142857 | AO13: =1*$F$65 -> 600 | AP13: =AQ13*$F$57 -> 2000 | AQ13: 1.5 | AR13: =2*('АРМАТУРНЫЕ РАБОТЫ'!$AD$23+'АРМАТУРНЫЕ РАБОТЫ'!$AD$24+'АРМАТУРНЫЕ РАБОТЫ'!$AD$115+'АРМАТУРНЫЕ РАБОТЫ'!$AD$116) -> 6000 | AS13: 40 | AT13: =MROUND((AO13+AP13)*AS13/(100-AS13),100) -> 1700 | AV13: =MROUND(AX13+AY13+BA13+BC13,500) -> 11500 | AW13: =AX13*100/AV13 -> 5.2173913 | AX13: =1*$F$65 -> 600 | AY13: =AZ13*$F$57 -> 2000 | AZ13: 1.5 | BA13: =2*('АРМАТУРНЫЕ РАБОТЫ'!$AJ$23+'АРМАТУРНЫЕ РАБОТЫ'!$AJ$24+'АРМАТУРНЫЕ РАБОТЫ'!$AJ$115+'АРМАТУРНЫЕ РАБОТЫ'!$AJ$116) -> 7000 | BB13: 40 | BC13: =MROUND((AX13+AY13)*BB13/(100-BB13),100) -> 1700
B15: 3 | D15: Задняя полусфера | L15: =MROUND(N15+O15+Q15+S15,500) -> 10500 | M15: =N15*100/L15 -> 17.142857 | N15: =3*$F$65 -> 1800 | O15: =P15*$F$57 -> 2666.6667 | P15: 2 | Q15: =('АРМАТУРНЫЕ РАБОТЫ'!$L$23+'АРМАТУРНЫЕ РАБОТЫ'!$L$24+'АРМАТУРНЫЕ РАБОТЫ'!$L$115+'АРМАТУРНЫЕ РАБОТЫ'!$L$116)*2 -> 3000 | R15: 40 | S15: =MROUND((N15+O15)*R15/(100-R15),100) -> 3000 | U15: =MROUND(W15+X15+Z15+AB15,500) -> 10500 | V15: =W15*100/U15 -> 17.142857 | W15: =3*$F$65 -> 1800 | X15: =Y15*$F$57 -> 2800 | Y15: 2.1 | Z15: =('АРМАТУРНЫЕ РАБОТЫ'!$R$23+'АРМАТУРНЫЕ РАБОТЫ'!$R$24+'АРМАТУРНЫЕ РАБОТЫ'!$R$115+'АРМАТУРНЫЕ РАБОТЫ'!$R$116)*2 -> 3000 | AA15: 40 | AB15: =MROUND((W15+X15)*AA15/(100-AA15),100) -> 3100 | AD15: =MROUND(AF15+AG15+AI15+AK15,500) -> 11500 | AE15: =AF15*100/AD15 -> 15.652174 | AF15: =3*$F$65 -> 1800 | AG15: =AH15*$F$57 -> 2933.3333 | AH15: 2.2 | AI15: =2*('АРМАТУРНЫЕ РАБОТЫ'!$X$23+'АРМАТУРНЫЕ РАБОТЫ'!$X$24+'АРМАТУРНЫЕ РАБОТЫ'!$X$115+'АРМАТУРНЫЕ РАБОТЫ'!$X$116) -> 3800 | AJ15: 40 | AK15: =MROUND((AF15+AG15)*AJ15/(100-AJ15),100) -> 3200 | AM15: =MROUND(AO15+AP15+AR15+AT15,500) -> 14000 | AN15: =AO15*100/AM15 -> 12.857143 | AO15: =3*$F$65 -> 1800 | AP15: =AQ15*$F$57 -> 3066.6667 | AQ15: 2.3 | AR15: =2*('АРМАТУРНЫЕ РАБОТЫ'!$AD$23+'АРМАТУРНЫЕ РАБОТЫ'!$AD$24+'АРМАТУРНЫЕ РАБОТЫ'!$AD$115+'АРМАТУРНЫЕ РАБОТЫ'!$AD$116) -> 6000 | AS15: 40 | AT15: =MROUND((AO15+AP15)*AS15/(100-AS15),100) -> 3200 | AV15: =MROUND(AX15+AY15+BA15+BC15,500) -> 15500 | AW15: =AX15*100/AV15 -> 11.612903 | AX15: =3*$F$65 -> 1800 | AY15: =AZ15*$F$57 -> 3333.3333 | AZ15: 2.5 | BA15: =2*('АРМАТУРНЫЕ РАБОТЫ'!$AJ$23+'АРМАТУРНЫЕ РАБОТЫ'!$AJ$24+'АРМАТУРНЫЕ РАБОТЫ'!$AJ$115+'АРМАТУРНЫЕ РАБОТЫ'!$AJ$116) -> 7000 | BB15: 40 | BC15: =MROUND((AX15+AY15)*BB15/(100-BB15),100) -> 3400
B17: 4 | D17: Передняя полусфера | L17: =MROUND(N17+O17+Q17+S17,500) -> 11500 | M17: =N17*100/L17 -> 20.869565 | N17: =4*$F$65 -> 2400 | O17: =P17*$F$57 -> 2666.6667 | P17: 2 | Q17: =('АРМАТУРНЫЕ РАБОТЫ'!$L$23+'АРМАТУРНЫЕ РАБОТЫ'!$L$24+'АРМАТУРНЫЕ РАБОТЫ'!$L$115+'АРМАТУРНЫЕ РАБОТЫ'!$L$116)*2 -> 3000 | R17: 40 | S17: =MROUND((N17+O17)*R17/(100-R17),100) -> 3400 | U17: =MROUND(W17+X17+Z17+AB17,500) -> 11500 | V17: =W17*100/U17 -> 20.869565 | W17: =4*$F$65 -> 2400 | X17: =Y17*$F$57 -> 2800 | Y17: 2.1 | Z17: =('АРМАТУРНЫЕ РАБОТЫ'!$R$23+'АРМАТУРНЫЕ РАБОТЫ'!$R$24+'АРМАТУРНЫЕ РАБОТЫ'!$R$115+'АРМАТУРНЫЕ РАБОТЫ'!$R$116)*2 -> 3000 | AA17: 40 | AB17: =MROUND((W17+X17)*AA17/(100-AA17),100) -> 3500 | AD17: =MROUND(AF17+AG17+AI17+AK17,500) -> 12500 | AE17: =AF17*100/AD17 -> 19.2 | AF17: =4*$F$65 -> 2400 | AG17: =AH17*$F$57 -> 2933.3333 | AH17: 2.2 | AI17: =2*('АРМАТУРНЫЕ РАБОТЫ'!$X$23+'АРМАТУРНЫЕ РАБОТЫ'!$X$24+'АРМАТУРНЫЕ РАБОТЫ'!$X$115+'АРМАТУРНЫЕ РАБОТЫ'!$X$116) -> 3800 | AJ17: 40 | AK17: =MROUND((AF17+AG17)*AJ17/(100-AJ17),100) -> 3600 | AM17: =MROUND(AO17+AP17+AR17+AT17,500) -> 15000 | AN17: =AO17*100/AM17 -> 16 | AO17: =4*$F$65 -> 2400 | AP17: =AQ17*$F$57 -> 3066.6667 | AQ17: 2.3 | AR17: =2*('АРМАТУРНЫЕ РАБОТЫ'!$AD$23+'АРМАТУРНЫЕ РАБОТЫ'!$AD$24+'АРМАТУРНЫЕ РАБОТЫ'!$AD$115+'АРМАТУРНЫЕ РАБОТЫ'!$AD$116) -> 6000 | AS17: 40 | AT17: =MROUND((AO17+AP17)*AS17/(100-AS17),100) -> 3600 | AV17: =MROUND(AX17+AY17+BA17+BC17,500) -> 16500 | AW17: =AX17*100/AV17 -> 14.545455 | AX17: =4*$F$65 -> 2400 | AY17: =AZ17*$F$57 -> 3333.3333 | AZ17: 2.5 | BA17: =2*('АРМАТУРНЫЕ РАБОТЫ'!$AJ$23+'АРМАТУРНЫЕ РАБОТЫ'!$AJ$24+'АРМАТУРНЫЕ РАБОТЫ'!$AJ$115+'АРМАТУРНЫЕ РАБОТЫ'!$AJ$116) -> 7000 | BB17: 40 | BC17: =MROUND((AX17+AY17)*BB17/(100-BB17),100) -> 3800
B19: 5 | D19: Люк | L19: =MROUND(N19+O19+Q19+S19,500) -> 3000 | M19: =N19*100/L19 -> 40 | N19: =2*$F$65 -> 1200 | O19: =P19*$F$57 -> 666.66667 | P19: 0.5 | R19: 40 | S19: =MROUND((N19+O19)*R19/(100-R19),100) -> 1200 | U19: =MROUND(W19+X19+Z19+AB19,500) -> 3500 | V19: =W19*100/U19 -> 34.285714 | W19: =2*$F$65 -> 1200 | X19: =Y19*$F$57 -> 800 | Y19: 0.6 | AA19: 40 | AB19: =MROUND((W19+X19)*AA19/(100-AA19),100) -> 1300 | AD19: =MROUND(AF19+AG19+AI19+AK19,500) -> 3500 | AE19: =AF19*100/AD19 -> 34.285714 | AF19: =2*$F$65 -> 1200 | AG19: =AH19*$F$57 -> 933.33333 | AH19: 0.7 | AJ19: 40 | AK19: =MROUND((AF19+AG19)*AJ19/(100-AJ19),100) -> 1400 | AM19: =MROUND(AO19+AP19+AR19+AT19,500) -> 3500 | AN19: =AO19*100/AM19 -> 34.285714 | AO19: =2*$F$65 -> 1200 | AP19: =AQ19*$F$57 -> 933.33333 | AQ19: 0.7 | AS19: 40 | AT19: =MROUND((AO19+AP19)*AS19/(100-AS19),100) -> 1400 | AV19: =MROUND(AX19+AY19+BA19+BC19,500) -> 4000 | AW19: =AX19*100/AV19 -> 30 | AX19: =2*$F$65 -> 1200 | AY19: =AZ19*$F$57 -> 1066.6667 | AZ19: 0.8 | BB19: 40 | BC19: =MROUND((AX19+AY19)*BB19/(100-BB19),100) -> 1500
B21: 6 | D21: Панорама | L21: =MROUND(N21+O21+Q21+S21,500) -> 8500 | M21: =N21*100/L21 -> 28.235294 | N21: =4*$F$65 -> 2400 | O21: =P21*$F$57 -> 2666.6667 | P21: 2 | R21: 40 | S21: =MROUND((N21+O21)*R21/(100-R21),100) -> 3400 | U21: =MROUND(W21+X21+Z21+AB21,500) -> 9500 | V21: =W21*100/U21 -> 25.263158 | W21: =4*$F$65 -> 2400 | X21: =Y21*$F$57 -> 2800 | Y21: 2.1 | AA21: 45 | AB21: =MROUND((W21+X21)*AA21/(100-AA21),100) -> 4300 | AD21: =MROUND(AF21+AG21+AI21+AK21,500) -> 10500 | AE21: =AF21*100/AD21 -> 22.857143 | AF21: =4*$F$65 -> 2400 | AG21: =AH21*$F$57 -> 2933.3333 | AH21: 2.2 | AJ21: 50 | AK21: =MROUND((AF21+AG21)*AJ21/(100-AJ21),100) -> 5300 | AM21: =MROUND(AO21+AP21+AR21+AT21,500) -> 11000 | AN21: =AO21*100/AM21 -> 21.818182 | AO21: =4*$F$65 -> 2400 | AP21: =AQ21*$F$57 -> 3066.6667 | AQ21: 2.3 | AS21: 50 | AT21: =MROUND((AO21+AP21)*AS21/(100-AS21),100) -> 5500 | AV21: =MROUND(AX21+AY21+BA21+BC21,500) -> 11500 | AW21: =AX21*100/AV21 -> 20.869565 | AX21: =4*$F$65 -> 2400 | AY21: =AZ21*$F$57 -> 3333.3333 | AZ21: 2.5 | BB21: 50 | BC21: =MROUND((AX21+AY21)*BB21/(100-BB21),100) -> 5700
B23: АТЕРМАЛЬНАЯ ПЛЕНКА. СВЕТОПРОПУСКАЕМОСТЬ 64%. NDFOS
B25: 7 | D25: Лобовое стекло | L25: =MROUND(N25+O25+Q25+S25,500) -> 7500 | M25: =N25*100/L25 -> 16 | N25: =2*$F$65 -> 1200 | O25: =P25*$F$59 -> 1850 | P25: 1.5 | R25: 60 | S25: =MROUND((N25+O25)*R25/(100-R25),100) -> 4600 | U25: =MROUND(W25+X25+Z25+AB25,500) -> 8000 | V25: =W25*100/U25 -> 15 | W25: =2*$F$65 -> 1200 | X25: =Y25*$F$59 -> 1973.3333 | Y25: 1.6 | AA25: 60 | AB25: =MROUND((W25+X25)*AA25/(100-AA25),100) -> 4800 | AD25: =MROUND(AF25+AG25+AI25+AK25,500) -> 8000 | AE25: =AF25*100/AD25 -> 15 | AF25: =2*$F$65 -> 1200 | AG25: =AH25*$F$59 -> 2096.6667 | AH25: 1.7 | AJ25: 60 | AK25: =MROUND((AF25+AG25)*AJ25/(100-AJ25),100) -> 4900 | AM25: =MROUND(AO25+AP25+AR25+AT25,500) -> 8500 | AN25: =AO25*100/AM25 -> 14.117647 | AO25: =2*$F$65 -> 1200 | AP25: =AQ25*$F$59 -> 2220 | AQ25: 1.8 | AS25: 60 | AT25: =MROUND((AO25+AP25)*AS25/(100-AS25),100) -> 5100 | AV25: =MROUND(AX25+AY25+BA25+BC25,500) -> 9000 | AW25: =AX25*100/AV25 -> 13.333333 | AX25: =2*$F$65 -> 1200 | AY25: =AZ25*$F$59 -> 2466.6667 | AZ25: 2 | BB25: 60 | BC25: =MROUND((AX25+AY25)*BB25/(100-BB25),100) -> 5500
B27: 8 | D27: Передние боковые | L27: =MROUND(N27+O27+Q27+S27,500) -> 7500 | M27: =N27*100/L27 -> 8 | N27: =1*$F$65 -> 600 | O27: =P27*$F$59 -> 1233.3333 | P27: 1 | Q27: =('АРМАТУРНЫЕ РАБОТЫ'!$L$23+'АРМАТУРНЫЕ РАБОТЫ'!$L$24+'АРМАТУРНЫЕ РАБОТЫ'!$L$115+'АРМАТУРНЫЕ РАБОТЫ'!$L$116)*2 -> 3000 | R27: 60 | S27: =MROUND((N27+O27)*R27/(100-R27),100) -> 2800 | U27: =MROUND(W27+X27+Z27+AB27,500) -> 8500 | V27: =W27*100/U27 -> 7.0588235 | W27: =1*$F$65 -> 600 | X27: =Y27*$F$59 -> 1603.3333 | Y27: 1.3 | Z27: =('АРМАТУРНЫЕ РАБОТЫ'!$R$23+'АРМАТУРНЫЕ РАБОТЫ'!$R$24+'АРМАТУРНЫЕ РАБОТЫ'!$R$115+'АРМАТУРНЫЕ РАБОТЫ'!$R$116)*2 -> 3000 | AA27: 60 | AB27: =MROUND((W27+X27)*AA27/(100-AA27),100) -> 3300 | AD27: =MROUND(AF27+AG27+AI27+AK27,500) -> 9500 | AE27: =AF27*100/AD27 -> 6.3157895 | AF27: =1*$F$65 -> 600 | AG27: =AH27*$F$59 -> 1726.6667 | AH27: 1.4 | AI27: =2*('АРМАТУРНЫЕ РАБОТЫ'!$X$23+'АРМАТУРНЫЕ РАБОТЫ'!$X$24+'АРМАТУРНЫЕ РАБОТЫ'!$X$115+'АРМАТУРНЫЕ РАБОТЫ'!$X$116) -> 3800 | AJ27: 60 | AK27: =MROUND((AF27+AG27)*AJ27/(100-AJ27),100) -> 3500 | AM27: =MROUND(AO27+AP27+AR27+AT27,500) -> 12000 | AN27: =AO27*100/AM27 -> 5 | AO27: =1*$F$65 -> 600 | AP27: =AQ27*$F$59 -> 1850 | AQ27: 1.5 | AR27: =2*('АРМАТУРНЫЕ РАБОТЫ'!$AD$23+'АРМАТУРНЫЕ РАБОТЫ'!$AD$24+'АРМАТУРНЫЕ РАБОТЫ'!$AD$115+'АРМАТУРНЫЕ РАБОТЫ'!$AD$116) -> 6000 | AS27: 60 | AT27: =MROUND((AO27+AP27)*AS27/(100-AS27),100) -> 3700 | AV27: =MROUND(AX27+AY27+BA27+BC27,500) -> 13000 | AW27: =AX27*100/AV27 -> 4.6153846 | AX27: =1*$F$65 -> 600 | AY27: =AZ27*$F$59 -> 1850 | AZ27: 1.5 | BA27: =2*('АРМАТУРНЫЕ РАБОТЫ'!$AJ$23+'АРМАТУРНЫЕ РАБОТЫ'!$AJ$24+'АРМАТУРНЫЕ РАБОТЫ'!$AJ$115+'АРМАТУРНЫЕ РАБОТЫ'!$AJ$116) -> 7000 | BB27: 60 | BC27: =MROUND((AX27+AY27)*BB27/(100-BB27),100) -> 3700
